Workbook

Sheet Beheer
A2: 🎯 Quiz Instellingen
A3: Configureer rondes en teams — al het andere wordt automatisch bijgewerkt.
A4: RONDES | B4: Totaal aantal rondes | C4: 12 | F4: TEAMS | H4: 💡 HOE HET WERKT
A6: # | B6: PNT | C6: NAAM | F6: TEAMNAAM | H6: 1. Stel het totale aantal rondes in in het perzikkleurige vak (C4) — max 30
A7: =IF(ROW()-6<=$C$4,ROW()-6,"") -> 1 | B7: 10 | C7: Rond de wereld | F7: De Frietkotbazen | H7: 2. Pas het maximum aantal punten per ronde aan in kolom B
A8: =IF(ROW()-6<=$C$4,ROW()-6,"") -> 2 | B8: 10 | C8: Woordslang | F8: Manneke Pis & Co | H8: 3. Hernoem rondes in kolom C (bijv. "Actua", "Doe-ronde")
A9: =IF(ROW()-6<=$C$4,ROW()-6,"") -> 3 | B9: 10 | C9: Lokaal | F9: De Trage Schildpadden | H9: 4. Voeg teamnamen toe of verwijder ze in kolom F — max 60 teams
A10: =IF(ROW()-6<=$C$4,ROW()-6,"") -> 4 | B10: 20 | C10: Tussenronde: Vlaggen | F10: Stoempers United | H10: 5. Voer de scores per ronde van elk team in op het tabblad Dashboard Totalen en de Ranglijst worden automatisch bijgewerkt
A11: =IF(ROW()-6<=$C$4,ROW()-6,"") -> 5 | B11: 10 | C11: Actua | F11: De Bierbuiken
A12: =IF(ROW()-6<=$C$4,ROW()-6,"") -> 6 | B12: 10 | C12: Film | F12: Tjevenbende | H12: 🏷️ TIE-BREAK KOLOM
A13: =IF(ROW()-6<=$C$4,ROW()-6,"") -> 7 | B13: 10 | C13: Fauna en Flora | F13: De Wafelijzers | H13: Wordt gebruikt op het Dashboard (kolom B) om teams te scheiden die op hetzelfde totale aantal punten eindigen.
A14: =IF(ROW()-6<=$C$4,ROW()-6,"") -> 8 | B14: 15 | C14: Tussenronde: Droedels | F14: Amai Zeg! | H14: Stel aan het begin van de quiz een tie-break vraag met een numeriek antwoord (bijv. "Hoeveel eilanden heeft Griekenland?").
A15: =IF(ROW()-6<=$C$4,ROW()-6,"") -> 9 | B15: 10 | C15: Muziek | F15: De Choco Prinsen | H15: Voer in Dashboard kolom B het absolute verschil in tussen de gok van elk team en het juiste antwoord.
A16: =IF(ROW()-6<=$C$4,ROW()-6,"") -> 10 | B16: 10 | C16: Kleuren | F16: Smoutebollen FC | H16: Lager = beter. Het team dat het dichtst bij het juiste antwoord zit (kleinste getal) wint de tie-break. Laat leeg indien niet gebruikt.
A17: =IF(ROW()-6<=$C$4,ROW()-6,"") -> 11 | B17: 5 | C17: Tussenronde: Snel! | F17: De Plezante Pintjes
A18: =IF(ROW()-6<=$C$4,ROW()-6,"") -> 12 | B18: 10 | C18: Eindspel | F18: Schele Vanthilt
A19: =IF(ROW()-6<=$C$4,ROW()-6,"") | C19: =IF(A19="","","Ronde "&A19) | F19: De Kletskoppen
A20: =IF(ROW()-6<=$C$4,ROW()-6,"") | C20: =IF(A20="","","Ronde "&A20) | F20: Boeren met Verstand
A21: =IF(ROW()-6<=$C$4,ROW()-6,"") | C21: =IF(A21="","","Ronde "&A21) | F21: De Goe Goesting
A22: =IF(ROW()-6<=$C$4,ROW()-6,"") | C22: =IF(A22="","","Ronde "&A22) | F22: Jommeke's Wreker
A23: =IF(ROW()-6<=$C$4,ROW()-6,"") | C23: =IF(A23="","","Ronde "&A23) | F23: De Stoute Schoenen
A24: =IF(ROW()-6<=$C$4,ROW()-6,"") | C24: =IF(A24="","","Ronde "&A24) | F24: Pataten met Stoofvlees
A25: =IF(ROW()-6<=$C$4,ROW()-6,"") | C25: =IF(A25="","","Ronde "&A25) | F25: De Zatte Garnaal
A26: =IF(ROW()-6<=$C$4,ROW()-6,"") | C26: =IF(A26="","","Ronde "&A26) | F26: Kieken zonder Kop
A27: =IF(ROW()-6<=$C$4,ROW()-6,"") | C27: =IF(A27="","","Ronde "&A27) | F27: De Madammen
A28: =IF(ROW()-6<=$C$4,ROW()-6,"") | C28: =IF(A28="","","Ronde "&A28) | F28: Gentse Feestneuzen
A29: =IF(ROW()-6<=$C$4,ROW()-6,"") | C29: =IF(A29="","","Ronde "&A29) | F29: De Lambiek Liga
A30: =IF(ROW()-6<=$C$4,ROW()-6,"") | C30: =IF(A30="","","Ronde "&A30) | F30: Kortrijkse Krollen
A31: =IF(ROW()-6<=$C$4,ROW()-6,"") | C31: =IF(A31="","","Ronde "&A31) | F31: De Wijze Uilen
A32: =IF(ROW()-6<=$C$4,ROW()-6,"") | C32: =IF(A32="","","Ronde "&A32)
A33: =IF(ROW()-6<=$C$4,ROW()-6,"") | C33: =IF(A33="","","Ronde "&A33)
A34: =IF(ROW()-6<=$C$4,ROW()-6,"") | C34: =IF(A34="","","Ronde "&A34)
A35: =IF(ROW()-6<=$C$4,ROW()-6,"") | C35: =IF(A35="","","Ronde "&A35)
A36: =IF(ROW()-6<=$C$4,ROW()-6,"") | C36: =IF(A36="","","Ronde "&A36)

Sheet Dashboard
A1: Team | B1: Tie-break | C1: {=IFERROR(IF(COLUMNS($C1:C1)<=Beheer!$C$4,IF(LEFT(INDEX(Beheer!$C$7:$C$36,COLUMNS($C1:C1)),6)="Ronde ","R"&MID(INDEX(Beheer!$C$7:$C$36,COLUMNS($C1:C1)),7,10),LEFT(INDEX(Beheer!$C$7:$C$36,COLUMNS($C1:C1)),7))&" (/"&INDEX(Beheer!$B$7:$B$37,COLUMNS($C1:C1))&")","")," ")} -> Rond de (/10) | D1: {=IFERROR(IF(COLUMNS($C1:D1)<=Beheer!$C$4,IF(LEFT(INDEX(Beheer!$C$7:$C$36,COLUMNS($C1:D1)),6)="Ronde ","R"&MID(INDEX(Beheer!$C$7:$C$36,COLUMNS($C1:D1)),7,10),LEFT(INDEX(Beheer!$C$7:$C$36,COLUMNS($C1:D1)),7))&" (/"&INDEX(Beheer!$B$7:$B$37,COLUMNS($C1:D1))&")","")," ")} -> Woordsl (/10) | E1: {=IFERROR(IF(COLUMNS($C1:E1)<=Beheer!$C$4,IF(LEFT(INDEX(Beheer!$C$7:$C$36,COLUMNS($C1:E1)),6)="Ronde ","R"&MID(INDEX(Beheer!$C$7:$C$36,COLUMNS($C1:E1)),7,10),LEFT(INDEX(Beheer!$C$7:$C$36,COLUMNS($C1:E1)),7))&" (/"&INDEX(Beheer!$B$7:$B$37,COLUMNS($C1:E1))&")","")," ")} -> Lokaal (/10) | F1: {=IFERROR(IF(COLUMNS($C1:F1)<=Beheer!$C$4,IF(LEFT(INDEX(Beheer!$C$7:$C$36,COLUMNS($C1:F1)),6)="Ronde ","R"&MID(INDEX(Beheer!$C$7:$C$36,COLUMNS($C1:F1)),7,10),LEFT(INDEX(Beheer!$C$7:$C$36,COLUMNS($C1:F1)),7))&" (/"&INDEX(Beheer!$B$7:$B$37,COLUMNS($C1:F1))&")","")," ")} -> Tussenr (/20) | G1: {=IFERROR(IF(COLUMNS($C1:G1)<=Beheer!$C$4,IF(LEFT(INDEX(Beheer!$C$7:$C$36,COLUMNS($C1:G1)),6)="Ronde ","R"&MID(INDEX(Beheer!$C$7:$C$36,COLUMNS($C1:G1)),7,10),LEFT(INDEX(Beheer!$C$7:$C$36,COLUMNS($C1:G1)),7))&" (/"&INDEX(Beheer!$B$7:$B$37,COLUMNS($C1:G1))&")","")," ")} -> Actua (/10) | H1: {=IFERROR(IF(COLUMNS($C1:H1)<=Beheer!$C$4,IF(LEFT(INDEX(Beheer!$C$7:$C$36,COLUMNS($C1:H1)),6)="Ronde ","R"&MID(INDEX(Beheer!$C$7:$C$36,COLUMNS($C1:H1)),7,10),LEFT(INDEX(Beheer!$C$7:$C$36,COLUMNS($C1:H1)),7))&" (/"&INDEX(Beheer!$B$7:$B$37,COLUMNS($C1:H1))&")","")," ")} -> Film (/10) | I1: {=IFERROR(IF(COLUMNS($C1:I1)<=Beheer!$C$4,IF(LEFT(INDEX(Beheer!$C$7:$C$36,COLUMNS($C1:I1)),6)="Ronde ","R"&MID(INDEX(Beheer!$C$7:$C$36,COLUMNS($C1:I1)),7,10),LEFT(INDEX(Beheer!$C$7:$C$36,COLUMNS($C1:I1)),7))&" (/"&INDEX(Beheer!$B$7:$B$37,COLUMNS($C1:I1))&")","")," ")} -> Fauna e (/10) | J1: {=IFERROR(IF(COLUMNS($C1:J1)<=Beheer!$C$4,IF(LEFT(INDEX(Beheer!$C$7:$C$36,COLUMNS($C1:J1)),6)="Ronde ","R"&MID(INDEX(Beheer!$C$7:$C$36,COLUMNS($C1:J1)),7,10),LEFT(INDEX(Beheer!$C$7:$C$36,COLUMNS($C1:J1)),7))&" (/"&INDEX(Beheer!$B$7:$B$37,COLUMNS($C1:J1))&")","")," ")} -> Tussenr (/15) | ... AF1: {=IFERROR(IF(COLUMNS($C1:AF1)<=Beheer!$C$4,IF(LEFT(INDEX(Beheer!$C$7:$C$36,COLUMNS($C1:AF1)),6)="Ronde ","R"&MID(INDEX(Beheer!$C$7:$C$36,COLUMNS($C1:AF1)),7,10),LEFT(INDEX(Beheer!$C$7:$C$36,COLUMNS($C1:AF1)),7))&" (/"&INDEX(Beheer!$B$7:$B$37,COLUMNS($C1:AF1))&")","")," ")} | AG1: Totaal | AH1: Max | AI1: Sorteersleutel
A2: {=IFERROR(IF(INDEX(Beheer!$F$7:$F$66,ROWS($A$2:A2))="","",INDEX(Beheer!$F$7:$F$66,ROWS($A$2:A2))),"")} -> De Frietkotbazen | B2: 17 | C2: 10 | D2: 1 | E2: 1 | F2: 20 | G2: 8 | H2: 1 | I2: 5 | J2: 4 | K2: 3 | L2: 8 | M2: 1 | N2: 3 | AG2: =IF($A2="","",SUM(C2:AF2)) -> 65 | AH2: {=IF($A2="","",SUMPRODUCT((ROW(Beheer!$B$7:$B$36)-ROW(Beheer!$B$7)+1<=Beheer!$C$4)*IFERROR(Beheer!$B$7:$B$36*1,0)))} -> 130 | AI2: =IF($A2="",-1,SUM(C2:AF2)-IFERROR(B2,999)/100000) -> 64.99983
A3: {=IFERROR(IF(INDEX(Beheer!$F$7:$F$66,ROWS($A$2:A3))="","",INDEX(Beheer!$F$7:$F$66,ROWS($A$2:A3))),"")} -> Manneke Pis & Co | B3: 4 | C3: 10 | D3: 8 | E3: 9 | F3: 4 | G3: 9 | H3: 10 | I3: 6 | J3: 2 | K3: 3 | L3: 6 | M3: 4 | N3: 9 | AG3: =IF($A3="","",SUM(C3:AF3)) -> 80 | AH3: {=IF($A3="","",SUMPRODUCT((ROW(Beheer!$B$7:$B$36)-ROW(Beheer!$B$7)+1<=Beheer!$C$4)*IFERROR(Beheer!$B$7:$B$36*1,0)))} -> 130 | AI3: =IF($A3="",-1,SUM(C3:AF3)-IFERROR(B3,999)/100000) -> 79.99996
A4: {=IFERROR(IF(INDEX(Beheer!$F$7:$F$66,ROWS($A$2:A4))="","",INDEX(Beheer!$F$7:$F$66,ROWS($A$2:A4))),"")} -> De Trage Schildpadden | B4: 22 | C4: 3 | D4: 10 | E4: 3 | F4: 6 | G4: 5 | H4: 1 | I4: 2 | J4: 10 | K4: 1 | L4: 9 | M4: 2 | N4: 4 | AG4: =IF($A4="","",SUM(C4:AF4)) -> 56 | AH4: {=IF($A4="","",SUMPRODUCT((ROW(Beheer!$B$7:$B$36)-ROW(Beheer!$B$7)+1<=Beheer!$C$4)*IFERROR(Beheer!$B$7:$B$36*1,0)))} -> 130 | AI4: =IF($A4="",-1,SUM(C4:AF4)-IFERROR(B4,999)/100000) -> 55.99978
A5: {=IFERROR(IF(INDEX(Beheer!$F$7:$F$66,ROWS($A$2:A5))="","",INDEX(Beheer!$F$7:$F$66,ROWS($A$2:A5))),"")} -> Stoempers United | B5: 9 | C5: 5 | D5: 1 | E5: 9 | F5: 8 | G5: 9 | H5: 7 | I5: 8 | J5: 5 | K5: 4 | L5: 3 | M5: 3 | N5: 9 | AG5: =IF($A5="","",SUM(C5:AF5)) -> 71 | AH5: {=IF($A5="","",SUMPRODUCT((ROW(Beheer!$B$7:$B$36)-ROW(Beheer!$B$7)+1<=Beheer!$C$4)*IFERROR(Beheer!$B$7:$B$36*1,0)))} -> 130 | AI5: =IF($A5="",-1,SUM(C5:AF5)-IFERROR(B5,999)/100000) -> 70.99991
A6: {=IFERROR(IF(INDEX(Beheer!$F$7:$F$66,ROWS($A$2:A6))="","",INDEX(Beheer!$F$7:$F$66,ROWS($A$2:A6))),"")} -> De Bierbuiken | B6: 1 | C6: 3 | D6: 1 | E6: 5 | F6: 8 | G6: 1 | H6: 5 | I6: 9 | J6: 8 | K6: 4 | L6: 5 | M6: 2 | N6: 8 | AG6: =IF($A6="","",SUM(C6:AF6)) -> 59 | AH6: {=IF($A6="","",SUMPRODUCT((ROW(Beheer!$B$7:$B$36)-ROW(Beheer!$B$7)+1<=Beheer!$C$4)*IFERROR(Beheer!$B$7:$B$36*1,0)))} -> 130 | AI6: =IF($A6="",-1,SUM(C6:AF6)-IFERROR(B6,999)/100000) -> 58.99999
A7: {=IFERROR(IF(INDEX(Beheer!$F$7:$F$66,ROWS($A$2:A7))="","",INDEX(Beheer!$F$7:$F$66,ROWS($A$2:A7))),"")} -> Tjevenbende | B7: 13 | C7: 3 | D7: 10 | E7: 3 | F7: 14 | G7: 8 | H7: 10 | I7: 3 | J7: 11 | K7: 6 | L7: 6 | M7: 3 | N7: 5 | AG7: =IF($A7="","",SUM(C7:AF7)) -> 82 | AH7: {=IF($A7="","",SUMPRODUCT((ROW(Beheer!$B$7:$B$36)-ROW(Beheer!$B$7)+1<=Beheer!$C$4)*IFERROR(Beheer!$B$7:$B$36*1,0)))} -> 130 | AI7: =IF($A7="",-1,SUM(C7:AF7)-IFERROR(B7,999)/100000) -> 81.99987
A8: {=IFERROR(IF(INDEX(Beheer!$F$7:$F$66,ROWS($A$2:A8))="","",INDEX(Beheer!$F$7:$F$66,ROWS($A$2:A8))),"")} -> De Wafelijzers | B8: 25 | C8: 4 | D8: 8 | E8: 4 | F8: 18 | G8: 1 | H8: 5 | I8: 3 | J8: 12 | K8: 2 | L8: 2 | M8: 1 | N8: 8 | AG8: =IF($A8="","",SUM(C8:AF8)) -> 68 | AH8: {=IF($A8="","",SUMPRODUCT((ROW(Beheer!$B$7:$B$36)-ROW(Beheer!$B$7)+1<=Beheer!$C$4)*IFERROR(Beheer!$B$7:$B$36*1,0)))} -> 130 | AI8: =IF($A8="",-1,SUM(C8:AF8)-IFERROR(B8,999)/100000) -> 67.99975
A9: {=IFERROR(IF(INDEX(Beheer!$F$7:$F$66,ROWS($A$2:A9))="","",INDEX(Beheer!$F$7:$F$66,ROWS($A$2:A9))),"")} -> Amai Zeg! | B9: 6 | C9: 10 | D9: 8 | E9: 8 | F9: 13 | G9: 3 | H9: 3 | I9: 2 | J9: 7 | K9: 4 | L9: 3 | M9: 5 | N9: 10 | AG9: =IF($A9="","",SUM(C9:AF9)) -> 76 | AH9: {=IF($A9="","",SUMPRODUCT((ROW(Beheer!$B$7:$B$36)-ROW(Beheer!$B$7)+1<=Beheer!$C$4)*IFERROR(Beheer!$B$7:$B$36*1,0)))} -> 130 | AI9: =IF($A9="",-1,SUM(C9:AF9)-IFERROR(B9,999)/100000) -> 75.99994
A10: {=IFERROR(IF(INDEX(Beheer!$F$7:$F$66,ROWS($A$2:A10))="","",INDEX(Beheer!$F$7:$F$66,ROWS($A$2:A10))),"")} -> De Choco Prinsen | B10: 19 | C10: 9 | D10: 10 | E10: 1 | F10: 4 | G10: 9 | H10: 2 | I10: 5 | J10: 5 | K10: 4 | L10: 6 | M10: 4 | N10: 7 | AG10: =IF($A10="","",SUM(C10:AF10)) -> 66 | AH10: {=IF($A10="","",SUMPRODUCT((ROW(Beheer!$B$7:$B$36)-ROW(Beheer!$B$7)+1<=Beheer!$C$4)*IFERROR(Beheer!$B$7:$B$36*1,0)))} -> 130 | AI10: =IF($A10="",-1,SUM(C10:AF10)-IFERROR(B10,999)/100000) -> 65.99981
A11: {=IFERROR(IF(INDEX(Beheer!$F$7:$F$66,ROWS($A$2:A11))="","",INDEX(Beheer!$F$7:$F$66,ROWS($A$2:A11))),"")} -> Smoutebollen FC | B11: 11 | C11: 9 | D11: 10 | E11: 5 | F11: 1 | G11: 10 | H11: 3 | I11: 9 | J11: 9 | K11: 9 | L11: 3 | M11: 2 | N11: 4 | AG11: =IF($A11="","",SUM(C11:AF11)) -> 74 | AH11: {=IF($A11="","",SUMPRODUCT((ROW(Beheer!$B$7:$B$36)-ROW(Beheer!$B$7)+1<=Beheer!$C$4)*IFERROR(Beheer!$B$7:$B$36*1,0)))} -> 130 | AI11: =IF($A11="",-1,SUM(C11:AF11)-IFERROR(B11,999)/100000) -> 73.99989
A12: {=IFERROR(IF(INDEX(Beheer!$F$7:$F$66,ROWS($A$2:A12))="","",INDEX(Beheer!$F$7:$F$66,ROWS($A$2:A12))),"")} -> De Plezante Pintjes | B12: 3 | C12: 7 | D12: 6 | E12: 3 | F12: 5 | G12: 10 | H12: 6 | I12: 10 | J12: 11 | K12: 3 | L12: 8 | M12: 3 | N12: 9 | AG12: =IF($A12="","",SUM(C12:AF12)) -> 81 | AH12: {=IF($A12="","",SUMPRODUCT((ROW(Beheer!$B$7:$B$36)-ROW(Beheer!$B$7)+1<=Beheer!$C$4)*IFERROR(Beheer!$B$7:$B$36*1,0)))} -> 130 | AI12: =IF($A12="",-1,SUM(C12:AF12)-IFERROR(B12,999)/100000) -> 80.99997
A13: {=IFERROR(IF(INDEX(Beheer!$F$7:$F$66,ROWS($A$2:A13))="","",INDEX(Beheer!$F$7:$F$66,ROWS($A$2:A13))),"")} -> Schele Vanthilt | B13: 15 | C13: 10 | D13: 8 | E13: 1 | F13: 20 | G13: 4 | H13: 7 | I13: 7 | J13: 13 | K13: 10 | L13: 8 | M13: 1 | N13: 7 | AG13: =IF($A13="","",SUM(C13:AF13)) -> 96 | AH13: {=IF($A13="","",SUMPRODUCT((ROW(Beheer!$B$7:$B$36)-ROW(Beheer!$B$7)+1<=Beheer!$C$4)*IFERROR(Beheer!$B$7:$B$36*1,0)))} -> 130 | AI13: =IF($A13="",-1,SUM(C13:AF13)-IFERROR(B13,999)/100000) -> 95.99985
... A26: {=IFERROR(IF(INDEX(Beheer!$F$7:$F$66,ROWS($A$2:A26))="","",INDEX(Beheer!$F$7:$F$66,ROWS($A$2:A26))),"")} -> De Wijze Uilen | B26: 16 | C26: 4 | D26: 7 | E26: 3 | F26: 13 | G26: 1 | H26: 10 | I26: 7 | J26: 8 | K26: 3 | L26: 9 | M26: 1 | N26: 6 | AG26: =IF($A26="","",SUM(C26:AF26)) -> 72 | AH26: {=IF($A26="","",SUMPRODUCT((ROW(Beheer!$B$7:$B$36)-ROW(Beheer!$B$7)+1<=Beheer!$C$4)*IFERROR(Beheer!$B$7:$B$36*1,0)))} -> 130 | AI26: =IF($A26="",-1,SUM(C26:AF26)-IFERROR(B26,999)/100000) -> 71.99984
A27: {=IFERROR(IF(INDEX(Beheer!$F$7:$F$66,ROWS($A$2:A27))="","",INDEX(Beheer!$F$7:$F$66,ROWS($A$2:A27))),"")} | AG27: =IF($A27="","",SUM(C27:AF27)) | AH27: {=IF($A27="","",SUMPRODUCT((ROW(Beheer!$B$7:$B$36)-ROW(Beheer!$B$7)+1<=Beheer!$C$4)*IFERROR(Beheer!$B$7:$B$36*1,0)))} | AI27: =IF($A27="",-1,SUM(C27:AF27)-IFERROR(B27,999)/100000) -> -1
A28: {=IFERROR(IF(INDEX(Beheer!$F$7:$F$66,ROWS($A$2:A28))="","",INDEX(Beheer!$F$7:$F$66,ROWS($A$2:A28))),"")} | AG28: =IF($A28="","",SUM(C28:AF28)) | AH28: {=IF($A28="","",SUMPRODUCT((ROW(Beheer!$B$7:$B$36)-ROW(Beheer!$B$7)+1<=Beheer!$C$4)*IFERROR(Beheer!$B$7:$B$36*1,0)))} | AI28: =IF($A28="",-1,SUM(C28:AF28)-IFERROR(B28,999)/100000) -> -1
A29: {=IFERROR(IF(INDEX(Beheer!$F$7:$F$66,ROWS($A$2:A29))="","",INDEX(Beheer!$F$7:$F$66,ROWS($A$2:A29))),"")} | AG29: =IF($A29="","",SUM(C29:AF29)) | AH29: {=IF($A29="","",SUMPRODUCT((ROW(Beheer!$B$7:$B$36)-ROW(Beheer!$B$7)+1<=Beheer!$C$4)*IFERROR(Beheer!$B$7:$B$36*1,0)))} | AI29: =IF($A29="",-1,SUM(C29:AF29)-IFERROR(B29,999)/100000) -> -1
A30: {=IFERROR(IF(INDEX(Beheer!$F$7:$F$66,ROWS($A$2:A30))="","",INDEX(Beheer!$F$7:$F$66,ROWS($A$2:A30))),"")} | AG30: =IF($A30="","",SUM(C30:AF30)) | AH30: {=IF($A30="","",SUMPRODUCT((ROW(Beheer!$B$7:$B$36)-ROW(Beheer!$B$7)+1<=Beheer!$C$4)*IFERROR(Beheer!$B$7:$B$36*1,0)))} | AI30: =IF($A30="",-1,SUM(C30:AF30)-IFERROR(B30,999)/100000) -> -1
A31: {=IFERROR(IF(INDEX(Beheer!$F$7:$F$66,ROWS($A$2:A31))="","",INDEX(Beheer!$F$7:$F$66,ROWS($A$2:A31))),"")} | AG31: =IF($A31="","",SUM(C31:AF31)) | AH31: {=IF($A31="","",SUMPRODUCT((ROW(Beheer!$B$7:$B$36)-ROW(Beheer!$B$7)+1<=Beheer!$C$4)*IFERROR(Beheer!$B$7:$B$36*1,0)))} | AI31: =IF($A31="",-1,SUM(C31:AF31)-IFERROR(B31,999)/100000) -> -1
A32: {=IFERROR(IF(INDEX(Beheer!$F$7:$F$66,ROWS($A$2:A32))="","",INDEX(Beheer!$F$7:$F$66,ROWS($A$2:A32))),"")} | AG32: =IF($A32="","",SUM(C32:AF32)) | AH32: {=IF($A32="","",SUMPRODUCT((ROW(Beheer!$B$7:$B$36)-ROW(Beheer!$B$7)+1<=Beheer!$C$4)*IFERROR(Beheer!$B$7:$B$36*1,0)))} | AI32: =IF($A32="",-1,SUM(C32:AF32)-IFERROR(B32,999)/100000) -> -1
A33: {=IFERROR(IF(INDEX(Beheer!$F$7:$F$66,ROWS($A$2:A33))="","",INDEX(Beheer!$F$7:$F$66,ROWS($A$2:A33))),"")} | AG33: =IF($A33="","",SUM(C33:AF33)) | AH33: {=IF($A33="","",SUMPRODUCT((ROW(Beheer!$B$7:$B$36)-ROW(Beheer!$B$7)+1<=Beheer!$C$4)*IFERROR(Beheer!$B$7:$B$36*1,0)))} | AI33: =IF($A33="",-1,SUM(C33:AF33)-IFERROR(B33,999)/100000) -> -1
A34: {=IFERROR(IF(INDEX(Beheer!$F$7:$F$66,ROWS($A$2:A34))="","",INDEX(Beheer!$F$7:$F$66,ROWS($A$2:A34))),"")} | AG34: =IF($A34="","",SUM(C34:AF34)) | AH34: {=IF($A34="","",SUMPRODUCT((ROW(Beheer!$B$7:$B$36)-ROW(Beheer!$B$7)+1<=Beheer!$C$4)*IFERROR(Beheer!$B$7:$B$36*1,0)))} | AI34: =IF($A34="",-1,SUM(C34:AF34)-IFERROR(B34,999)/100000) -> -1
A35: {=IFERROR(IF(INDEX(Beheer!$F$7:$F$66,ROWS($A$2:A35))="","",INDEX(Beheer!$F$7:$F$66,ROWS($A$2:A35))),"")} | AG35: =IF($A35="","",SUM(C35:AF35)) | AH35: {=IF($A35="","",SUMPRODUCT((ROW(Beheer!$B$7:$B$36)-ROW(Beheer!$B$7)+1<=Beheer!$C$4)*IFERROR(Beheer!$B$7:$B$36*1,0)))} | AI35: =IF($A35="",-1,SUM(C35:AF35)-IFERROR(B35,999)/100000) -> -1
A36: {=IFERROR(IF(INDEX(Beheer!$F$7:$F$66,ROWS($A$2:A36))="","",INDEX(Beheer!$F$7:$F$66,ROWS($A$2:A36))),"")} | AG36: =IF($A36="","",SUM(C36:AF36)) | AH36: {=IF($A36="","",SUMPRODUCT((ROW(Beheer!$B$7:$B$36)-ROW(Beheer!$B$7)+1<=Beheer!$C$4)*IFERROR(Beheer!$B$7:$B$36*1,0)))} | AI36: =IF($A36="",-1,SUM(C36:AF36)-IFERROR(B36,999)/100000) -> -1
A37: {=IFERROR(IF(INDEX(Beheer!$F$7:$F$66,ROWS($A$2:A37))="","",INDEX(Beheer!$F$7:$F$66,ROWS($A$2:A37))),"")} | AG37: =IF($A37="","",SUM(C37:AF37)) | AH37: {=IF($A37="","",SUMPRODUCT((ROW(Beheer!$B$7:$B$36)-ROW(Beheer!$B$7)+1<=Beheer!$C$4)*IFERROR(Beheer!$B$7:$B$36*1,0)))} | AI37: =IF($A37="",-1,SUM(C37:AF37)-IFERROR(B37,999)/100000) -> -1
A38: {=IFERROR(IF(INDEX(Beheer!$F$7:$F$66,ROWS($A$2:A38))="","",INDEX(Beheer!$F$7:$F$66,ROWS($A$2:A38))),"")} | AG38: =IF($A38="","",SUM(C38:AF38)) | AH38: {=IF($A38="","",SUMPRODUCT((ROW(Beheer!$B$7:$B$36)-ROW(Beheer!$B$7)+1<=Beheer!$C$4)*IFERROR(Beheer!$B$7:$B$36*1,0)))} | AI38: =IF($A38="",-1,SUM(C38:AF38)-IFERROR(B38,999)/100000) -> -1
... A61: {=IFERROR(IF(INDEX(Beheer!$F$7:$F$66,ROWS($A$2:A61))="","",INDEX(Beheer!$F$7:$F$66,ROWS($A$2:A61))),"")} | AG61: =IF($A61="","",SUM(C61:AF61)) | AH61: {=IF($A61="","",SUMPRODUCT((ROW(Beheer!$B$7:$B$36)-ROW(Beheer!$B$7)+1<=Beheer!$C$4)*IFERROR(Beheer!$B$7:$B$36*1,0)))} | AI61: =IF($A61="",-1,SUM(C61:AF61)-IFERROR(B61,999)/100000) -> -1

Sheet Ranglijst
A1: Rang | B1: Team | C1: Score | D1: {=IFERROR(IF(COLUMNS($D1:D1)<=Beheer!$C$4,IF(LEFT(INDEX(Beheer!$C$7:$C$36,COLUMNS($D1:D1)),6)="Ronde ","R"&MID(INDEX(Beheer!$C$7:$C$36,COLUMNS($D1:D1)),7,10),LEFT(INDEX(Beheer!$C$7:$C$36,COLUMNS($D1:D1)),7)),""),"")} -> Rond de | E1: {=IFERROR(IF(COLUMNS($D1:E1)<=Beheer!$C$4,IF(LEFT(INDEX(Beheer!$C$7:$C$36,COLUMNS($D1:E1)),6)="Ronde ","R"&MID(INDEX(Beheer!$C$7:$C$36,COLUMNS($D1:E1)),7,10),LEFT(INDEX(Beheer!$C$7:$C$36,COLUMNS($D1:E1)),7)),""),"")} -> Woordsl | F1: {=IFERROR(IF(COLUMNS($D1:F1)<=Beheer!$C$4,IF(LEFT(INDEX(Beheer!$C$7:$C$36,COLUMNS($D1:F1)),6)="Ronde ","R"&MID(INDEX(Beheer!$C$7:$C$36,COLUMNS($D1:F1)),7,10),LEFT(INDEX(Beheer!$C$7:$C$36,COLUMNS($D1:F1)),7)),""),"")} -> Lokaal | G1: {=IFERROR(IF(COLUMNS($D1:G1)<=Beheer!$C$4,IF(LEFT(INDEX(Beheer!$C$7:$C$36,COLUMNS($D1:G1)),6)="Ronde ","R"&MID(INDEX(Beheer!$C$7:$C$36,COLUMNS($D1:G1)),7,10),LEFT(INDEX(Beheer!$C$7:$C$36,COLUMNS($D1:G1)),7)),""),"")} -> Tussenr | H1: {=IFERROR(IF(COLUMNS($D1:H1)<=Beheer!$C$4,IF(LEFT(INDEX(Beheer!$C$7:$C$36,COLUMNS($D1:H1)),6)="Ronde ","R"&MID(INDEX(Beheer!$C$7:$C$36,COLUMNS($D1:H1)),7,10),LEFT(INDEX(Beheer!$C$7:$C$36,COLUMNS($D1:H1)),7)),""),"")} -> Actua | I1: {=IFERROR(IF(COLUMNS($D1:I1)<=Beheer!$C$4,IF(LEFT(INDEX(Beheer!$C$7:$C$36,COLUMNS($D1:I1)),6)="Ronde ","R"&MID(INDEX(Beheer!$C$7:$C$36,COLUMNS($D1:I1)),7,10),LEFT(INDEX(Beheer!$C$7:$C$36,COLUMNS($D1:I1)),7)),""),"")} -> Film | J1: {=IFERROR(IF(COLUMNS($D1:J1)<=Beheer!$C$4,IF(LEFT(INDEX(Beheer!$C$7:$C$36,COLUMNS($D1:J1)),6)="Ronde ","R"&MID(INDEX(Beheer!$C$7:$C$36,COLUMNS($D1:J1)),7,10),LEFT(INDEX(Beheer!$C$7:$C$36,COLUMNS($D1:J1)),7)),""),"")} -> Fauna e | K1: {=IFERROR(IF(COLUMNS($D1:K1)<=Beheer!$C$4,IF(LEFT(INDEX(Beheer!$C$7:$C$36,COLUMNS($D1:K1)),6)="Ronde ","R"&MID(INDEX(Beheer!$C$7:$C$36,COLUMNS($D1:K1)),7,10),LEFT(INDEX(Beheer!$C$7:$C$36,COLUMNS($D1:K1)),7)),""),"")} -> Tussenr | ... AF1: {=IFERROR(IF(COLUMNS($D1:AF1)<=Beheer!$C$4,IF(LEFT(INDEX(Beheer!$C$7:$C$36,COLUMNS($D1:AF1)),6)="Ronde ","R"&MID(INDEX(Beheer!$C$7:$C$36,COLUMNS($D1:AF1)),7,10),LEFT(INDEX(Beheer!$C$7:$C$36,COLUMNS($D1:AF1)),7)),""),"")} | AG1: {=IFERROR(IF(COLUMNS($D1:AG1)<=Beheer!$C$4,IF(LEFT(INDEX(Beheer!$C$7:$C$36,COLUMNS($D1:AG1)),6)="Round ","R"&MID(INDEX(Beheer!$C$7:$C$36,COLUMNS($D1:AG1)),7,10),LEFT(INDEX(Beheer!$C$7:$C$36,COLUMNS($D1:AG1)),7)),""),"")}
A2: =IF(ROWS($A$2:A2)>COUNTA(Beheer!$F$7:$F$66),"",ROWS($A$2:A2)) -> 1 | B2: =IF($A2="","",INDEX(Dashboard!$A$2:$A$61,MATCH(LARGE(Dashboard!$AI$2:$AI$61,$A2),Dashboard!$AI$2:$AI$61,0))) -> Schele Vanthilt | C2: =IF($A2="","",INDEX(Dashboard!$AG$2:$AG$61,MATCH(LARGE(Dashboard!$AI$2:$AI$61,$A2),Dashboard!$AI$2:$AI$61,0))&" / "&INDEX(Dashboard!$AH$2:$AH$61,MATCH(LARGE(Dashboard!$AI$2:$AI$61,$A2),Dashboard!$AI$2:$AI$61,0))) -> 96 / 130 | D2: {=IF(OR($A2="",COLUMNS($D2:D2)>Beheer!$C$4),"",N(INDEX(Dashboard!$C$2:$AF$61,MATCH(LARGE(Dashboard!$AI$2:$AI$61,$A2),Dashboard!$AI$2:$AI$61,0),COLUMNS($D2:D2)))&"/"&INDEX(Beheer!$B$7:$B$36,COLUMNS($D2:D2)))} -> 10/10 | E2: {=IF(OR($A2="",COLUMNS($D2:E2)>Beheer!$C$4),"",N(INDEX(Dashboard!$C$2:$AF$61,MATCH(LARGE(Dashboard!$AI$2:$AI$61,$A2),Dashboard!$AI$2:$AI$61,0),COLUMNS($D2:E2)))&"/"&INDEX(Beheer!$B$7:$B$36,COLUMNS($D2:E2)))} -> 8/10 | F2: {=IF(OR($A2="",COLUMNS($D2:F2)>Beheer!$C$4),"",N(INDEX(Dashboard!$C$2:$AF$61,MATCH(LARGE(Dashboard!$AI$2:$AI$61,$A2),Dashboard!$AI$2:$AI$61,0),COLUMNS($D2:F2)))&"/"&INDEX(Beheer!$B$7:$B$36,COLUMNS($D2:F2)))} -> 1/10 | G2: {=IF(OR($A2="",COLUMNS($D2:G2)>Beheer!$C$4),"",N(INDEX(Dashboard!$C$2:$AF$61,MATCH(LARGE(Dashboard!$AI$2:$AI$61,$A2),Dashboard!$AI$2:$AI$61,0),COLUMNS($D2:G2)))&"/"&INDEX(Beheer!$B$7:$B$36,COLUMNS($D2:G2)))} -> 20/20 | H2: {=IF(OR($A2="",COLUMNS($D2:H2)>Beheer!$C$4),"",N(INDEX(Dashboard!$C$2:$AF$61,MATCH(LARGE(Dashboard!$AI$2:$AI$61,$A2),Dashboard!$AI$2:$AI$61,0),COLUMNS($D2:H2)))&"/"&INDEX(Beheer!$B$7:$B$36,COLUMNS($D2:H2)))} -> 4/10 | I2: {=IF(OR($A2="",COLUMNS($D2:I2)>Beheer!$C$4),"",N(INDEX(Dashboard!$C$2:$AF$61,MATCH(LARGE(Dashboard!$AI$2:$AI$61,$A2),Dashboard!$AI$2:$AI$61,0),COLUMNS($D2:I2)))&"/"&INDEX(Beheer!$B$7:$B$36,COLUMNS($D2:I2)))} -> 7/10 | J2: {=IF(OR($A2="",COLUMNS($D2:J2)>Beheer!$C$4),"",N(INDEX(Dashboard!$C$2:$AF$61,MATCH(LARGE(Dashboard!$AI$2:$AI$61,$A2),Dashboard!$AI$2:$AI$61,0),COLUMNS($D2:J2)))&"/"&INDEX(Beheer!$B$7:$B$36,COLUMNS($D2:J2)))} -> 7/10 | K2: {=IF(OR($A2="",COLUMNS($D2:K2)>Beheer!$C$4),"",N(INDEX(Dashboard!$C$2:$AF$61,MATCH(LARGE(Dashboard!$AI$2:$AI$61,$A2),Dashboard!$AI$2:$AI$61,0),COLUMNS($D2:K2)))&"/"&INDEX(Beheer!$B$7:$B$36,COLUMNS($D2:K2)))} -> 13/15 | ... AG2: {=IF(OR($A2="",COLUMNS($D2:AG2)>Beheer!$C$4),"",N(INDEX(Dashboard!$C$2:$AF$61,MATCH(LARGE(Dashboard!$AI$2:$AI$61,$A2),Dashboard!$AI$2:$AI$61,0),COLUMNS($D2:AG2)))&"/"&INDEX(Beheer!$B$7:$B$36,COLUMNS($D2:AG2)))}
A3: =IF(ROWS($A$2:A3)>COUNTA(Beheer!$F$7:$F$66),"",ROWS($A$2:A3)) -> 2 | B3: =IF($A3="","",INDEX(Dashboard!$A$2:$A$61,MATCH(LARGE(Dashboard!$AI$2:$AI$61,$A3),Dashboard!$AI$2:$AI$61,0))) -> Boeren met Verstand | C3: =IF($A3="","",INDEX(Dashboard!$AG$2:$AG$61,MATCH(LARGE(Dashboard!$AI$2:$AI$61,$A3),Dashboard!$AI$2:$AI$61,0))&" / "&INDEX(Dashboard!$AH$2:$AH$61,MATCH(LARGE(Dashboard!$AI$2:$AI$61,$A3),Dashboard!$AI$2:$AI$61,0))) -> 88 / 130 | D3: {=IF(OR($A3="",COLUMNS($D3:D3)>Beheer!$C$4),"",N(INDEX(Dashboard!$C$2:$AF$61,MATCH(LARGE(Dashboard!$AI$2:$AI$61,$A3),Dashboard!$AI$2:$AI$61,0),COLUMNS($D3:D3)))&"/"&INDEX(Beheer!$B$7:$B$36,COLUMNS($D3:D3)))} -> 8/10 | E3: {=IF(OR($A3="",COLUMNS($D3:E3)>Beheer!$C$4),"",N(INDEX(Dashboard!$C$2:$AF$61,MATCH(LARGE(Dashboard!$AI$2:$AI$61,$A3),Dashboard!$AI$2:$AI$61,0),COLUMNS($D3:E3)))&"/"&INDEX(Beheer!$B$7:$B$36,COLUMNS($D3:E3)))} -> 5/10 | F3: {=IF(OR($A3="",COLUMNS($D3:F3)>Beheer!$C$4),"",N(INDEX(Dashboard!$C$2:$AF$61,MATCH(LARGE(Dashboard!$AI$2:$AI$61,$A3),Dashboard!$AI$2:$AI$61,0),COLUMNS($D3:F3)))&"/"&INDEX(Beheer!$B$7:$B$36,COLUMNS($D3:F3)))} -> 3/10 | G3: {=IF(OR($A3="",COLUMNS($D3:G3)>Beheer!$C$4),"",N(INDEX(Dashboard!$C$2:$AF$61,MATCH(LARGE(Dashboard!$AI$2:$AI$61,$A3),Dashboard!$AI$2:$AI$61,0),COLUMNS($D3:G3)))&"/"&INDEX(Beheer!$B$7:$B$36,COLUMNS($D3:G3)))} -> 18/20 | H3: {=IF(OR($A3="",COLUMNS($D3:H3)>Beheer!$C$4),"",N(INDEX(Dashboard!$C$2:$AF$61,MATCH(LARGE(Dashboard!$AI$2:$AI$61,$A3),Dashboard!$AI$2:$AI$61,0),COLUMNS($D3:H3)))&"/"&INDEX(Beheer!$B$7:$B$36,COLUMNS($D3:H3)))} -> 8/10 | I3: {=IF(OR($A3="",COLUMNS($D3:I3)>Beheer!$C$4),"",N(INDEX(Dashboard!$C$2:$AF$61,MATCH(LARGE(Dashboard!$AI$2:$AI$61,$A3),Dashboard!$AI$2:$AI$61,0),COLUMNS($D3:I3)))&"/"&INDEX(Beheer!$B$7:$B$36,COLUMNS($D3:I3)))} -> 3/10 | J3: {=IF(OR($A3="",COLUMNS($D3:J3)>Beheer!$C$4),"",N(INDEX(Dashboard!$C$2:$AF$61,MATCH(LARGE(Dashboard!$AI$2:$AI$61,$A3),Dashboard!$AI$2:$AI$61,0),COLUMNS($D3:J3)))&"/"&INDEX(Beheer!$B$7:$B$36,COLUMNS($D3:J3)))} -> 8/10 | K3: {=IF(OR($A3="",COLUMNS($D3:K3)>Beheer!$C$4),"",N(INDEX(Dashboard!$C$2:$AF$61,MATCH(LARGE(Dashboard!$AI$2:$AI$61,$A3),Dashboard!$AI$2:$AI$61,0),COLUMNS($D3:K3)))&"/"&INDEX(Beheer!$B$7:$B$36,COLUMNS($D3:K3)))} -> 15/15 | ... AG3: {=IF(OR($A3="",COLUMNS($D3:AG3)>Beheer!$C$4),"",N(INDEX(Dashboard!$C$2:$AF$61,MATCH(LARGE(Dashboard!$AI$2:$AI$61,$A3),Dashboard!$AI$2:$AI$61,0),COLUMNS($D3:AG3)))&"/"&INDEX(Beheer!$B$7:$B$36,COLUMNS($D3:AG3)))}
A4: =IF(ROWS($A$2:A4)>COUNTA(Beheer!$F$7:$F$66),"",ROWS($A$2:A4)) -> 3 | B4: =IF($A4="","",INDEX(Dashboard!$A$2:$A$61,MATCH(LARGE(Dashboard!$AI$2:$AI$61,$A4),Dashboard!$AI$2:$AI$61,0))) -> Tjevenbende | C4: =IF($A4="","",INDEX(Dashboard!$AG$2:$AG$61,MATCH(LARGE(Dashboard!$AI$2:$AI$61,$A4),Dashboard!$AI$2:$AI$61,0))&" / "&INDEX(Dashboard!$AH$2:$AH$61,MATCH(LARGE(Dashboard!$AI$2:$AI$61,$A4),Dashboard!$AI$2:$AI$61,0))) -> 82 / 130 | D4: {=IF(OR($A4="",COLUMNS($D4:D4)>Beheer!$C$4),"",N(INDEX(Dashboard!$C$2:$AF$61,MATCH(LARGE(Dashboard!$AI$2:$AI$61,$A4),Dashboard!$AI$2:$AI$61,0),COLUMNS($D4:D4)))&"/"&INDEX(Beheer!$B$7:$B$36,COLUMNS($D4:D4)))} -> 3/10 | E4: {=IF(OR($A4="",COLUMNS($D4:E4)>Beheer!$C$4),"",N(INDEX(Dashboard!$C$2:$AF$61,MATCH(LARGE(Dashboard!$AI$2:$AI$61,$A4),Dashboard!$AI$2:$AI$61,0),COLUMNS($D4:E4)))&"/"&INDEX(Beheer!$B$7:$B$36,COLUMNS($D4:E4)))} -> 10/10 | F4: {=IF(OR($A4="",COLUMNS($D4:F4)>Beheer!$C$4),"",N(INDEX(Dashboard!$C$2:$AF$61,MATCH(LARGE(Dashboard!$AI$2:$AI$61,$A4),Dashboard!$AI$2:$AI$61,0),COLUMNS($D4:F4)))&"/"&INDEX(Beheer!$B$7:$B$36,COLUMNS($D4:F4)))} -> 3/10 | G4: {=IF(OR($A4="",COLUMNS($D4:G4)>Beheer!$C$4),"",N(INDEX(Dashboard!$C$2:$AF$61,MATCH(LARGE(Dashboard!$AI$2:$AI$61,$A4),Dashboard!$AI$2:$AI$61,0),COLUMNS($D4:G4)))&"/"&INDEX(Beheer!$B$7:$B$36,COLUMNS($D4:G4)))} -> 14/20 | H4: {=IF(OR($A4="",COLUMNS($D4:H4)>Beheer!$C$4),"",N(INDEX(Dashboard!$C$2:$AF$61,MATCH(LARGE(Dashboard!$AI$2:$AI$61,$A4),Dashboard!$AI$2:$AI$61,0),COLUMNS($D4:H4)))&"/"&INDEX(Beheer!$B$7:$B$36,COLUMNS($D4:H4)))} -> 8/10 | I4: {=IF(OR($A4="",COLUMNS($D4:I4)>Beheer!$C$4),"",N(INDEX(Dashboard!$C$2:$AF$61,MATCH(LARGE(Dashboard!$AI$2:$AI$61,$A4),Dashboard!$AI$2:$AI$61,0),COLUMNS($D4:I4)))&"/"&INDEX(Beheer!$B$7:$B$36,COLUMNS($D4:I4)))} -> 10/10 | J4: {=IF(OR($A4="",COLUMNS($D4:J4)>Beheer!$C$4),"",N(INDEX(Dashboard!$C$2:$AF$61,MATCH(LARGE(Dashboard!$AI$2:$AI$61,$A4),Dashboard!$AI$2:$AI$61,0),COLUMNS($D4:J4)))&"/"&INDEX(Beheer!$B$7:$B$36,COLUMNS($D4:J4)))} -> 3/10 | K4: {=IF(OR($A4="",COLUMNS($D4:K4)>Beheer!$C$4),"",N(INDEX(Dashboard!$C$2:$AF$61,MATCH(LARGE(Dashboard!$AI$2:$AI$61,$A4),Dashboard!$AI$2:$AI$61,0),COLUMNS($D4:K4)))&"/"&INDEX(Beheer!$B$7:$B$36,COLUMNS($D4:K4)))} -> 11/15 | ... AG4: {=IF(OR($A4="",COLUMNS($D4:AG4)>Beheer!$C$4),"",N(INDEX(Dashboard!$C$2:$AF$61,MATCH(LARGE(Dashboard!$AI$2:$AI$61,$A4),Dashboard!$AI$2:$AI$61,0),COLUMNS($D4:AG4)))&"/"&INDEX(Beheer!$B$7:$B$36,COLUMNS($D4:AG4)))}
A5: =IF(ROWS($A$2:A5)>COUNTA(Beheer!$F$7:$F$66),"",ROWS($A$2:A5)) -> 4 | B5: =IF($A5="","",INDEX(Dashboard!$A$2:$A$61,MATCH(LARGE(Dashboard!$AI$2:$AI$61,$A5),Dashboard!$AI$2:$AI$61,0))) -> De Stoute Schoenen | C5: =IF($A5="","",INDEX(Dashboard!$AG$2:$AG$61,MATCH(LARGE(Dashboard!$AI$2:$AI$61,$A5),Dashboard!$AI$2:$AI$61,0))&" / "&INDEX(Dashboard!$AH$2:$AH$61,MATCH(LARGE(Dashboard!$AI$2:$AI$61,$A5),Dashboard!$AI$2:$AI$61,0))) -> 82 / 130 | D5: {=IF(OR($A5="",COLUMNS($D5:D5)>Beheer!$C$4),"",N(INDEX(Dashboard!$C$2:$AF$61,MATCH(LARGE(Dashboard!$AI$2:$AI$61,$A5),Dashboard!$AI$2:$AI$61,0),COLUMNS($D5:D5)))&"/"&INDEX(Beheer!$B$7:$B$36,COLUMNS($D5:D5)))} -> 8/10 | E5: {=IF(OR($A5="",COLUMNS($D5:E5)>Beheer!$C$4),"",N(INDEX(Dashboard!$C$2:$AF$61,MATCH(LARGE(Dashboard!$AI$2:$AI$61,$A5),Dashboard!$AI$2:$AI$61,0),COLUMNS($D5:E5)))&"/"&INDEX(Beheer!$B$7:$B$36,COLUMNS($D5:E5)))} -> 9/10 | F5: {=IF(OR($A5="",COLUMNS($D5:F5)>Beheer!$C$4),"",N(INDEX(Dashboard!$C$2:$AF$61,MATCH(LARGE(Dashboard!$AI$2:$AI$61,$A5),Dashboard!$AI$2:$AI$61,0),COLUMNS($D5:F5)))&"/"&INDEX(Beheer!$B$7:$B$36,COLUMNS($D5:F5)))} -> 5/10 | G5: {=IF(OR($A5="",COLUMNS($D5:G5)>Beheer!$C$4),"",N(INDEX(Dashboard!$C$2:$AF$61,MATCH(LARGE(Dashboard!$AI$2:$AI$61,$A5),Dashboard!$AI$2:$AI$61,0),COLUMNS($D5:G5)))&"/"&INDEX(Beheer!$B$7:$B$36,COLUMNS($D5:G5)))} -> 20/20 | H5: {=IF(OR($A5="",COLUMNS($D5:H5)>Beheer!$C$4),"",N(INDEX(Dashboard!$C$2:$AF$61,MATCH(LARGE(Dashboard!$AI$2:$AI$61,$A5),Dashboard!$AI$2:$AI$61,0),COLUMNS($D5:H5)))&"/"&INDEX(Beheer!$B$7:$B$36,COLUMNS($D5:H5)))} -> 3/10 | I5: {=IF(OR($A5="",COLUMNS($D5:I5)>Beheer!$C$4),"",N(INDEX(Dashboard!$C$2:$AF$61,MATCH(LARGE(Dashboard!$AI$2:$AI$61,$A5),Dashboard!$AI$2:$AI$61,0),COLUMNS($D5:I5)))&"/"&INDEX(Beheer!$B$7:$B$36,COLUMNS($D5:I5)))} -> 8/10 | J5: {=IF(OR($A5="",COLUMNS($D5:J5)>Beheer!$C$4),"",N(INDEX(Dashboard!$C$2:$AF$61,MATCH(LARGE(Dashboard!$AI$2:$AI$61,$A5),Dashboard!$AI$2:$AI$61,0),COLUMNS($D5:J5)))&"/"&INDEX(Beheer!$B$7:$B$36,COLUMNS($D5:J5)))} -> 7/10 | K5: {=IF(OR($A5="",COLUMNS($D5:K5)>Beheer!$C$4),"",N(INDEX(Dashboard!$C$2:$AF$61,MATCH(LARGE(Dashboard!$AI$2:$AI$61,$A5),Dashboard!$AI$2:$AI$61,0),COLUMNS($D5:K5)))&"/"&INDEX(Beheer!$B$7:$B$36,COLUMNS($D5:K5)))} -> 13/15 | ... AG5: {=IF(OR($A5="",COLUMNS($D5:AG5)>Beheer!$C$4),"",N(INDEX(Dashboard!$C$2:$AF$61,MATCH(LARGE(Dashboard!$AI$2:$AI$61,$A5),Dashboard!$AI$2:$AI$61,0),COLUMNS($D5:AG5)))&"/"&INDEX(Beheer!$B$7:$B$36,COLUMNS($D5:AG5)))}
A6: =IF(ROWS($A$2:A6)>COUNTA(Beheer!$F$7:$F$66),"",ROWS($A$2:A6)) -> 5 | B6: =IF($A6="","",INDEX(Dashboard!$A$2:$A$61,MATCH(LARGE(Dashboard!$AI$2:$AI$61,$A6),Dashboard!$AI$2:$AI$61,0))) -> De Plezante Pintjes | C6: =IF($A6="","",INDEX(Dashboard!$AG$2:$AG$61,MATCH(LARGE(Dashboard!$AI$2:$AI$61,$A6),Dashboard!$AI$2:$AI$61,0))&" / "&INDEX(Dashboard!$AH$2:$AH$61,MATCH(LARGE(Dashboard!$AI$2:$AI$61,$A6),Dashboard!$AI$2:$AI$61,0))) -> 81 / 130 | D6: {=IF(OR($A6="",COLUMNS($D6:D6)>Beheer!$C$4),"",N(INDEX(Dashboard!$C$2:$AF$61,MATCH(LARGE(Dashboard!$AI$2:$AI$61,$A6),Dashboard!$AI$2:$AI$61,0),COLUMNS($D6:D6)))&"/"&INDEX(Beheer!$B$7:$B$36,COLUMNS($D6:D6)))} -> 7/10 | E6: {=IF(OR($A6="",COLUMNS($D6:E6)>Beheer!$C$4),"",N(INDEX(Dashboard!$C$2:$AF$61,MATCH(LARGE(Dashboard!$AI$2:$AI$61,$A6),Dashboard!$AI$2:$AI$61,0),COLUMNS($D6:E6)))&"/"&INDEX(Beheer!$B$7:$B$36,COLUMNS($D6:E6)))} -> 6/10 | F6: {=IF(OR($A6="",COLUMNS($D6:F6)>Beheer!$C$4),"",N(INDEX(Dashboard!$C$2:$AF$61,MATCH(LARGE(Dashboard!$AI$2:$AI$61,$A6),Dashboard!$AI$2:$AI$61,0),COLUMNS($D6:F6)))&"/"&INDEX(Beheer!$B$7:$B$36,COLUMNS($D6:F6)))} -> 3/10 | G6: {=IF(OR($A6="",COLUMNS($D6:G6)>Beheer!$C$4),"",N(INDEX(Dashboard!$C$2:$AF$61,MATCH(LARGE(Dashboard!$AI$2:$AI$61,$A6),Dashboard!$AI$2:$AI$61,0),COLUMNS($D6:G6)))&"/"&INDEX(Beheer!$B$7:$B$36,COLUMNS($D6:G6)))} -> 5/20 | H6: {=IF(OR($A6="",COLUMNS($D6:H6)>Beheer!$C$4),"",N(INDEX(Dashboard!$C$2:$AF$61,MATCH(LARGE(Dashboard!$AI$2:$AI$61,$A6),Dashboard!$AI$2:$AI$61,0),COLUMNS($D6:H6)))&"/"&INDEX(Beheer!$B$7:$B$36,COLUMNS($D6:H6)))} -> 10/10 | I6: {=IF(OR($A6="",COLUMNS($D6:I6)>Beheer!$C$4),"",N(INDEX(Dashboard!$C$2:$AF$61,MATCH(LARGE(Dashboard!$AI$2:$AI$61,$A6),Dashboard!$AI$2:$AI$61,0),COLUMNS($D6:I6)))&"/"&INDEX(Beheer!$B$7:$B$36,COLUMNS($D6:I6)))} -> 6/10 | J6: {=IF(OR($A6="",COLUMNS($D6:J6)>Beheer!$C$4),"",N(INDEX(Dashboard!$C$2:$AF$61,MATCH(LARGE(Dashboard!$AI$2:$AI$61,$A6),Dashboard!$AI$2:$AI$61,0),COLUMNS($D6:J6)))&"/"&INDEX(Beheer!$B$7:$B$36,COLUMNS($D6:J6)))} -> 10/10 | K6: {=IF(OR($A6="",COLUMNS($D6:K6)>Beheer!$C$4),"",N(INDEX(Dashboard!$C$2:$AF$61,MATCH(LARGE(Dashboard!$AI$2:$AI$61,$A6),Dashboard!$AI$2:$AI$61,0),COLUMNS($D6:K6)))&"/"&INDEX(Beheer!$B$7:$B$36,COLUMNS($D6:K6)))} -> 11/15 | ... AG6: {=IF(OR($A6="",COLUMNS($D6:AG6)>Beheer!$C$4),"",N(INDEX(Dashboard!$C$2:$AF$61,MATCH(LARGE(Dashboard!$AI$2:$AI$61,$A6),Dashboard!$AI$2:$AI$61,0),COLUMNS($D6:AG6)))&"/"&INDEX(Beheer!$B$7:$B$36,COLUMNS($D6:AG6)))}
A7: =IF(ROWS($A$2:A7)>COUNTA(Beheer!$F$7:$F$66),"",ROWS($A$2:A7)) -> 6 | B7: =IF($A7="","",INDEX(Dashboard!$A$2:$A$61,MATCH(LARGE(Dashboard!$AI$2:$AI$61,$A7),Dashboard!$AI$2:$AI$61,0))) -> Manneke Pis & Co | C7: =IF($A7="","",INDEX(Dashboard!$AG$2:$AG$61,MATCH(LARGE(Dashboard!$AI$2:$AI$61,$A7),Dashboard!$AI$2:$AI$61,0))&" / "&INDEX(Dashboard!$AH$2:$AH$61,MATCH(LARGE(Dashboard!$AI$2:$AI$61,$A7),Dashboard!$AI$2:$AI$61,0))) -> 80 / 130 | D7: {=IF(OR($A7="",COLUMNS($D7:D7)>Beheer!$C$4),"",N(INDEX(Dashboard!$C$2:$AF$61,MATCH(LARGE(Dashboard!$AI$2:$AI$61,$A7),Dashboard!$AI$2:$AI$61,0),COLUMNS($D7:D7)))&"/"&INDEX(Beheer!$B$7:$B$36,COLUMNS($D7:D7)))} -> 10/10 | E7: {=IF(OR($A7="",COLUMNS($D7:E7)>Beheer!$C$4),"",N(INDEX(Dashboard!$C$2:$AF$61,MATCH(LARGE(Dashboard!$AI$2:$AI$61,$A7),Dashboard!$AI$2:$AI$61,0),COLUMNS($D7:E7)))&"/"&INDEX(Beheer!$B$7:$B$36,COLUMNS($D7:E7)))} -> 8/10 | F7: {=IF(OR($A7="",COLUMNS($D7:F7)>Beheer!$C$4),"",N(INDEX(Dashboard!$C$2:$AF$61,MATCH(LARGE(Dashboard!$AI$2:$AI$61,$A7),Dashboard!$AI$2:$AI$61,0),COLUMNS($D7:F7)))&"/"&INDEX(Beheer!$B$7:$B$36,COLUMNS($D7:F7)))} -> 9/10 | G7: {=IF(OR($A7="",COLUMNS($D7:G7)>Beheer!$C$4),"",N(INDEX(Dashboard!$C$2:$AF$61,MATCH(LARGE(Dashboard!$AI$2:$AI$61,$A7),Dashboard!$AI$2:$AI$61,0),COLUMNS($D7:G7)))&"/"&INDEX(Beheer!$B$7:$B$36,COLUMNS($D7:G7)))} -> 4/20 | H7: {=IF(OR($A7="",COLUMNS($D7:H7)>Beheer!$C$4),"",N(INDEX(Dashboard!$C$2:$AF$61,MATCH(LARGE(Dashboard!$AI$2:$AI$61,$A7),Dashboard!$AI$2:$AI$61,0),COLUMNS($D7:H7)))&"/"&INDEX(Beheer!$B$7:$B$36,COLUMNS($D7:H7)))} -> 9/10 | I7: {=IF(OR($A7="",COLUMNS($D7:I7)>Beheer!$C$4),"",N(INDEX(Dashboard!$C$2:$AF$61,MATCH(LARGE(Dashboard!$AI$2:$AI$61,$A7),Dashboard!$AI$2:$AI$61,0),COLUMNS($D7:I7)))&"/"&INDEX(Beheer!$B$7:$B$36,COLUMNS($D7:I7)))} -> 10/10 | J7: {=IF(OR($A7="",COLUMNS($D7:J7)>Beheer!$C$4),"",N(INDEX(Dashboard!$C$2:$AF$61,MATCH(LARGE(Dashboard!$AI$2:$AI$61,$A7),Dashboard!$AI$2:$AI$61,0),COLUMNS($D7:J7)))&"/"&INDEX(Beheer!$B$7:$B$36,COLUMNS($D7:J7)))} -> 6/10 | K7: {=IF(OR($A7="",COLUMNS($D7:K7)>Beheer!$C$4),"",N(INDEX(Dashboard!$C$2:$AF$61,MATCH(LARGE(Dashboard!$AI$2:$AI$61,$A7),Dashboard!$AI$2:$AI$61,0),COLUMNS($D7:K7)))&"/"&INDEX(Beheer!$B$7:$B$36,COLUMNS($D7:K7)))} -> 2/15 | ... AG7: {=IF(OR($A7="",COLUMNS($D7:AG7)>Beheer!$C$4),"",N(INDEX(Dashboard!$C$2:$AF$61,MATCH(LARGE(Dashboard!$AI$2:$AI$61,$A7),Dashboard!$AI$2:$AI$61,0),COLUMNS($D7:AG7)))&"/"&INDEX(Beheer!$B$7:$B$36,COLUMNS($D7:AG7)))}
A8: =IF(ROWS($A$2:A8)>COUNTA(Beheer!$F$7:$F$66),"",ROWS($A$2:A8)) -> 7 | B8: =IF($A8="","",INDEX(Dashboard!$A$2:$A$61,MATCH(LARGE(Dashboard!$AI$2:$AI$61,$A8),Dashboard!$AI$2:$AI$61,0))) -> De Goe Goesting | C8: =IF($A8="","",INDEX(Dashboard!$AG$2:$AG$61,MATCH(LARGE(Dashboard!$AI$2:$AI$61,$A8),Dashboard!$AI$2:$AI$61,0))&" / "&INDEX(Dashboard!$AH$2:$AH$61,MATCH(LARGE(Dashboard!$AI$2:$AI$61,$A8),Dashboard!$AI$2:$AI$61,0))) -> 80 / 130 | D8: {=IF(OR($A8="",COLUMNS($D8:D8)>Beheer!$C$4),"",N(INDEX(Dashboard!$C$2:$AF$61,MATCH(LARGE(Dashboard!$AI$2:$AI$61,$A8),Dashboard!$AI$2:$AI$61,0),COLUMNS($D8:D8)))&"/"&INDEX(Beheer!$B$7:$B$36,COLUMNS($D8:D8)))} -> 1/10 | E8: {=IF(OR($A8="",COLUMNS($D8:E8)>Beheer!$C$4),"",N(INDEX(Dashboard!$C$2:$AF$61,MATCH(LARGE(Dashboard!$AI$2:$AI$61,$A8),Dashboard!$AI$2:$AI$61,0),COLUMNS($D8:E8)))&"/"&INDEX(Beheer!$B$7:$B$36,COLUMNS($D8:E8)))} -> 8/10 | F8: {=IF(OR($A8="",COLUMNS($D8:F8)>Beheer!$C$4),"",N(INDEX(Dashboard!$C$2:$AF$61,MATCH(LARGE(Dashboard!$AI$2:$AI$61,$A8),Dashboard!$AI$2:$AI$61,0),COLUMNS($D8:F8)))&"/"&INDEX(Beheer!$B$7:$B$36,COLUMNS($D8:F8)))} -> 7/10 | G8: {=IF(OR($A8="",COLUMNS($D8:G8)>Beheer!$C$4),"",N(INDEX(Dashboard!$C$2:$AF$61,MATCH(LARGE(Dashboard!$AI$2:$AI$61,$A8),Dashboard!$AI$2:$AI$61,0),COLUMNS($D8:G8)))&"/"&INDEX(Beheer!$B$7:$B$36,COLUMNS($D8:G8)))} -> 10/20 | H8: {=IF(OR($A8="",COLUMNS($D8:H8)>Beheer!$C$4),"",N(INDEX(Dashboard!$C$2:$AF$61,MATCH(LARGE(Dashboard!$AI$2:$AI$61,$A8),Dashboard!$AI$2:$AI$61,0),COLUMNS($D8:H8)))&"/"&INDEX(Beheer!$B$7:$B$36,COLUMNS($D8:H8)))} -> 9/10 | I8: {=IF(OR($A8="",COLUMNS($D8:I8)>Beheer!$C$4),"",N(INDEX(Dashboard!$C$2:$AF$61,MATCH(LARGE(Dashboard!$AI$2:$AI$61,$A8),Dashboard!$AI$2:$AI$61,0),COLUMNS($D8:I8)))&"/"&INDEX(Beheer!$B$7:$B$36,COLUMNS($D8:I8)))} -> 9/10 | J8: {=IF(OR($A8="",COLUMNS($D8:J8)>Beheer!$C$4),"",N(INDEX(Dashboard!$C$2:$AF$61,MATCH(LARGE(Dashboard!$AI$2:$AI$61,$A8),Dashboard!$AI$2:$AI$61,0),COLUMNS($D8:J8)))&"/"&INDEX(Beheer!$B$7:$B$36,COLUMNS($D8:J8)))} -> 4/10 | K8: {=IF(OR($A8="",COLUMNS($D8:K8)>Beheer!$C$4),"",N(INDEX(Dashboard!$C$2:$AF$61,MATCH(LARGE(Dashboard!$AI$2:$AI$61,$A8),Dashboard!$AI$2:$AI$61,0),COLUMNS($D8:K8)))&"/"&INDEX(Beheer!$B$7:$B$36,COLUMNS($D8:K8)))} -> 7/15 | ... AG8: {=IF(OR($A8="",COLUMNS($D8:AG8)>Beheer!$C$4),"",N(INDEX(Dashboard!$C$2:$AF$61,MATCH(LARGE(Dashboard!$AI$2:$AI$61,$A8),Dashboard!$AI$2:$AI$61,0),COLUMNS($D8:AG8)))&"/"&INDEX(Beheer!$B$7:$B$36,COLUMNS($D8:AG8)))}
A9: =IF(ROWS($A$2:A9)>COUNTA(Beheer!$F$7:$F$66),"",ROWS($A$2:A9)) -> 8 | B9: =IF($A9="","",INDEX(Dashboard!$A$2:$A$61,MATCH(LARGE(Dashboard!$AI$2:$AI$61,$A9),Dashboard!$AI$2:$AI$61,0))) -> De Lambiek Liga | C9: =IF($A9="","",INDEX(Dashboard!$AG$2:$AG$61,MATCH(LARGE(Dashboard!$AI$2:$AI$61,$A9),Dashboard!$AI$2:$AI$61,0))&" / "&INDEX(Dashboard!$AH$2:$AH$61,MATCH(LARGE(Dashboard!$AI$2:$AI$61,$A9),Dashboard!$AI$2:$AI$61,0))) -> 79 / 130 | D9: {=IF(OR($A9="",COLUMNS($D9:D9)>Beheer!$C$4),"",N(INDEX(Dashboard!$C$2:$AF$61,MATCH(LARGE(Dashboard!$AI$2:$AI$61,$A9),Dashboard!$AI$2:$AI$61,0),COLUMNS($D9:D9)))&"/"&INDEX(Beheer!$B$7:$B$36,COLUMNS($D9:D9)))} -> 10/10 | E9: {=IF(OR($A9="",COLUMNS($D9:E9)>Beheer!$C$4),"",N(INDEX(Dashboard!$C$2:$AF$61,MATCH(LARGE(Dashboard!$AI$2:$AI$61,$A9),Dashboard!$AI$2:$AI$61,0),COLUMNS($D9:E9)))&"/"&INDEX(Beheer!$B$7:$B$36,COLUMNS($D9:E9)))} -> 2/10 | F9: {=IF(OR($A9="",COLUMNS($D9:F9)>Beheer!$C$4),"",N(INDEX(Dashboard!$C$2:$AF$61,MATCH(LARGE(Dashboard!$AI$2:$AI$61,$A9),Dashboard!$AI$2:$AI$61,0),COLUMNS($D9:F9)))&"/"&INDEX(Beheer!$B$7:$B$36,COLUMNS($D9:F9)))} -> 2/10 | G9: {=IF(OR($A9="",COLUMNS($D9:G9)>Beheer!$C$4),"",N(INDEX(Dashboard!$C$2:$AF$61,MATCH(LARGE(Dashboard!$AI$2:$AI$61,$A9),Dashboard!$AI$2:$AI$61,0),COLUMNS($D9:G9)))&"/"&INDEX(Beheer!$B$7:$B$36,COLUMNS($D9:G9)))} -> 7/20 | H9: {=IF(OR($A9="",COLUMNS($D9:H9)>Beheer!$C$4),"",N(INDEX(Dashboard!$C$2:$AF$61,MATCH(LARGE(Dashboard!$AI$2:$AI$61,$A9),Dashboard!$AI$2:$AI$61,0),COLUMNS($D9:H9)))&"/"&INDEX(Beheer!$B$7:$B$36,COLUMNS($D9:H9)))} -> 6/10 | I9: {=IF(OR($A9="",COLUMNS($D9:I9)>Beheer!$C$4),"",N(INDEX(Dashboard!$C$2:$AF$61,MATCH(LARGE(Dashboard!$AI$2:$AI$61,$A9),Dashboard!$AI$2:$AI$61,0),COLUMNS($D9:I9)))&"/"&INDEX(Beheer!$B$7:$B$36,COLUMNS($D9:I9)))} -> 9/10 | J9: {=IF(OR($A9="",COLUMNS($D9:J9)>Beheer!$C$4),"",N(INDEX(Dashboard!$C$2:$AF$61,MATCH(LARGE(Dashboard!$AI$2:$AI$61,$A9),Dashboard!$AI$2:$AI$61,0),COLUMNS($D9:J9)))&"/"&INDEX(Beheer!$B$7:$B$36,COLUMNS($D9:J9)))} -> 8/10 | K9: {=IF(OR($A9="",COLUMNS($D9:K9)>Beheer!$C$4),"",N(INDEX(Dashboard!$C$2:$AF$61,MATCH(LARGE(Dashboard!$AI$2:$AI$61,$A9),Dashboard!$AI$2:$AI$61,0),COLUMNS($D9:K9)))&"/"&INDEX(Beheer!$B$7:$B$36,COLUMNS($D9:K9)))} -> 13/15 | ... AG9: {=IF(OR($A9="",COLUMNS($D9:AG9)>Beheer!$C$4),"",N(INDEX(Dashboard!$C$2:$AF$61,MATCH(LARGE(Dashboard!$AI$2:$AI$61,$A9),Dashboard!$AI$2:$AI$61,0),COLUMNS($D9:AG9)))&"/"&INDEX(Beheer!$B$7:$B$36,COLUMNS($D9:AG9)))}
A10: =IF(ROWS($A$2:A10)>COUNTA(Beheer!$F$7:$F$66),"",ROWS($A$2:A10)) -> 9 | B10: =IF($A10="","",INDEX(Dashboard!$A$2:$A$61,MATCH(LARGE(Dashboard!$AI$2:$AI$61,$A10),Dashboard!$AI$2:$AI$61,0))) -> De Zatte Garnaal | C10: =IF($A10="","",INDEX(Dashboard!$AG$2:$AG$61,MATCH(LARGE(Dashboard!$AI$2:$AI$61,$A10),Dashboard!$AI$2:$AI$61,0))&" / "&INDEX(Dashboard!$AH$2:$AH$61,MATCH(LARGE(Dashboard!$AI$2:$AI$61,$A10),Dashboard!$AI$2:$AI$61,0))) -> 79 / 130 | D10: {=IF(OR($A10="",COLUMNS($D10:D10)>Beheer!$C$4),"",N(INDEX(Dashboard!$C$2:$AF$61,MATCH(LARGE(Dashboard!$AI$2:$AI$61,$A10),Dashboard!$AI$2:$AI$61,0),COLUMNS($D10:D10)))&"/"&INDEX(Beheer!$B$7:$B$36,COLUMNS($D10:D10)))} -> 7/10 | E10: {=IF(OR($A10="",COLUMNS($D10:E10)>Beheer!$C$4),"",N(INDEX(Dashboard!$C$2:$AF$61,MATCH(LARGE(Dashboard!$AI$2:$AI$61,$A10),Dashboard!$AI$2:$AI$61,0),COLUMNS($D10:E10)))&"/"&INDEX(Beheer!$B$7:$B$36,COLUMNS($D10:E10)))} -> 7/10 | F10: {=IF(OR($A10="",COLUMNS($D10:F10)>Beheer!$C$4),"",N(INDEX(Dashboard!$C$2:$AF$61,MATCH(LARGE(Dashboard!$AI$2:$AI$61,$A10),Dashboard!$AI$2:$AI$61,0),COLUMNS($D10:F10)))&"/"&INDEX(Beheer!$B$7:$B$36,COLUMNS($D10:F10)))} -> 4/10 | G10: {=IF(OR($A10="",COLUMNS($D10:G10)>Beheer!$C$4),"",N(INDEX(Dashboard!$C$2:$AF$61,MATCH(LARGE(Dashboard!$AI$2:$AI$61,$A10),Dashboard!$AI$2:$AI$61,0),COLUMNS($D10:G10)))&"/"&INDEX(Beheer!$B$7:$B$36,COLUMNS($D10:G10)))} -> 12/20 | H10: {=IF(OR($A10="",COLUMNS($D10:H10)>Beheer!$C$4),"",N(INDEX(Dashboard!$C$2:$AF$61,MATCH(LARGE(Dashboard!$AI$2:$AI$61,$A10),Dashboard!$AI$2:$AI$61,0),COLUMNS($D10:H10)))&"/"&INDEX(Beheer!$B$7:$B$36,COLUMNS($D10:H10)))} -> 9/10 | I10: {=IF(OR($A10="",COLUMNS($D10:I10)>Beheer!$C$4),"",N(INDEX(Dashboard!$C$2:$AF$61,MATCH(LARGE(Dashboard!$AI$2:$AI$61,$A10),Dashboard!$AI$2:$AI$61,0),COLUMNS($D10:I10)))&"/"&INDEX(Beheer!$B$7:$B$36,COLUMNS($D10:I10)))} -> 3/10 | J10: {=IF(OR($A10="",COLUMNS($D10:J10)>Beheer!$C$4),"",N(INDEX(Dashboard!$C$2:$AF$61,MATCH(LARGE(Dashboard!$AI$2:$AI$61,$A10),Dashboard!$AI$2:$AI$61,0),COLUMNS($D10:J10)))&"/"&INDEX(Beheer!$B$7:$B$36,COLUMNS($D10:J10)))} -> 7/10 | K10: {=IF(OR($A10="",COLUMNS($D10:K10)>Beheer!$C$4),"",N(INDEX(Dashboard!$C$2:$AF$61,MATCH(LARGE(Dashboard!$AI$2:$AI$61,$A10),Dashboard!$AI$2:$AI$61,0),COLUMNS($D10:K10)))&"/"&INDEX(Beheer!$B$7:$B$36,COLUMNS($D10:K10)))} -> 10/15 | ... AG10: {=IF(OR($A10="",COLUMNS($D10:AG10)>Beheer!$C$4),"",N(INDEX(Dashboard!$C$2:$AF$61,MATCH(LARGE(Dashboard!$AI$2:$AI$61,$A10),Dashboard!$AI$2:$AI$61,0),COLUMNS($D10:AG10)))&"/"&INDEX(Beheer!$B$7:$B$36,COLUMNS($D10:AG10)))}
A11: =IF(ROWS($A$2:A11)>COUNTA(Beheer!$F$7:$F$66),"",ROWS($A$2:A11)) -> 10 | B11: =IF($A11="","",INDEX(Dashboard!$A$2:$A$61,MATCH(LARGE(Dashboard!$AI$2:$AI$61,$A11),Dashboard!$AI$2:$AI$61,0))) -> Amai Zeg! | C11: =IF($A11="","",INDEX(Dashboard!$AG$2:$AG$61,MATCH(LARGE(Dashboard!$AI$2:$AI$61,$A11),Dashboard!$AI$2:$AI$61,0))&" / "&INDEX(Dashboard!$AH$2:$AH$61,MATCH(LARGE(Dashboard!$AI$2:$AI$61,$A11),Dashboard!$AI$2:$AI$61,0))) -> 76 / 130 | D11: {=IF(OR($A11="",COLUMNS($D11:D11)>Beheer!$C$4),"",N(INDEX(Dashboard!$C$2:$AF$61,MATCH(LARGE(Dashboard!$AI$2:$AI$61,$A11),Dashboard!$AI$2:$AI$61,0),COLUMNS($D11:D11)))&"/"&INDEX(Beheer!$B$7:$B$36,COLUMNS($D11:D11)))} -> 10/10 | E11: {=IF(OR($A11="",COLUMNS($D11:E11)>Beheer!$C$4),"",N(INDEX(Dashboard!$C$2:$AF$61,MATCH(LARGE(Dashboard!$AI$2:$AI$61,$A11),Dashboard!$AI$2:$AI$61,0),COLUMNS($D11:E11)))&"/"&INDEX(Beheer!$B$7:$B$36,COLUMNS($D11:E11)))} -> 8/10 | F11: {=IF(OR($A11="",COLUMNS($D11:F11)>Beheer!$C$4),"",N(INDEX(Dashboard!$C$2:$AF$61,MATCH(LARGE(Dashboard!$AI$2:$AI$61,$A11),Dashboard!$AI$2:$AI$61,0),COLUMNS($D11:F11)))&"/"&INDEX(Beheer!$B$7:$B$36,COLUMNS($D11:F11)))} -> 8/10 | G11: {=IF(OR($A11="",COLUMNS($D11:G11)>Beheer!$C$4),"",N(INDEX(Dashboard!$C$2:$AF$61,MATCH(LARGE(Dashboard!$AI$2:$AI$61,$A11),Dashboard!$AI$2:$AI$61,0),COLUMNS($D11:G11)))&"/"&INDEX(Beheer!$B$7:$B$36,COLUMNS($D11:G11)))} -> 13/20 | H11: {=IF(OR($A11="",COLUMNS($D11:H11)>Beheer!$C$4),"",N(INDEX(Dashboard!$C$2:$AF$61,MATCH(LARGE(Dashboard!$AI$2:$AI$61,$A11),Dashboard!$AI$2:$AI$61,0),COLUMNS($D11:H11)))&"/"&INDEX(Beheer!$B$7:$B$36,COLUMNS($D11:H11)))} -> 3/10 | I11: {=IF(OR($A11="",COLUMNS($D11:I11)>Beheer!$C$4),"",N(INDEX(Dashboard!$C$2:$AF$61,MATCH(LARGE(Dashboard!$AI$2:$AI$61,$A11),Dashboard!$AI$2:$AI$61,0),COLUMNS($D11:I11)))&"/"&INDEX(Beheer!$B$7:$B$36,COLUMNS($D11:I11)))} -> 3/10 | J11: {=IF(OR($A11="",COLUMNS($D11:J11)>Beheer!$C$4),"",N(INDEX(Dashboard!$C$2:$AF$61,MATCH(LARGE(Dashboard!$AI$2:$AI$61,$A11),Dashboard!$AI$2:$AI$61,0),COLUMNS($D11:J11)))&"/"&INDEX(Beheer!$B$7:$B$36,COLUMNS($D11:J11)))} -> 2/10 | K11: {=IF(OR($A11="",COLUMNS($D11:K11)>Beheer!$C$4),"",N(INDEX(Dashboard!$C$2:$AF$61,MATCH(LARGE(Dashboard!$AI$2:$AI$61,$A11),Dashboard!$AI$2:$AI$61,0),COLUMNS($D11:K11)))&"/"&INDEX(Beheer!$B$7:$B$36,COLUMNS($D11:K11)))} -> 7/15 | ... AG11: {=IF(OR($A11="",COLUMNS($D11:AG11)>Beheer!$C$4),"",N(INDEX(Dashboard!$C$2:$AF$61,MATCH(LARGE(Dashboard!$AI$2:$AI$61,$A11),Dashboard!$AI$2:$AI$61,0),COLUMNS($D11:AG11)))&"/"&INDEX(Beheer!$B$7:$B$36,COLUMNS($D11:AG11)))}
A12: =IF(ROWS($A$2:A12)>COUNTA(Beheer!$F$7:$F$66),"",ROWS($A$2:A12)) -> 11 | B12: =IF($A12="","",INDEX(Dashboard!$A$2:$A$61,MATCH(LARGE(Dashboard!$AI$2:$AI$61,$A12),Dashboard!$AI$2:$AI$61,0))) -> Pataten met Stoofvlees | C12: =IF($A12="","",INDEX(Dashboard!$AG$2:$AG$61,MATCH(LARGE(Dashboard!$AI$2:$AI$61,$A12),Dashboard!$AI$2:$AI$61,0))&" / "&INDEX(Dashboard!$AH$2:$AH$61,MATCH(LARGE(Dashboard!$AI$2:$AI$61,$A12),Dashboard!$AI$2:$AI$61,0))) -> 74 / 130 | D12: {=IF(OR($A12="",COLUMNS($D12:D12)>Beheer!$C$4),"",N(INDEX(Dashboard!$C$2:$AF$61,MATCH(LARGE(Dashboard!$AI$2:$AI$61,$A12),Dashboard!$AI$2:$AI$61,0),COLUMNS($D12:D12)))&"/"&INDEX(Beheer!$B$7:$B$36,COLUMNS($D12:D12)))} -> 10/10 | E12: {=IF(OR($A12="",COLUMNS($D12:E12)>Beheer!$C$4),"",N(INDEX(Dashboard!$C$2:$AF$61,MATCH(LARGE(Dashboard!$AI$2:$AI$61,$A12),Dashboard!$AI$2:$AI$61,0),COLUMNS($D12:E12)))&"/"&INDEX(Beheer!$B$7:$B$36,COLUMNS($D12:E12)))} -> 10/10 | F12: {=IF(OR($A12="",COLUMNS($D12:F12)>Beheer!$C$4),"",N(INDEX(Dashboard!$C$2:$AF$61,MATCH(LARGE(Dashboard!$AI$2:$AI$61,$A12),Dashboard!$AI$2:$AI$61,0),COLUMNS($D12:F12)))&"/"&INDEX(Beheer!$B$7:$B$36,COLUMNS($D12:F12)))} -> 1/10 | G12: {=IF(OR($A12="",COLUMNS($D12:G12)>Beheer!$C$4),"",N(INDEX(Dashboard!$C$2:$AF$61,MATCH(LARGE(Dashboard!$AI$2:$AI$61,$A12),Dashboard!$AI$2:$AI$61,0),COLUMNS($D12:G12)))&"/"&INDEX(Beheer!$B$7:$B$36,COLUMNS($D12:G12)))} -> 11/20 | H12: {=IF(OR($A12="",COLUMNS($D12:H12)>Beheer!$C$4),"",N(INDEX(Dashboard!$C$2:$AF$61,MATCH(LARGE(Dashboard!$AI$2:$AI$61,$A12),Dashboard!$AI$2:$AI$61,0),COLUMNS($D12:H12)))&"/"&INDEX(Beheer!$B$7:$B$36,COLUMNS($D12:H12)))} -> 4/10 | I12: {=IF(OR($A12="",COLUMNS($D12:I12)>Beheer!$C$4),"",N(INDEX(Dashboard!$C$2:$AF$61,MATCH(LARGE(Dashboard!$AI$2:$AI$61,$A12),Dashboard!$AI$2:$AI$61,0),COLUMNS($D12:I12)))&"/"&INDEX(Beheer!$B$7:$B$36,COLUMNS($D12:I12)))} -> 2/10 | J12: {=IF(OR($A12="",COLUMNS($D12:J12)>Beheer!$C$4),"",N(INDEX(Dashboard!$C$2:$AF$61,MATCH(LARGE(Dashboard!$AI$2:$AI$61,$A12),Dashboard!$AI$2:$AI$61,0),COLUMNS($D12:J12)))&"/"&INDEX(Beheer!$B$7:$B$36,COLUMNS($D12:J12)))} -> 4/10 | K12: {=IF(OR($A12="",COLUMNS($D12:K12)>Beheer!$C$4),"",N(INDEX(Dashboard!$C$2:$AF$61,MATCH(LARGE(Dashboard!$AI$2:$AI$61,$A12),Dashboard!$AI$2:$AI$61,0),COLUMNS($D12:K12)))&"/"&INDEX(Beheer!$B$7:$B$36,COLUMNS($D12:K12)))} -> 10/15 | ... AG12: {=IF(OR($A12="",COLUMNS($D12:AG12)>Beheer!$C$4),"",N(INDEX(Dashboard!$C$2:$AF$61,MATCH(LARGE(Dashboard!$AI$2:$AI$61,$A12),Dashboard!$AI$2:$AI$61,0),COLUMNS($D12:AG12)))&"/"&INDEX(Beheer!$B$7:$B$36,COLUMNS($D12:AG12)))}
A13: =IF(ROWS($A$2:A13)>COUNTA(Beheer!$F$7:$F$66),"",ROWS($A$2:A13)) -> 12 | B13: =IF($A13="","",INDEX(Dashboard!$A$2:$A$61,MATCH(LARGE(Dashboard!$AI$2:$AI$61,$A13),Dashboard!$AI$2:$AI$61,0))) -> Smoutebollen FC | C13: =IF($A13="","",INDEX(Dashboard!$AG$2:$AG$61,MATCH(LARGE(Dashboard!$AI$2:$AI$61,$A13),Dashboard!$AI$2:$AI$61,0))&" / "&INDEX(Dashboard!$AH$2:$AH$61,MATCH(LARGE(Dashboard!$AI$2:$AI$61,$A13),Dashboard!$AI$2:$AI$61,0))) -> 74 / 130 | D13: {=IF(OR($A13="",COLUMNS($D13:D13)>Beheer!$C$4),"",N(INDEX(Dashboard!$C$2:$AF$61,MATCH(LARGE(Dashboard!$AI$2:$AI$61,$A13),Dashboard!$AI$2:$AI$61,0),COLUMNS($D13:D13)))&"/"&INDEX(Beheer!$B$7:$B$36,COLUMNS($D13:D13)))} -> 9/10 | E13: {=IF(OR($A13="",COLUMNS($D13:E13)>Beheer!$C$4),"",N(INDEX(Dashboard!$C$2:$AF$61,MATCH(LARGE(Dashboard!$AI$2:$AI$61,$A13),Dashboard!$AI$2:$AI$61,0),COLUMNS($D13:E13)))&"/"&INDEX(Beheer!$B$7:$B$36,COLUMNS($D13:E13)))} -> 10/10 | F13: {=IF(OR($A13="",COLUMNS($D13:F13)>Beheer!$C$4),"",N(INDEX(Dashboard!$C$2:$AF$61,MATCH(LARGE(Dashboard!$AI$2:$AI$61,$A13),Dashboard!$AI$2:$AI$61,0),COLUMNS($D13:F13)))&"/"&INDEX(Beheer!$B$7:$B$36,COLUMNS($D13:F13)))} -> 5/10 | G13: {=IF(OR($A13="",COLUMNS($D13:G13)>Beheer!$C$4),"",N(INDEX(Dashboard!$C$2:$AF$61,MATCH(LARGE(Dashboard!$AI$2:$AI$61,$A13),Dashboard!$AI$2:$AI$61,0),COLUMNS($D13:G13)))&"/"&INDEX(Beheer!$B$7:$B$36,COLUMNS($D13:G13)))} -> 1/20 | H13: {=IF(OR($A13="",COLUMNS($D13:H13)>Beheer!$C$4),"",N(INDEX(Dashboard!$C$2:$AF$61,MATCH(LARGE(Dashboard!$AI$2:$AI$61,$A13),Dashboard!$AI$2:$AI$61,0),COLUMNS($D13:H13)))&"/"&INDEX(Beheer!$B$7:$B$36,COLUMNS($D13:H13)))} -> 10/10 | I13: {=IF(OR($A13="",COLUMNS($D13:I13)>Beheer!$C$4),"",N(INDEX(Dashboard!$C$2:$AF$61,MATCH(LARGE(Dashboard!$AI$2:$AI$61,$A13),Dashboard!$AI$2:$AI$61,0),COLUMNS($D13:I13)))&"/"&INDEX(Beheer!$B$7:$B$36,COLUMNS($D13:I13)))} -> 3/10 | J13: {=IF(OR($A13="",COLUMNS($D13:J13)>Beheer!$C$4),"",N(INDEX(Dashboard!$C$2:$AF$61,MATCH(LARGE(Dashboard!$AI$2:$AI$61,$A13),Dashboard!$AI$2:$AI$61,0),COLUMNS($D13:J13)))&"/"&INDEX(Beheer!$B$7:$B$36,COLUMNS($D13:J13)))} -> 9/10 | K13: {=IF(OR($A13="",COLUMNS($D13:K13)>Beheer!$C$4),"",N(INDEX(Dashboard!$C$2:$AF$61,MATCH(LARGE(Dashboard!$AI$2:$AI$61,$A13),Dashboard!$AI$2:$AI$61,0),COLUMNS($D13:K13)))&"/"&INDEX(Beheer!$B$7:$B$36,COLUMNS($D13:K13)))} -> 9/15 | ... AG13: {=IF(OR($A13="",COLUMNS($D13:AG13)>Beheer!$C$4),"",N(INDEX(Dashboard!$C$2:$AF$61,MATCH(LARGE(Dashboard!$AI$2:$AI$61,$A13),Dashboard!$AI$2:$AI$61,0),COLUMNS($D13:AG13)))&"/"&INDEX(Beheer!$B$7:$B$36,COLUMNS($D13:AG13)))}
... A61: =IF(ROWS($A$2:A61)>COUNTA(Beheer!$F$7:$F$66),"",ROWS($A$2:A61)) | B61: =IF($A61="","",INDEX(Dashboard!$A$2:$A$61,MATCH(LARGE(Dashboard!$AI$2:$AI$61,$A61),Dashboard!$AI$2:$AI$61,0))) | C61: =IF($A61="","",INDEX(Dashboard!$AG$2:$AG$61,MATCH(LARGE(Dashboard!$AI$2:$AI$61,$A61),Dashboard!$AI$2:$AI$61,0))&" / "&INDEX(Dashboard!$AH$2:$AH$61,MATCH(LARGE(Dashboard!$AI$2:$AI$61,$A61),Dashboard!$AI$2:$AI$61,0))) | D61: {=IF(OR($A61="",COLUMNS($D61:D61)>Beheer!$C$4),"",N(INDEX(Dashboard!$C$2:$AF$61,MATCH(LARGE(Dashboard!$AI$2:$AI$61,$A61),Dashboard!$AI$2:$AI$61,0),COLUMNS($D61:D61)))&"/"&INDEX(Beheer!$B$7:$B$36,COLUMNS($D61:D61)))} | E61: {=IF(OR($A61="",COLUMNS($D61:E61)>Beheer!$C$4),"",N(INDEX(Dashboard!$C$2:$AF$61,MATCH(LARGE(Dashboard!$AI$2:$AI$61,$A61),Dashboard!$AI$2:$AI$61,0),COLUMNS($D61:E61)))&"/"&INDEX(Beheer!$B$7:$B$36,COLUMNS($D61:E61)))} | F61: {=IF(OR($A61="",COLUMNS($D61:F61)>Beheer!$C$4),"",N(INDEX(Dashboard!$C$2:$AF$61,MATCH(LARGE(Dashboard!$AI$2:$AI$61,$A61),Dashboard!$AI$2:$AI$61,0),COLUMNS($D61:F61)))&"/"&INDEX(Beheer!$B$7:$B$36,COLUMNS($D61:F61)))} | G61: {=IF(OR($A61="",COLUMNS($D61:G61)>Beheer!$C$4),"",N(INDEX(Dashboard!$C$2:$AF$61,MATCH(LARGE(Dashboard!$AI$2:$AI$61,$A61),Dashboard!$AI$2:$AI$61,0),COLUMNS($D61:G61)))&"/"&INDEX(Beheer!$B$7:$B$36,COLUMNS($D61:G61)))} | H61: {=IF(OR($A61="",COLUMNS($D61:H61)>Beheer!$C$4),"",N(INDEX(Dashboard!$C$2:$AF$61,MATCH(LARGE(Dashboard!$AI$2:$AI$61,$A61),Dashboard!$AI$2:$AI$61,0),COLUMNS($D61:H61)))&"/"&INDEX(Beheer!$B$7:$B$36,COLUMNS($D61:H61)))} | I61: {=IF(OR($A61="",COLUMNS($D61:I61)>Beheer!$C$4),"",N(INDEX(Dashboard!$C$2:$AF$61,MATCH(LARGE(Dashboard!$AI$2:$AI$61,$A61),Dashboard!$AI$2:$AI$61,0),COLUMNS($D61:I61)))&"/"&INDEX(Beheer!$B$7:$B$36,COLUMNS($D61:I61)))} | J61: {=IF(OR($A61="",COLUMNS($D61:J61)>Beheer!$C$4),"",N(INDEX(Dashboard!$C$2:$AF$61,MATCH(LARGE(Dashboard!$AI$2:$AI$61,$A61),Dashboard!$AI$2:$AI$61,0),COLUMNS($D61:J61)))&"/"&INDEX(Beheer!$B$7:$B$36,COLUMNS($D61:J61)))} | K61: {=IF(OR($A61="",COLUMNS($D61:K61)>Beheer!$C$4),"",N(INDEX(Dashboard!$C$2:$AF$61,MATCH(LARGE(Dashboard!$AI$2:$AI$61,$A61),Dashboard!$AI$2:$AI$61,0),COLUMNS($D61:K61)))&"/"&INDEX(Beheer!$B$7:$B$36,COLUMNS($D61:K61)))} | ... AG61: {=IF(OR($A61="",COLUMNS($D61:AG61)>Beheer!$C$4),"",N(INDEX(Dashboard!$C$2:$AF$61,MATCH(LARGE(Dashboard!$AI$2:$AI$61,$A61),Dashboard!$AI$2:$AI$61,0),COLUMNS($D61:AG61)))&"/"&INDEX(Beheer!$B$7:$B$36,COLUMNS($D61:AG61)))}

Sheet Statistieken
B2: Quiz Statistieken
B5: Geaggregeerde inzichten over alle teams en rondes
V6: 📈 Moeilijkheidsgraad Ronde
B7: TEAMS | G7: RONDES | L7: TOTAAL PUNTEN | Q7: GEM / RONDE | V7: Rd | W7: Gem | X7: Max | Y7: Min | Z7: Moeilijkheid (langer = makkelijker) | AA7: % Perfect
V8: =IF(1<=Beheer!$C$4,"R1","") -> R1 | W8: =IF(1<=Beheer!$C$4,ROUND(AVERAGE(OFFSET(Dashboard!$B$2,0,1,COUNTA(Beheer!$F$7:$F$66),1)),1),"") -> 6.5 | X8: =IF(1<=Beheer!$C$4,MAX(OFFSET(Dashboard!$B$2,0,1,COUNTA(Beheer!$F$7:$F$66),1)),"") -> 10 | Y8: =IF(1<=Beheer!$C$4,MIN(OFFSET(Dashboard!$B$2,0,1,COUNTA(Beheer!$F$7:$F$66),1)),"") -> 1 | Z8: =IF(1<=Beheer!$C$4,REPT("█",ROUND(AVERAGE(OFFSET(Dashboard!$B$2,0,1,COUNTA(Beheer!$F$7:$F$66),1))/INDEX(Beheer!$B$7:$B$66,1)*20,0)),"") -> █████████████ | AA8: =IF(1<=Beheer!$C$4,TEXT(COUNTIF(OFFSET(Dashboard!$B$2,0,1,COUNTA(Beheer!$F$7:$F$66),1),INDEX(Beheer!$B$7:$B$66,1))/COUNTA(Beheer!$F$7:$F$66),"0%"),"") -> 28%
B9: =COUNTA(Beheer!F7:F36) -> 25 | G9: =Beheer!C4 -> 12 | L9: =SUM(Dashboard!C2:AF61) -> 1802 | Q9: =ROUND(AVERAGE(Dashboard!C2:AF61),1) -> 6 | V9: =IF(2<=Beheer!$C$4,"R2","") -> R2 | W9: =IF(2<=Beheer!$C$4,ROUND(AVERAGE(OFFSET(Dashboard!$B$2,0,2,COUNTA(Beheer!$F$7:$F$66),1)),1),"") -> 6.4 | X9: =IF(2<=Beheer!$C$4,MAX(OFFSET(Dashboard!$B$2,0,2,COUNTA(Beheer!$F$7:$F$66),1)),"") -> 10 | Y9: =IF(2<=Beheer!$C$4,MIN(OFFSET(Dashboard!$B$2,0,2,COUNTA(Beheer!$F$7:$F$66),1)),"") -> 1 | Z9: =IF(2<=Beheer!$C$4,REPT("█",ROUND(AVERAGE(OFFSET(Dashboard!$B$2,0,2,COUNTA(Beheer!$F$7:$F$66),1))/INDEX(Beheer!$B$7:$B$66,2)*20,0)),"") -> █████████████ | AA9: =IF(2<=Beheer!$C$4,TEXT(COUNTIF(OFFSET(Dashboard!$B$2,0,2,COUNTA(Beheer!$F$7:$F$66),1),INDEX(Beheer!$B$7:$B$66,2))/COUNTA(Beheer!$F$7:$F$66),"0%"),"") -> 20%
V10: =IF(3<=Beheer!$C$4,"R3","") -> R3 | W10: =IF(3<=Beheer!$C$4,ROUND(AVERAGE(OFFSET(Dashboard!$B$2,0,3,COUNTA(Beheer!$F$7:$F$66),1)),1),"") -> 4.3 | X10: =IF(3<=Beheer!$C$4,MAX(OFFSET(Dashboard!$B$2,0,3,COUNTA(Beheer!$F$7:$F$66),1)),"") -> 9 | Y10: =IF(3<=Beheer!$C$4,MIN(OFFSET(Dashboard!$B$2,0,3,COUNTA(Beheer!$F$7:$F$66),1)),"") -> 1 | Z10: =IF(3<=Beheer!$C$4,REPT("█",ROUND(AVERAGE(OFFSET(Dashboard!$B$2,0,3,COUNTA(Beheer!$F$7:$F$66),1))/INDEX(Beheer!$B$7:$B$66,3)*20,0)),"") -> █████████ | AA10: =IF(3<=Beheer!$C$4,TEXT(COUNTIF(OFFSET(Dashboard!$B$2,0,3,COUNTA(Beheer!$F$7:$F$66),1),INDEX(Beheer!$B$7:$B$66,3))/COUNTA(Beheer!$F$7:$F$66),"0%"),"") -> 0%
V11: =IF(4<=Beheer!$C$4,"R4","") -> R4 | W11: =IF(4<=Beheer!$C$4,ROUND(AVERAGE(OFFSET(Dashboard!$B$2,0,4,COUNTA(Beheer!$F$7:$F$66),1)),1),"") -> 9.8 | X11: =IF(4<=Beheer!$C$4,MAX(OFFSET(Dashboard!$B$2,0,4,COUNTA(Beheer!$F$7:$F$66),1)),"") -> 20 | Y11: =IF(4<=Beheer!$C$4,MIN(OFFSET(Dashboard!$B$2,0,4,COUNTA(Beheer!$F$7:$F$66),1)),"") -> 1 | Z11: =IF(4<=Beheer!$C$4,REPT("█",ROUND(AVERAGE(OFFSET(Dashboard!$B$2,0,4,COUNTA(Beheer!$F$7:$F$66),1))/INDEX(Beheer!$B$7:$B$66,4)*20,0)),"") -> ██████████ | AA11: =IF(4<=Beheer!$C$4,TEXT(COUNTIF(OFFSET(Dashboard!$B$2,0,4,COUNTA(Beheer!$F$7:$F$66),1),INDEX(Beheer!$B$7:$B$66,4))/COUNTA(Beheer!$F$7:$F$66),"0%"),"") -> 12%
B12: 📊 Score Verdeling | L12: 🎯 Spreiding Teamprestaties | V12: =IF(5<=Beheer!$C$4,"R5","") -> R5 | W12: =IF(5<=Beheer!$C$4,ROUND(AVERAGE(OFFSET(Dashboard!$B$2,0,5,COUNTA(Beheer!$F$7:$F$66),1)),1),"") -> 6.3 | X12: =IF(5<=Beheer!$C$4,MAX(OFFSET(Dashboard!$B$2,0,5,COUNTA(Beheer!$F$7:$F$66),1)),"") -> 10 | Y12: =IF(5<=Beheer!$C$4,MIN(OFFSET(Dashboard!$B$2,0,5,COUNTA(Beheer!$F$7:$F$66),1)),"") -> 1 | Z12: =IF(5<=Beheer!$C$4,REPT("█",ROUND(AVERAGE(OFFSET(Dashboard!$B$2,0,5,COUNTA(Beheer!$F$7:$F$66),1))/INDEX(Beheer!$B$7:$B$66,5)*20,0)),"") -> █████████████ | AA12: =IF(5<=Beheer!$C$4,TEXT(COUNTIF(OFFSET(Dashboard!$B$2,0,5,COUNTA(Beheer!$F$7:$F$66),1),INDEX(Beheer!$B$7:$B$66,5))/COUNTA(Beheer!$F$7:$F$66),"0%"),"") -> 16%
B13: Hoogste score in één ronde | J13: =MAX(Dashboard!C2:AF61)&" pnt" -> 20 pnt | L13: Beste teamtotaal | T13: =MAX(Dashboard!AG2:AG61)&" pnt" -> 96 pnt | V13: =IF(6<=Beheer!$C$4,"R6","") -> R6 | W13: =IF(6<=Beheer!$C$4,ROUND(AVERAGE(OFFSET(Dashboard!$B$2,0,6,COUNTA(Beheer!$F$7:$F$66),1)),1),"") -> 5.7 | X13: =IF(6<=Beheer!$C$4,MAX(OFFSET(Dashboard!$B$2,0,6,COUNTA(Beheer!$F$7:$F$66),1)),"") -> 10 | Y13: =IF(6<=Beheer!$C$4,MIN(OFFSET(Dashboard!$B$2,0,6,COUNTA(Beheer!$F$7:$F$66),1)),"") -> 1 | Z13: =IF(6<=Beheer!$C$4,REPT("█",ROUND(AVERAGE(OFFSET(Dashboard!$B$2,0,6,COUNTA(Beheer!$F$7:$F$66),1))/INDEX(Beheer!$B$7:$B$66,6)*20,0)),"") -> ███████████ | AA13: =IF(6<=Beheer!$C$4,TEXT(COUNTIF(OFFSET(Dashboard!$B$2,0,6,COUNTA(Beheer!$F$7:$F$66),1),INDEX(Beheer!$B$7:$B$66,6))/COUNTA(Beheer!$F$7:$F$66),"0%"),"") -> 12%
B14: Laagste score in één ronde | J14: =MIN(Dashboard!C2:AF61)&" pnt" -> 1 pnt | L14: Slechtste teamtotaal | T14: =MIN(Dashboard!AG2:AG61)&" pnt" -> 49 pnt | V14: =IF(7<=Beheer!$C$4,"R7","") -> R7 | W14: =IF(7<=Beheer!$C$4,ROUND(AVERAGE(OFFSET(Dashboard!$B$2,0,7,COUNTA(Beheer!$F$7:$F$66),1)),1),"") -> 5.9 | X14: =IF(7<=Beheer!$C$4,MAX(OFFSET(Dashboard!$B$2,0,7,COUNTA(Beheer!$F$7:$F$66),1)),"") -> 10 | Y14: =IF(7<=Beheer!$C$4,MIN(OFFSET(Dashboard!$B$2,0,7,COUNTA(Beheer!$F$7:$F$66),1)),"") -> 2 | Z14: =IF(7<=Beheer!$C$4,REPT("█",ROUND(AVERAGE(OFFSET(Dashboard!$B$2,0,7,COUNTA(Beheer!$F$7:$F$66),1))/INDEX(Beheer!$B$7:$B$66,7)*20,0)),"") -> ████████████ | AA14: =IF(7<=Beheer!$C$4,TEXT(COUNTIF(OFFSET(Dashboard!$B$2,0,7,COUNTA(Beheer!$F$7:$F$66),1),INDEX(Beheer!$B$7:$B$66,7))/COUNTA(Beheer!$F$7:$F$66),"0%"),"") -> 8%
B15: Mediaan rondescore | J15: =ROUND(MEDIAN(Dashboard!C2:AF61),1)&" pnt" -> 6 pnt | L15: Gemiddeld teamtotaal | T15: =ROUND(AVERAGE(Dashboard!AG2:AG61),1)&" pnt" -> 72,1 pnt | V15: =IF(8<=Beheer!$C$4,"R8","") -> R8 | W15: =IF(8<=Beheer!$C$4,ROUND(AVERAGE(OFFSET(Dashboard!$B$2,0,8,COUNTA(Beheer!$F$7:$F$66),1)),1),"") -> 8.1 | X15: =IF(8<=Beheer!$C$4,MAX(OFFSET(Dashboard!$B$2,0,8,COUNTA(Beheer!$F$7:$F$66),1)),"") -> 15 | Y15: =IF(8<=Beheer!$C$4,MIN(OFFSET(Dashboard!$B$2,0,8,COUNTA(Beheer!$F$7:$F$66),1)),"") -> 2 | Z15: =IF(8<=Beheer!$C$4,REPT("█",ROUND(AVERAGE(OFFSET(Dashboard!$B$2,0,8,COUNTA(Beheer!$F$7:$F$66),1))/INDEX(Beheer!$B$7:$B$66,8)*20,0)),"") -> ███████████ | AA15: =IF(8<=Beheer!$C$4,TEXT(COUNTIF(OFFSET(Dashboard!$B$2,0,8,COUNTA(Beheer!$F$7:$F$66),1),INDEX(Beheer!$B$7:$B$66,8))/COUNTA(Beheer!$F$7:$F$66),"0%"),"") -> 4%
B16: Standaarddeviatie van scores | J16: =ROUND(STDEV(Dashboard!C2:AF61),2) -> 3.58 | L16: Score verschil (beste − slechtste) | T16: =(MAX(Dashboard!AG2:AG61)-MIN(Dashboard!AG2:AG61))&" pnt" -> 47 pnt | V16: =IF(9<=Beheer!$C$4,"R9","") -> R9 | W16: =IF(9<=Beheer!$C$4,ROUND(AVERAGE(OFFSET(Dashboard!$B$2,0,9,COUNTA(Beheer!$F$7:$F$66),1)),1),"") -> 4.8 | X16: =IF(9<=Beheer!$C$4,MAX(OFFSET(Dashboard!$B$2,0,9,COUNTA(Beheer!$F$7:$F$66),1)),"") -> 10 | Y16: =IF(9<=Beheer!$C$4,MIN(OFFSET(Dashboard!$B$2,0,9,COUNTA(Beheer!$F$7:$F$66),1)),"") -> 1 | Z16: =IF(9<=Beheer!$C$4,REPT("█",ROUND(AVERAGE(OFFSET(Dashboard!$B$2,0,9,COUNTA(Beheer!$F$7:$F$66),1))/INDEX(Beheer!$B$7:$B$66,9)*20,0)),"") -> ██████████ | AA16: =IF(9<=Beheer!$C$4,TEXT(COUNTIF(OFFSET(Dashboard!$B$2,0,9,COUNTA(Beheer!$F$7:$F$66),1),INDEX(Beheer!$B$7:$B$66,9))/COUNTA(Beheer!$F$7:$F$66),"0%"),"") -> 4%
