Workbook

Sheet Management
A2: 🎯 Quiz Setup
A3: Configure rounds and teams — everything else updates automatically.
A4: ROUNDS | B4: Total rounds | C4: 13 | F4: TEAMS | H4: 💡 HOW IT WORKS
A6: # | B6: PTS | C6: NAME | F6: TEAM NAME | H6: Add or remove teams in column F
A7: =IF(ROW()-6<=$C$4,ROW()-6,"") -> 1 | B7: 10 | C7: Rond de wereld | F7: De Vliegende Stroopwafels | H7: Set total rounds in the peach box (C4)
A8: =IF(ROW()-6<=$C$4,ROW()-6,"") -> 2 | B8: 10 | C8: Woordslang | F8: Bietsende Bitterballen | H8: Edit max points per round in column B
A9: =IF(ROW()-6<=$C$4,ROW()-6,"") -> 3 | B9: 10 | C9: Lokaal | F9: De Dolle Klompendansers | H9: Rename rounds in column C
A10: =IF(ROW()-6<=$C$4,ROW()-6,"") -> 4 | B10: 20 | C10: Tussenronde 1 | F10: Kaaskoppen United | H10: Dashboard & Standings update automatically
A11: =IF(ROW()-6<=$C$4,ROW()-6,"") -> 5 | B11: 10 | C11: Actua | F11: De Hossende Haringen
A12: =IF(ROW()-6<=$C$4,ROW()-6,"") -> 6 | B12: 10 | C12: =IF(A12="","","Round "&A12) -> Round 6 | F12: Tulpen uit Toeterdam
A13: =IF(ROW()-6<=$C$4,ROW()-6,"") -> 7 | B13: 10 | C13: =IF(A13="","","Round "&A13) -> Round 7 | F13: De Pittige Pepernoten
A14: =IF(ROW()-6<=$C$4,ROW()-6,"") -> 8 | B14: 15 | C14: Tussenronde 2 | F14: Fietsende Frikandellen
A15: =IF(ROW()-6<=$C$4,ROW()-6,"") -> 9 | B15: 10 | C15: =IF(A15="","","Round "&A15) -> Round 9 | F15: De Gekke Gouwenaars
A16: =IF(ROW()-6<=$C$4,ROW()-6,"") -> 10 | B16: 10 | C16: =IF(A16="","","Round "&A16) -> Round 10 | F16: Stampende Stamppotters
A17: =IF(ROW()-6<=$C$4,ROW()-6,"") -> 11 | B17: 5 | C17: Doe-ronde | F17: Kwistet
A18: =IF(ROW()-6<=$C$4,ROW()-6,"") -> 12 | B18: 10 | C18: =IF(A18="","","Round "&A18) -> Round 12 | F18: Nogeenploeg
A19: =IF(ROW()-6<=$C$4,ROW()-6,"") -> 13 | B19: 10 | C19: =IF(A19="","","Round "&A19) -> Round 13 | F19: Team19
A20: =IF(ROW()-6<=$C$4,ROW()-6,"") | C20: =IF(A20="","","Round "&A20) | F20: Team20
A21: =IF(ROW()-6<=$C$4,ROW()-6,"") | C21: =IF(A21="","","Round "&A21) | F21: Team21
A22: =IF(ROW()-6<=$C$4,ROW()-6,"") | C22: =IF(A22="","","Round "&A22) | F22: Team22
A23: =IF(ROW()-6<=$C$4,ROW()-6,"") | C23: =IF(A23="","","Round "&A23) | F23: Team23
A24: =IF(ROW()-6<=$C$4,ROW()-6,"") | C24: =IF(A24="","","Round "&A24) | F24: Team24
A25: =IF(ROW()-6<=$C$4,ROW()-6,"") | C25: =IF(A25="","","Round "&A25) | F25: Team25
A26: =IF(ROW()-6<=$C$4,ROW()-6,"") | C26: =IF(A26="","","Round "&A26) | F26: Team26
A27: =IF(ROW()-6<=$C$4,ROW()-6,"") | C27: =IF(A27="","","Round "&A27) | F27: Team27
A28: =IF(ROW()-6<=$C$4,ROW()-6,"") | C28: =IF(A28="","","Round "&A28) | F28: Team28
A29: =IF(ROW()-6<=$C$4,ROW()-6,"") | C29: =IF(A29="","","Round "&A29) | F29: Team29
A30: =IF(ROW()-6<=$C$4,ROW()-6,"") | C30: =IF(A30="","","Round "&A30) | F30: Team30
A31: =IF(ROW()-6<=$C$4,ROW()-6,"") | C31: =IF(A31="","","Round "&A31) | F31: Team31
... A36: =IF(ROW()-6<=$C$4,ROW()-6,"") | C36: =IF(A36="","","Round "&A36) | F36: Team36
F37: Team37
F38: Team38
F39: Team39
F40: Team40
F41: Team41
F42: Team42
F43: Team43
F44: Team44
F45: Team45
F46: Team46
...

Sheet Dashboard
A1: Team | B1: Tie-break | C1: {=IFERROR(IF(COLUMNS($C1:C1)<=Management!$C$4,IF(LEFT(INDEX(Management!$C$7:$C$36,COLUMNS($C1:C1)),6)="Round ","R"&MID(INDEX(Management!$C$7:$C$36,COLUMNS($C1:C1)),7,10),LEFT(INDEX(Management!$C$7:$C$36,COLUMNS($C1:C1)),7))&" (/"&INDEX(Management!$B$7:$B$36,COLUMNS($C1:C1))&")",""),"")} -> Rond de (/10) | D1: {=IFERROR(IF(COLUMNS($C1:D1)<=Management!$C$4,IF(LEFT(INDEX(Management!$C$7:$C$36,COLUMNS($C1:D1)),6)="Round ","R"&MID(INDEX(Management!$C$7:$C$36,COLUMNS($C1:D1)),7,10),LEFT(INDEX(Management!$C$7:$C$36,COLUMNS($C1:D1)),7))&" (/"&INDEX(Management!$B$7:$B$36,COLUMNS($C1:D1))&")",""),"")} -> Woordsl (/10) | E1: {=IFERROR(IF(COLUMNS($C1:E1)<=Management!$C$4,IF(LEFT(INDEX(Management!$C$7:$C$36,COLUMNS($C1:E1)),6)="Round ","R"&MID(INDEX(Management!$C$7:$C$36,COLUMNS($C1:E1)),7,10),LEFT(INDEX(Management!$C$7:$C$36,COLUMNS($C1:E1)),7))&" (/"&INDEX(Management!$B$7:$B$36,COLUMNS($C1:E1))&")",""),"")} -> Lokaal (/10) | F1: {=IFERROR(IF(COLUMNS($C1:F1)<=Management!$C$4,IF(LEFT(INDEX(Management!$C$7:$C$36,COLUMNS($C1:F1)),6)="Round ","R"&MID(INDEX(Management!$C$7:$C$36,COLUMNS($C1:F1)),7,10),LEFT(INDEX(Management!$C$7:$C$36,COLUMNS($C1:F1)),7))&" (/"&INDEX(Management!$B$7:$B$36,COLUMNS($C1:F1))&")",""),"")} -> Tussenr (/20) | G1: {=IFERROR(IF(COLUMNS($C1:G1)<=Management!$C$4,IF(LEFT(INDEX(Management!$C$7:$C$36,COLUMNS($C1:G1)),6)="Round ","R"&MID(INDEX(Management!$C$7:$C$36,COLUMNS($C1:G1)),7,10),LEFT(INDEX(Management!$C$7:$C$36,COLUMNS($C1:G1)),7))&" (/"&INDEX(Management!$B$7:$B$36,COLUMNS($C1:G1))&")",""),"")} -> Actua (/10) | H1: {=IFERROR(IF(COLUMNS($C1:H1)<=Management!$C$4,IF(LEFT(INDEX(Management!$C$7:$C$36,COLUMNS($C1:H1)),6)="Round ","R"&MID(INDEX(Management!$C$7:$C$36,COLUMNS($C1:H1)),7,10),LEFT(INDEX(Management!$C$7:$C$36,COLUMNS($C1:H1)),7))&" (/"&INDEX(Management!$B$7:$B$36,COLUMNS($C1:H1))&")",""),"")} -> R6 (/10) | I1: {=IFERROR(IF(COLUMNS($C1:I1)<=Management!$C$4,IF(LEFT(INDEX(Management!$C$7:$C$36,COLUMNS($C1:I1)),6)="Round ","R"&MID(INDEX(Management!$C$7:$C$36,COLUMNS($C1:I1)),7,10),LEFT(INDEX(Management!$C$7:$C$36,COLUMNS($C1:I1)),7))&" (/"&INDEX(Management!$B$7:$B$36,COLUMNS($C1:I1))&")",""),"")} -> R7 (/10) | J1: {=IFERROR(IF(COLUMNS($C1:J1)<=Management!$C$4,IF(LEFT(INDEX(Management!$C$7:$C$36,COLUMNS($C1:J1)),6)="Round ","R"&MID(INDEX(Management!$C$7:$C$36,COLUMNS($C1:J1)),7,10),LEFT(INDEX(Management!$C$7:$C$36,COLUMNS($C1:J1)),7))&" (/"&INDEX(Management!$B$7:$B$36,COLUMNS($C1:J1))&")",""),"")} -> Tussenr (/15) | ... AF1: {=IFERROR(IF(COLUMNS($C1:AF1)<=Management!$C$4,IF(LEFT(INDEX(Management!$C$7:$C$36,COLUMNS($C1:AF1)),6)="Round ","R"&MID(INDEX(Management!$C$7:$C$36,COLUMNS($C1:AF1)),7,10),LEFT(INDEX(Management!$C$7:$C$36,COLUMNS($C1:AF1)),7))&" (/"&INDEX(Management!$B$7:$B$36,COLUMNS($C1:AF1))&")",""),"")} | AG1: Total | AH1: Max | AI1: Sort key
A2: {=IFERROR(IF(INDEX(Management!$F$7:$F$36,ROWS($A$2:A2))="","",INDEX(Management!$F$7:$F$36,ROWS($A$2:A2))),"")} -> De Vliegende Stroopwafels | B2: 2 | C2: 3 | D2: 4 | E2: 1 | F2: 5 | G2: 6 | H2: 10 | I2: 6 | J2: 15 | K2: 6 | L2: 6 | M2: 5 | N2: 6 | O2: 6 | AG2: =IF($A2="","",SUM(C2:AF2)) -> 79 | AH2: {=IF($A2="","",SUMPRODUCT((ROW(Management!$B$7:$B$36)-ROW(Management!$B$9)+1<=Management!$C$4)*IFERROR(Management!$B$7:$B$36*1,0)))} -> 140 | AI2: =IF($A2="",-1,SUM(C2:AF2)-IFERROR(B2,999)/100000) -> 78.99998
A3: {=IFERROR(IF(INDEX(Management!$F$7:$F$36,ROWS($A$2:A3))="","",INDEX(Management!$F$7:$F$36,ROWS($A$2:A3))),"")} -> Bietsende Bitterballen | B3: 10 | C3: 3 | D3: 4 | E3: 6 | F3: 1 | G3: 6 | H3: 8 | I3: 9 | J3: 5 | K3: 9 | L3: 9 | M3: 4 | N3: 9 | O3: 9 | AG3: =IF($A3="","",SUM(C3:AF3)) -> 82 | AH3: {=IF($A3="","",SUMPRODUCT((ROW(Management!$B$7:$B$36)-ROW(Management!$B$9)+1<=Management!$C$4)*IFERROR(Management!$B$7:$B$36*1,0)))} -> 140 | AI3: =IF($A3="",-1,SUM(C3:AF3)-IFERROR(B3,999)/100000) -> 81.9999
A4: {=IFERROR(IF(INDEX(Management!$F$7:$F$36,ROWS($A$2:A4))="","",INDEX(Management!$F$7:$F$36,ROWS($A$2:A4))),"")} -> De Dolle Klompendansers | B4: 6 | C4: 3 | D4: 6 | E4: 6 | F4: 5 | G4: 3 | H4: 4 | I4: 0 | J4: 11 | K4: 0 | L4: 0 | M4: 3 | N4: 0 | O4: 5 | AG4: =IF($A4="","",SUM(C4:AF4)) -> 46 | AH4: {=IF($A4="","",SUMPRODUCT((ROW(Management!$B$7:$B$36)-ROW(Management!$B$9)+1<=Management!$C$4)*IFERROR(Management!$B$7:$B$36*1,0)))} -> 140 | AI4: =IF($A4="",-1,SUM(C4:AF4)-IFERROR(B4,999)/100000) -> 45.99994
A5: {=IFERROR(IF(INDEX(Management!$F$7:$F$36,ROWS($A$2:A5))="","",INDEX(Management!$F$7:$F$36,ROWS($A$2:A5))),"")} -> Kaaskoppen United | B5: 3 | C5: 2 | D5: 10 | E5: 4 | F5: 17 | G5: 0 | H5: 10 | I5: 4 | J5: 12 | K5: 4 | L5: 4 | M5: 2 | N5: 4 | O5: 4 | AG5: =IF($A5="","",SUM(C5:AF5)) -> 77 | AH5: {=IF($A5="","",SUMPRODUCT((ROW(Management!$B$7:$B$36)-ROW(Management!$B$9)+1<=Management!$C$4)*IFERROR(Management!$B$7:$B$36*1,0)))} -> 140 | AI5: =IF($A5="",-1,SUM(C5:AF5)-IFERROR(B5,999)/100000) -> 76.99997
A6: {=IFERROR(IF(INDEX(Management!$F$7:$F$36,ROWS($A$2:A6))="","",INDEX(Management!$F$7:$F$36,ROWS($A$2:A6))),"")} -> De Hossende Haringen | B6: 9 | C6: 2 | D6: 9 | E6: 8 | F6: 3 | G6: 10 | H6: 0 | I6: 5 | J6: 9 | K6: 5 | L6: 5 | M6: 1 | N6: 5 | O6: 5 | AG6: =IF($A6="","",SUM(C6:AF6)) -> 67 | AH6: {=IF($A6="","",SUMPRODUCT((ROW(Management!$B$7:$B$36)-ROW(Management!$B$9)+1<=Management!$C$4)*IFERROR(Management!$B$7:$B$36*1,0)))} -> 140 | AI6: =IF($A6="",-1,SUM(C6:AF6)-IFERROR(B6,999)/100000) -> 66.99991
A7: {=IFERROR(IF(INDEX(Management!$F$7:$F$36,ROWS($A$2:A7))="","",INDEX(Management!$F$7:$F$36,ROWS($A$2:A7))),"")} -> Tulpen uit Toeterdam | B7: 1 | C7: 6 | D7: 10 | E7: 9 | F7: 10 | G7: 9 | H7: 4 | I7: 10 | J7: 9 | K7: 4 | L7: 3 | M7: 0 | N7: 4 | O7: 4 | AG7: =IF($A7="","",SUM(C7:AF7)) -> 82 | AH7: {=IF($A7="","",SUMPRODUCT((ROW(Management!$B$7:$B$36)-ROW(Management!$B$9)+1<=Management!$C$4)*IFERROR(Management!$B$7:$B$36*1,0)))} -> 140 | AI7: =IF($A7="",-1,SUM(C7:AF7)-IFERROR(B7,999)/100000) -> 81.99999
A8: {=IFERROR(IF(INDEX(Management!$F$7:$F$36,ROWS($A$2:A8))="","",INDEX(Management!$F$7:$F$36,ROWS($A$2:A8))),"")} -> De Pittige Pepernoten | B8: 1 | C8: 4 | D8: 6 | E8: 4 | F8: 15 | G8: 2 | H8: 4 | I8: 6 | J8: 9 | K8: 6 | L8: 6 | M8: 0 | N8: 6 | O8: 6 | AG8: =IF($A8="","",SUM(C8:AF8)) -> 74 | AH8: {=IF($A8="","",SUMPRODUCT((ROW(Management!$B$7:$B$36)-ROW(Management!$B$9)+1<=Management!$C$4)*IFERROR(Management!$B$7:$B$36*1,0)))} -> 140 | AI8: =IF($A8="",-1,SUM(C8:AF8)-IFERROR(B8,999)/100000) -> 73.99999
A9: {=IFERROR(IF(INDEX(Management!$F$7:$F$36,ROWS($A$2:A9))="","",INDEX(Management!$F$7:$F$36,ROWS($A$2:A9))),"")} -> Fietsende Frikandellen | B9: 5 | C9: 8 | D9: 8 | E9: 9 | F9: 18 | G9: 3 | H9: 4 | I9: 4 | J9: 4 | K9: 4 | L9: 4 | M9: 0 | N9: 4 | O9: 4 | AG9: =IF($A9="","",SUM(C9:AF9)) -> 74 | AH9: {=IF($A9="","",SUMPRODUCT((ROW(Management!$B$7:$B$36)-ROW(Management!$B$9)+1<=Management!$C$4)*IFERROR(Management!$B$7:$B$36*1,0)))} -> 140 | AI9: =IF($A9="",-1,SUM(C9:AF9)-IFERROR(B9,999)/100000) -> 73.99995
A10: {=IFERROR(IF(INDEX(Management!$F$7:$F$36,ROWS($A$2:A10))="","",INDEX(Management!$F$7:$F$36,ROWS($A$2:A10))),"")} -> De Gekke Gouwenaars | B10: 4 | C10: 8 | D10: 8 | E10: 6 | F10: 3 | G10: 3 | H10: 1 | I10: 6 | J10: 4 | K10: 6 | L10: 6 | M10: 0 | N10: 6 | O10: 6 | AG10: =IF($A10="","",SUM(C10:AF10)) -> 63 | AH10: {=IF($A10="","",SUMPRODUCT((ROW(Management!$B$7:$B$36)-ROW(Management!$B$9)+1<=Management!$C$4)*IFERROR(Management!$B$7:$B$36*1,0)))} -> 140 | AI10: =IF($A10="",-1,SUM(C10:AF10)-IFERROR(B10,999)/100000) -> 62.99996
A11: {=IFERROR(IF(INDEX(Management!$F$7:$F$36,ROWS($A$2:A11))="","",INDEX(Management!$F$7:$F$36,ROWS($A$2:A11))),"")} -> Stampende Stamppotters | B11: 9 | C11: 7 | D11: 3 | E11: 7 | F11: 12 | G11: 9 | H11: 3 | I11: 1 | J11: 3 | K11: 1 | L11: 1 | M11: 0 | N11: 1 | O11: 1 | AG11: =IF($A11="","",SUM(C11:AF11)) -> 49 | AH11: {=IF($A11="","",SUMPRODUCT((ROW(Management!$B$7:$B$36)-ROW(Management!$B$9)+1<=Management!$C$4)*IFERROR(Management!$B$7:$B$36*1,0)))} -> 140 | AI11: =IF($A11="",-1,SUM(C11:AF11)-IFERROR(B11,999)/100000) -> 48.99991
A12: {=IFERROR(IF(INDEX(Management!$F$7:$F$36,ROWS($A$2:A12))="","",INDEX(Management!$F$7:$F$36,ROWS($A$2:A12))),"")} -> Kwistet | B12: 11 | C12: 8 | D12: 5 | E12: 5 | F12: 5 | G12: 5 | H12: 5 | I12: 5 | J12: 5 | K12: 5 | L12: 5 | M12: 0 | N12: 5 | O12: 5 | AG12: =IF($A12="","",SUM(C12:AF12)) -> 63 | AH12: {=IF($A12="","",SUMPRODUCT((ROW(Management!$B$7:$B$36)-ROW(Management!$B$9)+1<=Management!$C$4)*IFERROR(Management!$B$7:$B$36*1,0)))} -> 140 | AI12: =IF($A12="",-1,SUM(C12:AF12)-IFERROR(B12,999)/100000) -> 62.99989
A13: {=IFERROR(IF(INDEX(Management!$F$7:$F$36,ROWS($A$2:A13))="","",INDEX(Management!$F$7:$F$36,ROWS($A$2:A13))),"")} -> Nogeenploeg | B13: 12 | C13: 7 | D13: 3 | E13: 7 | F13: 12 | G13: 9 | H13: 3 | I13: 1 | J13: 14 | K13: 8 | L13: 4 | M13: 2 | N13: 4 | O13: 4 | AG13: =IF($A13="","",SUM(C13:AF13)) -> 78 | AH13: {=IF($A13="","",SUMPRODUCT((ROW(Management!$B$7:$B$36)-ROW(Management!$B$9)+1<=Management!$C$4)*IFERROR(Management!$B$7:$B$36*1,0)))} -> 140 | AI13: =IF($A13="",-1,SUM(C13:AF13)-IFERROR(B13,999)/100000) -> 77.99988
... A31: {=IFERROR(IF(INDEX(Management!$F$7:$F$36,ROWS($A$2:A31))="","",INDEX(Management!$F$7:$F$36,ROWS($A$2:A31))),"")} -> Team36 | B31: 30 | C31: 7 | D31: 3 | E31: 7 | F31: 12 | G31: 9 | H31: 3 | I31: 1 | J31: 14 | K31: 8 | L31: 4 | M31: 2 | N31: 4 | O31: 4 | AG31: =IF($A31="","",SUM(C31:AF31)) -> 78 | AH31: {=IF($A31="","",SUMPRODUCT((ROW(Management!$B$7:$B$36)-ROW(Management!$B$9)+1<=Management!$C$4)*IFERROR(Management!$B$7:$B$36*1,0)))} -> 140 | AI31: =IF($A31="",-1,SUM(C31:AF31)-IFERROR(B31,999)/100000) -> 77.9997

Sheet Standings
A1: Rank | B1: Team | C1: Score | D1: {=IFERROR(IF(COLUMNS($D1:D1)<=Management!$C$4,IF(LEFT(INDEX(Management!$C$7:$C$36,COLUMNS($D1:D1)),6)="Round ","R"&MID(INDEX(Management!$C$7:$C$36,COLUMNS($D1:D1)),7,10),LEFT(INDEX(Management!$C$7:$C$36,COLUMNS($D1:D1)),7)),""),"")} -> Rond de | E1: {=IFERROR(IF(COLUMNS($D1:E1)<=Management!$C$4,IF(LEFT(INDEX(Management!$C$7:$C$36,COLUMNS($D1:E1)),6)="Round ","R"&MID(INDEX(Management!$C$7:$C$36,COLUMNS($D1:E1)),7,10),LEFT(INDEX(Management!$C$7:$C$36,COLUMNS($D1:E1)),7)),""),"")} -> Woordsl | F1: {=IFERROR(IF(COLUMNS($D1:F1)<=Management!$C$4,IF(LEFT(INDEX(Management!$C$7:$C$36,COLUMNS($D1:F1)),6)="Round ","R"&MID(INDEX(Management!$C$7:$C$36,COLUMNS($D1:F1)),7,10),LEFT(INDEX(Management!$C$7:$C$36,COLUMNS($D1:F1)),7)),""),"")} -> Lokaal | G1: {=IFERROR(IF(COLUMNS($D1:G1)<=Management!$C$4,IF(LEFT(INDEX(Management!$C$7:$C$36,COLUMNS($D1:G1)),6)="Round ","R"&MID(INDEX(Management!$C$7:$C$36,COLUMNS($D1:G1)),7,10),LEFT(INDEX(Management!$C$7:$C$36,COLUMNS($D1:G1)),7)),""),"")} -> Tussenr | H1: {=IFERROR(IF(COLUMNS($D1:H1)<=Management!$C$4,IF(LEFT(INDEX(Management!$C$7:$C$36,COLUMNS($D1:H1)),6)="Round ","R"&MID(INDEX(Management!$C$7:$C$36,COLUMNS($D1:H1)),7,10),LEFT(INDEX(Management!$C$7:$C$36,COLUMNS($D1:H1)),7)),""),"")} -> Actua | I1: {=IFERROR(IF(COLUMNS($D1:I1)<=Management!$C$4,IF(LEFT(INDEX(Management!$C$7:$C$36,COLUMNS($D1:I1)),6)="Round ","R"&MID(INDEX(Management!$C$7:$C$36,COLUMNS($D1:I1)),7,10),LEFT(INDEX(Management!$C$7:$C$36,COLUMNS($D1:I1)),7)),""),"")} -> R6 | J1: {=IFERROR(IF(COLUMNS($D1:J1)<=Management!$C$4,IF(LEFT(INDEX(Management!$C$7:$C$36,COLUMNS($D1:J1)),6)="Round ","R"&MID(INDEX(Management!$C$7:$C$36,COLUMNS($D1:J1)),7,10),LEFT(INDEX(Management!$C$7:$C$36,COLUMNS($D1:J1)),7)),""),"")} -> R7 | K1: {=IFERROR(IF(COLUMNS($D1:K1)<=Management!$C$4,IF(LEFT(INDEX(Management!$C$7:$C$36,COLUMNS($D1:K1)),6)="Round ","R"&MID(INDEX(Management!$C$7:$C$36,COLUMNS($D1:K1)),7,10),LEFT(INDEX(Management!$C$7:$C$36,COLUMNS($D1:K1)),7)),""),"")} -> Tussenr | ... AG1: {=IFERROR(IF(COLUMNS($D1:AG1)<=Management!$C$4,IF(LEFT(INDEX(Management!$C$7:$C$36,COLUMNS($D1:AG1)),6)="Round ","R"&MID(INDEX(Management!$C$7:$C$36,COLUMNS($D1:AG1)),7,10),LEFT(INDEX(Management!$C$7:$C$36,COLUMNS($D1:AG1)),7)),""),"")}
A2: =IF(ROWS($A$2:A2)>COUNTA(Management!$F$7:$F$36),"",ROWS($A$2:A2)) -> 1 | B2: =IF($A2="","",INDEX(Dashboard!$A$2:$A$31,MATCH(LARGE(Dashboard!$AI$2:$AI$31,$A2),Dashboard!$AI$2:$AI$31,0))) -> Team28 | C2: =IF($A2="","",INDEX(Dashboard!$AG$2:$AG$31,MATCH(LARGE(Dashboard!$AI$2:$AI$31,$A2),Dashboard!$AI$2:$AI$31,0))&" / "&INDEX(Dashboard!$AH$2:$AH$31,MATCH(LARGE(Dashboard!$AI$2:$AI$31,$A2),Dashboard!$AI$2:$AI$31,0))) -> 84 / 140 | D2: {=IF(OR($A2="",COLUMNS($D2:D2)>Management!$C$4),"",N(INDEX(Dashboard!$C$2:$AF$31,MATCH(LARGE(Dashboard!$AI$2:$AI$31,$A2),Dashboard!$AI$2:$AI$31,0),COLUMNS($D2:D2)))&"/"&INDEX(Management!$B$7:$B$36,COLUMNS($D2:D2)))} -> 7/10 | E2: {=IF(OR($A2="",COLUMNS($D2:E2)>Management!$C$4),"",N(INDEX(Dashboard!$C$2:$AF$31,MATCH(LARGE(Dashboard!$AI$2:$AI$31,$A2),Dashboard!$AI$2:$AI$31,0),COLUMNS($D2:E2)))&"/"&INDEX(Management!$B$7:$B$36,COLUMNS($D2:E2)))} -> 3/10 | F2: {=IF(OR($A2="",COLUMNS($D2:F2)>Management!$C$4),"",N(INDEX(Dashboard!$C$2:$AF$31,MATCH(LARGE(Dashboard!$AI$2:$AI$31,$A2),Dashboard!$AI$2:$AI$31,0),COLUMNS($D2:F2)))&"/"&INDEX(Management!$B$7:$B$36,COLUMNS($D2:F2)))} -> 7/10 | G2: {=IF(OR($A2="",COLUMNS($D2:G2)>Management!$C$4),"",N(INDEX(Dashboard!$C$2:$AF$31,MATCH(LARGE(Dashboard!$AI$2:$AI$31,$A2),Dashboard!$AI$2:$AI$31,0),COLUMNS($D2:G2)))&"/"&INDEX(Management!$B$7:$B$36,COLUMNS($D2:G2)))} -> 12/20 | H2: {=IF(OR($A2="",COLUMNS($D2:H2)>Management!$C$4),"",N(INDEX(Dashboard!$C$2:$AF$31,MATCH(LARGE(Dashboard!$AI$2:$AI$31,$A2),Dashboard!$AI$2:$AI$31,0),COLUMNS($D2:H2)))&"/"&INDEX(Management!$B$7:$B$36,COLUMNS($D2:H2)))} -> 9/10 | I2: {=IF(OR($A2="",COLUMNS($D2:I2)>Management!$C$4),"",N(INDEX(Dashboard!$C$2:$AF$31,MATCH(LARGE(Dashboard!$AI$2:$AI$31,$A2),Dashboard!$AI$2:$AI$31,0),COLUMNS($D2:I2)))&"/"&INDEX(Management!$B$7:$B$36,COLUMNS($D2:I2)))} -> 3/10 | J2: {=IF(OR($A2="",COLUMNS($D2:J2)>Management!$C$4),"",N(INDEX(Dashboard!$C$2:$AF$31,MATCH(LARGE(Dashboard!$AI$2:$AI$31,$A2),Dashboard!$AI$2:$AI$31,0),COLUMNS($D2:J2)))&"/"&INDEX(Management!$B$7:$B$36,COLUMNS($D2:J2)))} -> 1/10 | K2: {=IF(OR($A2="",COLUMNS($D2:K2)>Management!$C$4),"",N(INDEX(Dashboard!$C$2:$AF$31,MATCH(LARGE(Dashboard!$AI$2:$AI$31,$A2),Dashboard!$AI$2:$AI$31,0),COLUMNS($D2:K2)))&"/"&INDEX(Management!$B$7:$B$36,COLUMNS($D2:K2)))} -> 14/15 | ... AG2: {=IF(OR($A2="",COLUMNS($D2:AG2)>Management!$C$4),"",N(INDEX(Dashboard!$C$2:$AF$31,MATCH(LARGE(Dashboard!$AI$2:$AI$31,$A2),Dashboard!$AI$2:$AI$31,0),COLUMNS($D2:AG2)))&"/"&INDEX(Management!$B$7:$B$36,COLUMNS($D2:AG2)))}
A3: =IF(ROWS($A$2:A3)>COUNTA(Management!$F$7:$F$36),"",ROWS($A$2:A3)) -> 2 | B3: =IF($A3="","",INDEX(Dashboard!$A$2:$A$31,MATCH(LARGE(Dashboard!$AI$2:$AI$31,$A3),Dashboard!$AI$2:$AI$31,0))) -> Tulpen uit Toeterdam | C3: =IF($A3="","",INDEX(Dashboard!$AG$2:$AG$31,MATCH(LARGE(Dashboard!$AI$2:$AI$31,$A3),Dashboard!$AI$2:$AI$31,0))&" / "&INDEX(Dashboard!$AH$2:$AH$31,MATCH(LARGE(Dashboard!$AI$2:$AI$31,$A3),Dashboard!$AI$2:$AI$31,0))) -> 82 / 140 | D3: {=IF(OR($A3="",COLUMNS($D3:D3)>Management!$C$4),"",N(INDEX(Dashboard!$C$2:$AF$31,MATCH(LARGE(Dashboard!$AI$2:$AI$31,$A3),Dashboard!$AI$2:$AI$31,0),COLUMNS($D3:D3)))&"/"&INDEX(Management!$B$7:$B$36,COLUMNS($D3:D3)))} -> 6/10 | E3: {=IF(OR($A3="",COLUMNS($D3:E3)>Management!$C$4),"",N(INDEX(Dashboard!$C$2:$AF$31,MATCH(LARGE(Dashboard!$AI$2:$AI$31,$A3),Dashboard!$AI$2:$AI$31,0),COLUMNS($D3:E3)))&"/"&INDEX(Management!$B$7:$B$36,COLUMNS($D3:E3)))} -> 10/10 | F3: {=IF(OR($A3="",COLUMNS($D3:F3)>Management!$C$4),"",N(INDEX(Dashboard!$C$2:$AF$31,MATCH(LARGE(Dashboard!$AI$2:$AI$31,$A3),Dashboard!$AI$2:$AI$31,0),COLUMNS($D3:F3)))&"/"&INDEX(Management!$B$7:$B$36,COLUMNS($D3:F3)))} -> 9/10 | G3: {=IF(OR($A3="",COLUMNS($D3:G3)>Management!$C$4),"",N(INDEX(Dashboard!$C$2:$AF$31,MATCH(LARGE(Dashboard!$AI$2:$AI$31,$A3),Dashboard!$AI$2:$AI$31,0),COLUMNS($D3:G3)))&"/"&INDEX(Management!$B$7:$B$36,COLUMNS($D3:G3)))} -> 10/20 | H3: {=IF(OR($A3="",COLUMNS($D3:H3)>Management!$C$4),"",N(INDEX(Dashboard!$C$2:$AF$31,MATCH(LARGE(Dashboard!$AI$2:$AI$31,$A3),Dashboard!$AI$2:$AI$31,0),COLUMNS($D3:H3)))&"/"&INDEX(Management!$B$7:$B$36,COLUMNS($D3:H3)))} -> 9/10 | I3: {=IF(OR($A3="",COLUMNS($D3:I3)>Management!$C$4),"",N(INDEX(Dashboard!$C$2:$AF$31,MATCH(LARGE(Dashboard!$AI$2:$AI$31,$A3),Dashboard!$AI$2:$AI$31,0),COLUMNS($D3:I3)))&"/"&INDEX(Management!$B$7:$B$36,COLUMNS($D3:I3)))} -> 4/10 | J3: {=IF(OR($A3="",COLUMNS($D3:J3)>Management!$C$4),"",N(INDEX(Dashboard!$C$2:$AF$31,MATCH(LARGE(Dashboard!$AI$2:$AI$31,$A3),Dashboard!$AI$2:$AI$31,0),COLUMNS($D3:J3)))&"/"&INDEX(Management!$B$7:$B$36,COLUMNS($D3:J3)))} -> 10/10 | K3: {=IF(OR($A3="",COLUMNS($D3:K3)>Management!$C$4),"",N(INDEX(Dashboard!$C$2:$AF$31,MATCH(LARGE(Dashboard!$AI$2:$AI$31,$A3),Dashboard!$AI$2:$AI$31,0),COLUMNS($D3:K3)))&"/"&INDEX(Management!$B$7:$B$36,COLUMNS($D3:K3)))} -> 9/15 | ... AG3: {=IF(OR($A3="",COLUMNS($D3:AG3)>Management!$C$4),"",N(INDEX(Dashboard!$C$2:$AF$31,MATCH(LARGE(Dashboard!$AI$2:$AI$31,$A3),Dashboard!$AI$2:$AI$31,0),COLUMNS($D3:AG3)))&"/"&INDEX(Management!$B$7:$B$36,COLUMNS($D3:AG3)))}
A4: =IF(ROWS($A$2:A4)>COUNTA(Management!$F$7:$F$36),"",ROWS($A$2:A4)) -> 3 | B4: =IF($A4="","",INDEX(Dashboard!$A$2:$A$31,MATCH(LARGE(Dashboard!$AI$2:$AI$31,$A4),Dashboard!$AI$2:$AI$31,0))) -> Bietsende Bitterballen | C4: =IF($A4="","",INDEX(Dashboard!$AG$2:$AG$31,MATCH(LARGE(Dashboard!$AI$2:$AI$31,$A4),Dashboard!$AI$2:$AI$31,0))&" / "&INDEX(Dashboard!$AH$2:$AH$31,MATCH(LARGE(Dashboard!$AI$2:$AI$31,$A4),Dashboard!$AI$2:$AI$31,0))) -> 82 / 140 | D4: {=IF(OR($A4="",COLUMNS($D4:D4)>Management!$C$4),"",N(INDEX(Dashboard!$C$2:$AF$31,MATCH(LARGE(Dashboard!$AI$2:$AI$31,$A4),Dashboard!$AI$2:$AI$31,0),COLUMNS($D4:D4)))&"/"&INDEX(Management!$B$7:$B$36,COLUMNS($D4:D4)))} -> 3/10 | E4: {=IF(OR($A4="",COLUMNS($D4:E4)>Management!$C$4),"",N(INDEX(Dashboard!$C$2:$AF$31,MATCH(LARGE(Dashboard!$AI$2:$AI$31,$A4),Dashboard!$AI$2:$AI$31,0),COLUMNS($D4:E4)))&"/"&INDEX(Management!$B$7:$B$36,COLUMNS($D4:E4)))} -> 4/10 | F4: {=IF(OR($A4="",COLUMNS($D4:F4)>Management!$C$4),"",N(INDEX(Dashboard!$C$2:$AF$31,MATCH(LARGE(Dashboard!$AI$2:$AI$31,$A4),Dashboard!$AI$2:$AI$31,0),COLUMNS($D4:F4)))&"/"&INDEX(Management!$B$7:$B$36,COLUMNS($D4:F4)))} -> 6/10 | G4: {=IF(OR($A4="",COLUMNS($D4:G4)>Management!$C$4),"",N(INDEX(Dashboard!$C$2:$AF$31,MATCH(LARGE(Dashboard!$AI$2:$AI$31,$A4),Dashboard!$AI$2:$AI$31,0),COLUMNS($D4:G4)))&"/"&INDEX(Management!$B$7:$B$36,COLUMNS($D4:G4)))} -> 1/20 | H4: {=IF(OR($A4="",COLUMNS($D4:H4)>Management!$C$4),"",N(INDEX(Dashboard!$C$2:$AF$31,MATCH(LARGE(Dashboard!$AI$2:$AI$31,$A4),Dashboard!$AI$2:$AI$31,0),COLUMNS($D4:H4)))&"/"&INDEX(Management!$B$7:$B$36,COLUMNS($D4:H4)))} -> 6/10 | I4: {=IF(OR($A4="",COLUMNS($D4:I4)>Management!$C$4),"",N(INDEX(Dashboard!$C$2:$AF$31,MATCH(LARGE(Dashboard!$AI$2:$AI$31,$A4),Dashboard!$AI$2:$AI$31,0),COLUMNS($D4:I4)))&"/"&INDEX(Management!$B$7:$B$36,COLUMNS($D4:I4)))} -> 8/10 | J4: {=IF(OR($A4="",COLUMNS($D4:J4)>Management!$C$4),"",N(INDEX(Dashboard!$C$2:$AF$31,MATCH(LARGE(Dashboard!$AI$2:$AI$31,$A4),Dashboard!$AI$2:$AI$31,0),COLUMNS($D4:J4)))&"/"&INDEX(Management!$B$7:$B$36,COLUMNS($D4:J4)))} -> 9/10 | K4: {=IF(OR($A4="",COLUMNS($D4:K4)>Management!$C$4),"",N(INDEX(Dashboard!$C$2:$AF$31,MATCH(LARGE(Dashboard!$AI$2:$AI$31,$A4),Dashboard!$AI$2:$AI$31,0),COLUMNS($D4:K4)))&"/"&INDEX(Management!$B$7:$B$36,COLUMNS($D4:K4)))} -> 5/15 | ... AG4: {=IF(OR($A4="",COLUMNS($D4:AG4)>Management!$C$4),"",N(INDEX(Dashboard!$C$2:$AF$31,MATCH(LARGE(Dashboard!$AI$2:$AI$31,$A4),Dashboard!$AI$2:$AI$31,0),COLUMNS($D4:AG4)))&"/"&INDEX(Management!$B$7:$B$36,COLUMNS($D4:AG4)))}
A5: =IF(ROWS($A$2:A5)>COUNTA(Management!$F$7:$F$36),"",ROWS($A$2:A5)) -> 4 | B5: =IF($A5="","",INDEX(Dashboard!$A$2:$A$31,MATCH(LARGE(Dashboard!$AI$2:$AI$31,$A5),Dashboard!$AI$2:$AI$31,0))) -> Team22 | C5: =IF($A5="","",INDEX(Dashboard!$AG$2:$AG$31,MATCH(LARGE(Dashboard!$AI$2:$AI$31,$A5),Dashboard!$AI$2:$AI$31,0))&" / "&INDEX(Dashboard!$AH$2:$AH$31,MATCH(LARGE(Dashboard!$AI$2:$AI$31,$A5),Dashboard!$AI$2:$AI$31,0))) -> 82 / 140 | D5: {=IF(OR($A5="",COLUMNS($D5:D5)>Management!$C$4),"",N(INDEX(Dashboard!$C$2:$AF$31,MATCH(LARGE(Dashboard!$AI$2:$AI$31,$A5),Dashboard!$AI$2:$AI$31,0),COLUMNS($D5:D5)))&"/"&INDEX(Management!$B$7:$B$36,COLUMNS($D5:D5)))} -> 6/10 | E5: {=IF(OR($A5="",COLUMNS($D5:E5)>Management!$C$4),"",N(INDEX(Dashboard!$C$2:$AF$31,MATCH(LARGE(Dashboard!$AI$2:$AI$31,$A5),Dashboard!$AI$2:$AI$31,0),COLUMNS($D5:E5)))&"/"&INDEX(Management!$B$7:$B$36,COLUMNS($D5:E5)))} -> 10/10 | F5: {=IF(OR($A5="",COLUMNS($D5:F5)>Management!$C$4),"",N(INDEX(Dashboard!$C$2:$AF$31,MATCH(LARGE(Dashboard!$AI$2:$AI$31,$A5),Dashboard!$AI$2:$AI$31,0),COLUMNS($D5:F5)))&"/"&INDEX(Management!$B$7:$B$36,COLUMNS($D5:F5)))} -> 9/10 | G5: {=IF(OR($A5="",COLUMNS($D5:G5)>Management!$C$4),"",N(INDEX(Dashboard!$C$2:$AF$31,MATCH(LARGE(Dashboard!$AI$2:$AI$31,$A5),Dashboard!$AI$2:$AI$31,0),COLUMNS($D5:G5)))&"/"&INDEX(Management!$B$7:$B$36,COLUMNS($D5:G5)))} -> 10/20 | H5: {=IF(OR($A5="",COLUMNS($D5:H5)>Management!$C$4),"",N(INDEX(Dashboard!$C$2:$AF$31,MATCH(LARGE(Dashboard!$AI$2:$AI$31,$A5),Dashboard!$AI$2:$AI$31,0),COLUMNS($D5:H5)))&"/"&INDEX(Management!$B$7:$B$36,COLUMNS($D5:H5)))} -> 9/10 | I5: {=IF(OR($A5="",COLUMNS($D5:I5)>Management!$C$4),"",N(INDEX(Dashboard!$C$2:$AF$31,MATCH(LARGE(Dashboard!$AI$2:$AI$31,$A5),Dashboard!$AI$2:$AI$31,0),COLUMNS($D5:I5)))&"/"&INDEX(Management!$B$7:$B$36,COLUMNS($D5:I5)))} -> 4/10 | J5: {=IF(OR($A5="",COLUMNS($D5:J5)>Management!$C$4),"",N(INDEX(Dashboard!$C$2:$AF$31,MATCH(LARGE(Dashboard!$AI$2:$AI$31,$A5),Dashboard!$AI$2:$AI$31,0),COLUMNS($D5:J5)))&"/"&INDEX(Management!$B$7:$B$36,COLUMNS($D5:J5)))} -> 10/10 | K5: {=IF(OR($A5="",COLUMNS($D5:K5)>Management!$C$4),"",N(INDEX(Dashboard!$C$2:$AF$31,MATCH(LARGE(Dashboard!$AI$2:$AI$31,$A5),Dashboard!$AI$2:$AI$31,0),COLUMNS($D5:K5)))&"/"&INDEX(Management!$B$7:$B$36,COLUMNS($D5:K5)))} -> 9/15 | ... AG5: {=IF(OR($A5="",COLUMNS($D5:AG5)>Management!$C$4),"",N(INDEX(Dashboard!$C$2:$AF$31,MATCH(LARGE(Dashboard!$AI$2:$AI$31,$A5),Dashboard!$AI$2:$AI$31,0),COLUMNS($D5:AG5)))&"/"&INDEX(Management!$B$7:$B$36,COLUMNS($D5:AG5)))}
A6: =IF(ROWS($A$2:A6)>COUNTA(Management!$F$7:$F$36),"",ROWS($A$2:A6)) -> 5 | B6: =IF($A6="","",INDEX(Dashboard!$A$2:$A$31,MATCH(LARGE(Dashboard!$AI$2:$AI$31,$A6),Dashboard!$AI$2:$AI$31,0))) -> Team30 | C6: =IF($A6="","",INDEX(Dashboard!$AG$2:$AG$31,MATCH(LARGE(Dashboard!$AI$2:$AI$31,$A6),Dashboard!$AI$2:$AI$31,0))&" / "&INDEX(Dashboard!$AH$2:$AH$31,MATCH(LARGE(Dashboard!$AI$2:$AI$31,$A6),Dashboard!$AI$2:$AI$31,0))) -> 82 / 140 | D6: {=IF(OR($A6="",COLUMNS($D6:D6)>Management!$C$4),"",N(INDEX(Dashboard!$C$2:$AF$31,MATCH(LARGE(Dashboard!$AI$2:$AI$31,$A6),Dashboard!$AI$2:$AI$31,0),COLUMNS($D6:D6)))&"/"&INDEX(Management!$B$7:$B$36,COLUMNS($D6:D6)))} -> 6/10 | E6: {=IF(OR($A6="",COLUMNS($D6:E6)>Management!$C$4),"",N(INDEX(Dashboard!$C$2:$AF$31,MATCH(LARGE(Dashboard!$AI$2:$AI$31,$A6),Dashboard!$AI$2:$AI$31,0),COLUMNS($D6:E6)))&"/"&INDEX(Management!$B$7:$B$36,COLUMNS($D6:E6)))} -> 10/10 | F6: {=IF(OR($A6="",COLUMNS($D6:F6)>Management!$C$4),"",N(INDEX(Dashboard!$C$2:$AF$31,MATCH(LARGE(Dashboard!$AI$2:$AI$31,$A6),Dashboard!$AI$2:$AI$31,0),COLUMNS($D6:F6)))&"/"&INDEX(Management!$B$7:$B$36,COLUMNS($D6:F6)))} -> 9/10 | G6: {=IF(OR($A6="",COLUMNS($D6:G6)>Management!$C$4),"",N(INDEX(Dashboard!$C$2:$AF$31,MATCH(LARGE(Dashboard!$AI$2:$AI$31,$A6),Dashboard!$AI$2:$AI$31,0),COLUMNS($D6:G6)))&"/"&INDEX(Management!$B$7:$B$36,COLUMNS($D6:G6)))} -> 10/20 | H6: {=IF(OR($A6="",COLUMNS($D6:H6)>Management!$C$4),"",N(INDEX(Dashboard!$C$2:$AF$31,MATCH(LARGE(Dashboard!$AI$2:$AI$31,$A6),Dashboard!$AI$2:$AI$31,0),COLUMNS($D6:H6)))&"/"&INDEX(Management!$B$7:$B$36,COLUMNS($D6:H6)))} -> 9/10 | I6: {=IF(OR($A6="",COLUMNS($D6:I6)>Management!$C$4),"",N(INDEX(Dashboard!$C$2:$AF$31,MATCH(LARGE(Dashboard!$AI$2:$AI$31,$A6),Dashboard!$AI$2:$AI$31,0),COLUMNS($D6:I6)))&"/"&INDEX(Management!$B$7:$B$36,COLUMNS($D6:I6)))} -> 4/10 | J6: {=IF(OR($A6="",COLUMNS($D6:J6)>Management!$C$4),"",N(INDEX(Dashboard!$C$2:$AF$31,MATCH(LARGE(Dashboard!$AI$2:$AI$31,$A6),Dashboard!$AI$2:$AI$31,0),COLUMNS($D6:J6)))&"/"&INDEX(Management!$B$7:$B$36,COLUMNS($D6:J6)))} -> 10/10 | K6: {=IF(OR($A6="",COLUMNS($D6:K6)>Management!$C$4),"",N(INDEX(Dashboard!$C$2:$AF$31,MATCH(LARGE(Dashboard!$AI$2:$AI$31,$A6),Dashboard!$AI$2:$AI$31,0),COLUMNS($D6:K6)))&"/"&INDEX(Management!$B$7:$B$36,COLUMNS($D6:K6)))} -> 9/15 | ... AG6: {=IF(OR($A6="",COLUMNS($D6:AG6)>Management!$C$4),"",N(INDEX(Dashboard!$C$2:$AF$31,MATCH(LARGE(Dashboard!$AI$2:$AI$31,$A6),Dashboard!$AI$2:$AI$31,0),COLUMNS($D6:AG6)))&"/"&INDEX(Management!$B$7:$B$36,COLUMNS($D6:AG6)))}
A7: =IF(ROWS($A$2:A7)>COUNTA(Management!$F$7:$F$36),"",ROWS($A$2:A7)) -> 6 | B7: =IF($A7="","",INDEX(Dashboard!$A$2:$A$31,MATCH(LARGE(Dashboard!$AI$2:$AI$31,$A7),Dashboard!$AI$2:$AI$31,0))) -> De Vliegende Stroopwafels | C7: =IF($A7="","",INDEX(Dashboard!$AG$2:$AG$31,MATCH(LARGE(Dashboard!$AI$2:$AI$31,$A7),Dashboard!$AI$2:$AI$31,0))&" / "&INDEX(Dashboard!$AH$2:$AH$31,MATCH(LARGE(Dashboard!$AI$2:$AI$31,$A7),Dashboard!$AI$2:$AI$31,0))) -> 79 / 140 | D7: {=IF(OR($A7="",COLUMNS($D7:D7)>Management!$C$4),"",N(INDEX(Dashboard!$C$2:$AF$31,MATCH(LARGE(Dashboard!$AI$2:$AI$31,$A7),Dashboard!$AI$2:$AI$31,0),COLUMNS($D7:D7)))&"/"&INDEX(Management!$B$7:$B$36,COLUMNS($D7:D7)))} -> 3/10 | E7: {=IF(OR($A7="",COLUMNS($D7:E7)>Management!$C$4),"",N(INDEX(Dashboard!$C$2:$AF$31,MATCH(LARGE(Dashboard!$AI$2:$AI$31,$A7),Dashboard!$AI$2:$AI$31,0),COLUMNS($D7:E7)))&"/"&INDEX(Management!$B$7:$B$36,COLUMNS($D7:E7)))} -> 4/10 | F7: {=IF(OR($A7="",COLUMNS($D7:F7)>Management!$C$4),"",N(INDEX(Dashboard!$C$2:$AF$31,MATCH(LARGE(Dashboard!$AI$2:$AI$31,$A7),Dashboard!$AI$2:$AI$31,0),COLUMNS($D7:F7)))&"/"&INDEX(Management!$B$7:$B$36,COLUMNS($D7:F7)))} -> 1/10 | G7: {=IF(OR($A7="",COLUMNS($D7:G7)>Management!$C$4),"",N(INDEX(Dashboard!$C$2:$AF$31,MATCH(LARGE(Dashboard!$AI$2:$AI$31,$A7),Dashboard!$AI$2:$AI$31,0),COLUMNS($D7:G7)))&"/"&INDEX(Management!$B$7:$B$36,COLUMNS($D7:G7)))} -> 5/20 | H7: {=IF(OR($A7="",COLUMNS($D7:H7)>Management!$C$4),"",N(INDEX(Dashboard!$C$2:$AF$31,MATCH(LARGE(Dashboard!$AI$2:$AI$31,$A7),Dashboard!$AI$2:$AI$31,0),COLUMNS($D7:H7)))&"/"&INDEX(Management!$B$7:$B$36,COLUMNS($D7:H7)))} -> 6/10 | I7: {=IF(OR($A7="",COLUMNS($D7:I7)>Management!$C$4),"",N(INDEX(Dashboard!$C$2:$AF$31,MATCH(LARGE(Dashboard!$AI$2:$AI$31,$A7),Dashboard!$AI$2:$AI$31,0),COLUMNS($D7:I7)))&"/"&INDEX(Management!$B$7:$B$36,COLUMNS($D7:I7)))} -> 10/10 | J7: {=IF(OR($A7="",COLUMNS($D7:J7)>Management!$C$4),"",N(INDEX(Dashboard!$C$2:$AF$31,MATCH(LARGE(Dashboard!$AI$2:$AI$31,$A7),Dashboard!$AI$2:$AI$31,0),COLUMNS($D7:J7)))&"/"&INDEX(Management!$B$7:$B$36,COLUMNS($D7:J7)))} -> 6/10 | K7: {=IF(OR($A7="",COLUMNS($D7:K7)>Management!$C$4),"",N(INDEX(Dashboard!$C$2:$AF$31,MATCH(LARGE(Dashboard!$AI$2:$AI$31,$A7),Dashboard!$AI$2:$AI$31,0),COLUMNS($D7:K7)))&"/"&INDEX(Management!$B$7:$B$36,COLUMNS($D7:K7)))} -> 15/15 | ... AG7: {=IF(OR($A7="",COLUMNS($D7:AG7)>Management!$C$4),"",N(INDEX(Dashboard!$C$2:$AF$31,MATCH(LARGE(Dashboard!$AI$2:$AI$31,$A7),Dashboard!$AI$2:$AI$31,0),COLUMNS($D7:AG7)))&"/"&INDEX(Management!$B$7:$B$36,COLUMNS($D7:AG7)))}
A8: =IF(ROWS($A$2:A8)>COUNTA(Management!$F$7:$F$36),"",ROWS($A$2:A8)) -> 7 | B8: =IF($A8="","",INDEX(Dashboard!$A$2:$A$31,MATCH(LARGE(Dashboard!$AI$2:$AI$31,$A8),Dashboard!$AI$2:$AI$31,0))) -> Nogeenploeg | C8: =IF($A8="","",INDEX(Dashboard!$AG$2:$AG$31,MATCH(LARGE(Dashboard!$AI$2:$AI$31,$A8),Dashboard!$AI$2:$AI$31,0))&" / "&INDEX(Dashboard!$AH$2:$AH$31,MATCH(LARGE(Dashboard!$AI$2:$AI$31,$A8),Dashboard!$AI$2:$AI$31,0))) -> 78 / 140 | D8: {=IF(OR($A8="",COLUMNS($D8:D8)>Management!$C$4),"",N(INDEX(Dashboard!$C$2:$AF$31,MATCH(LARGE(Dashboard!$AI$2:$AI$31,$A8),Dashboard!$AI$2:$AI$31,0),COLUMNS($D8:D8)))&"/"&INDEX(Management!$B$7:$B$36,COLUMNS($D8:D8)))} -> 7/10 | E8: {=IF(OR($A8="",COLUMNS($D8:E8)>Management!$C$4),"",N(INDEX(Dashboard!$C$2:$AF$31,MATCH(LARGE(Dashboard!$AI$2:$AI$31,$A8),Dashboard!$AI$2:$AI$31,0),COLUMNS($D8:E8)))&"/"&INDEX(Management!$B$7:$B$36,COLUMNS($D8:E8)))} -> 3/10 | F8: {=IF(OR($A8="",COLUMNS($D8:F8)>Management!$C$4),"",N(INDEX(Dashboard!$C$2:$AF$31,MATCH(LARGE(Dashboard!$AI$2:$AI$31,$A8),Dashboard!$AI$2:$AI$31,0),COLUMNS($D8:F8)))&"/"&INDEX(Management!$B$7:$B$36,COLUMNS($D8:F8)))} -> 7/10 | G8: {=IF(OR($A8="",COLUMNS($D8:G8)>Management!$C$4),"",N(INDEX(Dashboard!$C$2:$AF$31,MATCH(LARGE(Dashboard!$AI$2:$AI$31,$A8),Dashboard!$AI$2:$AI$31,0),COLUMNS($D8:G8)))&"/"&INDEX(Management!$B$7:$B$36,COLUMNS($D8:G8)))} -> 12/20 | H8: {=IF(OR($A8="",COLUMNS($D8:H8)>Management!$C$4),"",N(INDEX(Dashboard!$C$2:$AF$31,MATCH(LARGE(Dashboard!$AI$2:$AI$31,$A8),Dashboard!$AI$2:$AI$31,0),COLUMNS($D8:H8)))&"/"&INDEX(Management!$B$7:$B$36,COLUMNS($D8:H8)))} -> 9/10 | I8: {=IF(OR($A8="",COLUMNS($D8:I8)>Management!$C$4),"",N(INDEX(Dashboard!$C$2:$AF$31,MATCH(LARGE(Dashboard!$AI$2:$AI$31,$A8),Dashboard!$AI$2:$AI$31,0),COLUMNS($D8:I8)))&"/"&INDEX(Management!$B$7:$B$36,COLUMNS($D8:I8)))} -> 3/10 | J8: {=IF(OR($A8="",COLUMNS($D8:J8)>Management!$C$4),"",N(INDEX(Dashboard!$C$2:$AF$31,MATCH(LARGE(Dashboard!$AI$2:$AI$31,$A8),Dashboard!$AI$2:$AI$31,0),COLUMNS($D8:J8)))&"/"&INDEX(Management!$B$7:$B$36,COLUMNS($D8:J8)))} -> 1/10 | K8: {=IF(OR($A8="",COLUMNS($D8:K8)>Management!$C$4),"",N(INDEX(Dashboard!$C$2:$AF$31,MATCH(LARGE(Dashboard!$AI$2:$AI$31,$A8),Dashboard!$AI$2:$AI$31,0),COLUMNS($D8:K8)))&"/"&INDEX(Management!$B$7:$B$36,COLUMNS($D8:K8)))} -> 14/15 | ... AG8: {=IF(OR($A8="",COLUMNS($D8:AG8)>Management!$C$4),"",N(INDEX(Dashboard!$C$2:$AF$31,MATCH(LARGE(Dashboard!$AI$2:$AI$31,$A8),Dashboard!$AI$2:$AI$31,0),COLUMNS($D8:AG8)))&"/"&INDEX(Management!$B$7:$B$36,COLUMNS($D8:AG8)))}
A9: =IF(ROWS($A$2:A9)>COUNTA(Management!$F$7:$F$36),"",ROWS($A$2:A9)) -> 8 | B9: =IF($A9="","",INDEX(Dashboard!$A$2:$A$31,MATCH(LARGE(Dashboard!$AI$2:$AI$31,$A9),Dashboard!$AI$2:$AI$31,0))) -> Team36 | C9: =IF($A9="","",INDEX(Dashboard!$AG$2:$AG$31,MATCH(LARGE(Dashboard!$AI$2:$AI$31,$A9),Dashboard!$AI$2:$AI$31,0))&" / "&INDEX(Dashboard!$AH$2:$AH$31,MATCH(LARGE(Dashboard!$AI$2:$AI$31,$A9),Dashboard!$AI$2:$AI$31,0))) -> 78 / 140 | D9: {=IF(OR($A9="",COLUMNS($D9:D9)>Management!$C$4),"",N(INDEX(Dashboard!$C$2:$AF$31,MATCH(LARGE(Dashboard!$AI$2:$AI$31,$A9),Dashboard!$AI$2:$AI$31,0),COLUMNS($D9:D9)))&"/"&INDEX(Management!$B$7:$B$36,COLUMNS($D9:D9)))} -> 7/10 | E9: {=IF(OR($A9="",COLUMNS($D9:E9)>Management!$C$4),"",N(INDEX(Dashboard!$C$2:$AF$31,MATCH(LARGE(Dashboard!$AI$2:$AI$31,$A9),Dashboard!$AI$2:$AI$31,0),COLUMNS($D9:E9)))&"/"&INDEX(Management!$B$7:$B$36,COLUMNS($D9:E9)))} -> 3/10 | F9: {=IF(OR($A9="",COLUMNS($D9:F9)>Management!$C$4),"",N(INDEX(Dashboard!$C$2:$AF$31,MATCH(LARGE(Dashboard!$AI$2:$AI$31,$A9),Dashboard!$AI$2:$AI$31,0),COLUMNS($D9:F9)))&"/"&INDEX(Management!$B$7:$B$36,COLUMNS($D9:F9)))} -> 7/10 | G9: {=IF(OR($A9="",COLUMNS($D9:G9)>Management!$C$4),"",N(INDEX(Dashboard!$C$2:$AF$31,MATCH(LARGE(Dashboard!$AI$2:$AI$31,$A9),Dashboard!$AI$2:$AI$31,0),COLUMNS($D9:G9)))&"/"&INDEX(Management!$B$7:$B$36,COLUMNS($D9:G9)))} -> 12/20 | H9: {=IF(OR($A9="",COLUMNS($D9:H9)>Management!$C$4),"",N(INDEX(Dashboard!$C$2:$AF$31,MATCH(LARGE(Dashboard!$AI$2:$AI$31,$A9),Dashboard!$AI$2:$AI$31,0),COLUMNS($D9:H9)))&"/"&INDEX(Management!$B$7:$B$36,COLUMNS($D9:H9)))} -> 9/10 | I9: {=IF(OR($A9="",COLUMNS($D9:I9)>Management!$C$4),"",N(INDEX(Dashboard!$C$2:$AF$31,MATCH(LARGE(Dashboard!$AI$2:$AI$31,$A9),Dashboard!$AI$2:$AI$31,0),COLUMNS($D9:I9)))&"/"&INDEX(Management!$B$7:$B$36,COLUMNS($D9:I9)))} -> 3/10 | J9: {=IF(OR($A9="",COLUMNS($D9:J9)>Management!$C$4),"",N(INDEX(Dashboard!$C$2:$AF$31,MATCH(LARGE(Dashboard!$AI$2:$AI$31,$A9),Dashboard!$AI$2:$AI$31,0),COLUMNS($D9:J9)))&"/"&INDEX(Management!$B$7:$B$36,COLUMNS($D9:J9)))} -> 1/10 | K9: {=IF(OR($A9="",COLUMNS($D9:K9)>Management!$C$4),"",N(INDEX(Dashboard!$C$2:$AF$31,MATCH(LARGE(Dashboard!$AI$2:$AI$31,$A9),Dashboard!$AI$2:$AI$31,0),COLUMNS($D9:K9)))&"/"&INDEX(Management!$B$7:$B$36,COLUMNS($D9:K9)))} -> 14/15 | ... AG9: {=IF(OR($A9="",COLUMNS($D9:AG9)>Management!$C$4),"",N(INDEX(Dashboard!$C$2:$AF$31,MATCH(LARGE(Dashboard!$AI$2:$AI$31,$A9),Dashboard!$AI$2:$AI$31,0),COLUMNS($D9:AG9)))&"/"&INDEX(Management!$B$7:$B$36,COLUMNS($D9:AG9)))}
A10: =IF(ROWS($A$2:A10)>COUNTA(Management!$F$7:$F$36),"",ROWS($A$2:A10)) -> 9 | B10: =IF($A10="","",INDEX(Dashboard!$A$2:$A$31,MATCH(LARGE(Dashboard!$AI$2:$AI$31,$A10),Dashboard!$AI$2:$AI$31,0))) -> Kaaskoppen United | C10: =IF($A10="","",INDEX(Dashboard!$AG$2:$AG$31,MATCH(LARGE(Dashboard!$AI$2:$AI$31,$A10),Dashboard!$AI$2:$AI$31,0))&" / "&INDEX(Dashboard!$AH$2:$AH$31,MATCH(LARGE(Dashboard!$AI$2:$AI$31,$A10),Dashboard!$AI$2:$AI$31,0))) -> 77 / 140 | D10: {=IF(OR($A10="",COLUMNS($D10:D10)>Management!$C$4),"",N(INDEX(Dashboard!$C$2:$AF$31,MATCH(LARGE(Dashboard!$AI$2:$AI$31,$A10),Dashboard!$AI$2:$AI$31,0),COLUMNS($D10:D10)))&"/"&INDEX(Management!$B$7:$B$36,COLUMNS($D10:D10)))} -> 2/10 | E10: {=IF(OR($A10="",COLUMNS($D10:E10)>Management!$C$4),"",N(INDEX(Dashboard!$C$2:$AF$31,MATCH(LARGE(Dashboard!$AI$2:$AI$31,$A10),Dashboard!$AI$2:$AI$31,0),COLUMNS($D10:E10)))&"/"&INDEX(Management!$B$7:$B$36,COLUMNS($D10:E10)))} -> 10/10 | F10: {=IF(OR($A10="",COLUMNS($D10:F10)>Management!$C$4),"",N(INDEX(Dashboard!$C$2:$AF$31,MATCH(LARGE(Dashboard!$AI$2:$AI$31,$A10),Dashboard!$AI$2:$AI$31,0),COLUMNS($D10:F10)))&"/"&INDEX(Management!$B$7:$B$36,COLUMNS($D10:F10)))} -> 4/10 | G10: {=IF(OR($A10="",COLUMNS($D10:G10)>Management!$C$4),"",N(INDEX(Dashboard!$C$2:$AF$31,MATCH(LARGE(Dashboard!$AI$2:$AI$31,$A10),Dashboard!$AI$2:$AI$31,0),COLUMNS($D10:G10)))&"/"&INDEX(Management!$B$7:$B$36,COLUMNS($D10:G10)))} -> 17/20 | H10: {=IF(OR($A10="",COLUMNS($D10:H10)>Management!$C$4),"",N(INDEX(Dashboard!$C$2:$AF$31,MATCH(LARGE(Dashboard!$AI$2:$AI$31,$A10),Dashboard!$AI$2:$AI$31,0),COLUMNS($D10:H10)))&"/"&INDEX(Management!$B$7:$B$36,COLUMNS($D10:H10)))} -> 0/10 | I10: {=IF(OR($A10="",COLUMNS($D10:I10)>Management!$C$4),"",N(INDEX(Dashboard!$C$2:$AF$31,MATCH(LARGE(Dashboard!$AI$2:$AI$31,$A10),Dashboard!$AI$2:$AI$31,0),COLUMNS($D10:I10)))&"/"&INDEX(Management!$B$7:$B$36,COLUMNS($D10:I10)))} -> 10/10 | J10: {=IF(OR($A10="",COLUMNS($D10:J10)>Management!$C$4),"",N(INDEX(Dashboard!$C$2:$AF$31,MATCH(LARGE(Dashboard!$AI$2:$AI$31,$A10),Dashboard!$AI$2:$AI$31,0),COLUMNS($D10:J10)))&"/"&INDEX(Management!$B$7:$B$36,COLUMNS($D10:J10)))} -> 4/10 | K10: {=IF(OR($A10="",COLUMNS($D10:K10)>Management!$C$4),"",N(INDEX(Dashboard!$C$2:$AF$31,MATCH(LARGE(Dashboard!$AI$2:$AI$31,$A10),Dashboard!$AI$2:$AI$31,0),COLUMNS($D10:K10)))&"/"&INDEX(Management!$B$7:$B$36,COLUMNS($D10:K10)))} -> 12/15 | ... AG10: {=IF(OR($A10="",COLUMNS($D10:AG10)>Management!$C$4),"",N(INDEX(Dashboard!$C$2:$AF$31,MATCH(LARGE(Dashboard!$AI$2:$AI$31,$A10),Dashboard!$AI$2:$AI$31,0),COLUMNS($D10:AG10)))&"/"&INDEX(Management!$B$7:$B$36,COLUMNS($D10:AG10)))}
A11: =IF(ROWS($A$2:A11)>COUNTA(Management!$F$7:$F$36),"",ROWS($A$2:A11)) -> 10 | B11: =IF($A11="","",INDEX(Dashboard!$A$2:$A$31,MATCH(LARGE(Dashboard!$AI$2:$AI$31,$A11),Dashboard!$AI$2:$AI$31,0))) -> Team20 | C11: =IF($A11="","",INDEX(Dashboard!$AG$2:$AG$31,MATCH(LARGE(Dashboard!$AI$2:$AI$31,$A11),Dashboard!$AI$2:$AI$31,0))&" / "&INDEX(Dashboard!$AH$2:$AH$31,MATCH(LARGE(Dashboard!$AI$2:$AI$31,$A11),Dashboard!$AI$2:$AI$31,0))) -> 77 / 140 | D11: {=IF(OR($A11="",COLUMNS($D11:D11)>Management!$C$4),"",N(INDEX(Dashboard!$C$2:$AF$31,MATCH(LARGE(Dashboard!$AI$2:$AI$31,$A11),Dashboard!$AI$2:$AI$31,0),COLUMNS($D11:D11)))&"/"&INDEX(Management!$B$7:$B$36,COLUMNS($D11:D11)))} -> 2/10 | E11: {=IF(OR($A11="",COLUMNS($D11:E11)>Management!$C$4),"",N(INDEX(Dashboard!$C$2:$AF$31,MATCH(LARGE(Dashboard!$AI$2:$AI$31,$A11),Dashboard!$AI$2:$AI$31,0),COLUMNS($D11:E11)))&"/"&INDEX(Management!$B$7:$B$36,COLUMNS($D11:E11)))} -> 10/10 | F11: {=IF(OR($A11="",COLUMNS($D11:F11)>Management!$C$4),"",N(INDEX(Dashboard!$C$2:$AF$31,MATCH(LARGE(Dashboard!$AI$2:$AI$31,$A11),Dashboard!$AI$2:$AI$31,0),COLUMNS($D11:F11)))&"/"&INDEX(Management!$B$7:$B$36,COLUMNS($D11:F11)))} -> 4/10 | G11: {=IF(OR($A11="",COLUMNS($D11:G11)>Management!$C$4),"",N(INDEX(Dashboard!$C$2:$AF$31,MATCH(LARGE(Dashboard!$AI$2:$AI$31,$A11),Dashboard!$AI$2:$AI$31,0),COLUMNS($D11:G11)))&"/"&INDEX(Management!$B$7:$B$36,COLUMNS($D11:G11)))} -> 17/20 | H11: {=IF(OR($A11="",COLUMNS($D11:H11)>Management!$C$4),"",N(INDEX(Dashboard!$C$2:$AF$31,MATCH(LARGE(Dashboard!$AI$2:$AI$31,$A11),Dashboard!$AI$2:$AI$31,0),COLUMNS($D11:H11)))&"/"&INDEX(Management!$B$7:$B$36,COLUMNS($D11:H11)))} -> 0/10 | I11: {=IF(OR($A11="",COLUMNS($D11:I11)>Management!$C$4),"",N(INDEX(Dashboard!$C$2:$AF$31,MATCH(LARGE(Dashboard!$AI$2:$AI$31,$A11),Dashboard!$AI$2:$AI$31,0),COLUMNS($D11:I11)))&"/"&INDEX(Management!$B$7:$B$36,COLUMNS($D11:I11)))} -> 10/10 | J11: {=IF(OR($A11="",COLUMNS($D11:J11)>Management!$C$4),"",N(INDEX(Dashboard!$C$2:$AF$31,MATCH(LARGE(Dashboard!$AI$2:$AI$31,$A11),Dashboard!$AI$2:$AI$31,0),COLUMNS($D11:J11)))&"/"&INDEX(Management!$B$7:$B$36,COLUMNS($D11:J11)))} -> 4/10 | K11: {=IF(OR($A11="",COLUMNS($D11:K11)>Management!$C$4),"",N(INDEX(Dashboard!$C$2:$AF$31,MATCH(LARGE(Dashboard!$AI$2:$AI$31,$A11),Dashboard!$AI$2:$AI$31,0),COLUMNS($D11:K11)))&"/"&INDEX(Management!$B$7:$B$36,COLUMNS($D11:K11)))} -> 12/15 | ... AG11: {=IF(OR($A11="",COLUMNS($D11:AG11)>Management!$C$4),"",N(INDEX(Dashboard!$C$2:$AF$31,MATCH(LARGE(Dashboard!$AI$2:$AI$31,$A11),Dashboard!$AI$2:$AI$31,0),COLUMNS($D11:AG11)))&"/"&INDEX(Management!$B$7:$B$36,COLUMNS($D11:AG11)))}
A12: =IF(ROWS($A$2:A12)>COUNTA(Management!$F$7:$F$36),"",ROWS($A$2:A12)) -> 11 | B12: =IF($A12="","",INDEX(Dashboard!$A$2:$A$31,MATCH(LARGE(Dashboard!$AI$2:$AI$31,$A12),Dashboard!$AI$2:$AI$31,0))) -> Team24 | C12: =IF($A12="","",INDEX(Dashboard!$AG$2:$AG$31,MATCH(LARGE(Dashboard!$AI$2:$AI$31,$A12),Dashboard!$AI$2:$AI$31,0))&" / "&INDEX(Dashboard!$AH$2:$AH$31,MATCH(LARGE(Dashboard!$AI$2:$AI$31,$A12),Dashboard!$AI$2:$AI$31,0))) -> 76 / 140 | D12: {=IF(OR($A12="",COLUMNS($D12:D12)>Management!$C$4),"",N(INDEX(Dashboard!$C$2:$AF$31,MATCH(LARGE(Dashboard!$AI$2:$AI$31,$A12),Dashboard!$AI$2:$AI$31,0),COLUMNS($D12:D12)))&"/"&INDEX(Management!$B$7:$B$36,COLUMNS($D12:D12)))} -> 8/10 | E12: {=IF(OR($A12="",COLUMNS($D12:E12)>Management!$C$4),"",N(INDEX(Dashboard!$C$2:$AF$31,MATCH(LARGE(Dashboard!$AI$2:$AI$31,$A12),Dashboard!$AI$2:$AI$31,0),COLUMNS($D12:E12)))&"/"&INDEX(Management!$B$7:$B$36,COLUMNS($D12:E12)))} -> 8/10 | F12: {=IF(OR($A12="",COLUMNS($D12:F12)>Management!$C$4),"",N(INDEX(Dashboard!$C$2:$AF$31,MATCH(LARGE(Dashboard!$AI$2:$AI$31,$A12),Dashboard!$AI$2:$AI$31,0),COLUMNS($D12:F12)))&"/"&INDEX(Management!$B$7:$B$36,COLUMNS($D12:F12)))} -> 9/10 | G12: {=IF(OR($A12="",COLUMNS($D12:G12)>Management!$C$4),"",N(INDEX(Dashboard!$C$2:$AF$31,MATCH(LARGE(Dashboard!$AI$2:$AI$31,$A12),Dashboard!$AI$2:$AI$31,0),COLUMNS($D12:G12)))&"/"&INDEX(Management!$B$7:$B$36,COLUMNS($D12:G12)))} -> 20/20 | H12: {=IF(OR($A12="",COLUMNS($D12:H12)>Management!$C$4),"",N(INDEX(Dashboard!$C$2:$AF$31,MATCH(LARGE(Dashboard!$AI$2:$AI$31,$A12),Dashboard!$AI$2:$AI$31,0),COLUMNS($D12:H12)))&"/"&INDEX(Management!$B$7:$B$36,COLUMNS($D12:H12)))} -> 3/10 | I12: {=IF(OR($A12="",COLUMNS($D12:I12)>Management!$C$4),"",N(INDEX(Dashboard!$C$2:$AF$31,MATCH(LARGE(Dashboard!$AI$2:$AI$31,$A12),Dashboard!$AI$2:$AI$31,0),COLUMNS($D12:I12)))&"/"&INDEX(Management!$B$7:$B$36,COLUMNS($D12:I12)))} -> 4/10 | J12: {=IF(OR($A12="",COLUMNS($D12:J12)>Management!$C$4),"",N(INDEX(Dashboard!$C$2:$AF$31,MATCH(LARGE(Dashboard!$AI$2:$AI$31,$A12),Dashboard!$AI$2:$AI$31,0),COLUMNS($D12:J12)))&"/"&INDEX(Management!$B$7:$B$36,COLUMNS($D12:J12)))} -> 4/10 | K12: {=IF(OR($A12="",COLUMNS($D12:K12)>Management!$C$4),"",N(INDEX(Dashboard!$C$2:$AF$31,MATCH(LARGE(Dashboard!$AI$2:$AI$31,$A12),Dashboard!$AI$2:$AI$31,0),COLUMNS($D12:K12)))&"/"&INDEX(Management!$B$7:$B$36,COLUMNS($D12:K12)))} -> 4/15 | ... AG12: {=IF(OR($A12="",COLUMNS($D12:AG12)>Management!$C$4),"",N(INDEX(Dashboard!$C$2:$AF$31,MATCH(LARGE(Dashboard!$AI$2:$AI$31,$A12),Dashboard!$AI$2:$AI$31,0),COLUMNS($D12:AG12)))&"/"&INDEX(Management!$B$7:$B$36,COLUMNS($D12:AG12)))}
A13: =IF(ROWS($A$2:A13)>COUNTA(Management!$F$7:$F$36),"",ROWS($A$2:A13)) -> 12 | B13: =IF($A13="","",INDEX(Dashboard!$A$2:$A$31,MATCH(LARGE(Dashboard!$AI$2:$AI$31,$A13),Dashboard!$AI$2:$AI$31,0))) -> De Pittige Pepernoten | C13: =IF($A13="","",INDEX(Dashboard!$AG$2:$AG$31,MATCH(LARGE(Dashboard!$AI$2:$AI$31,$A13),Dashboard!$AI$2:$AI$31,0))&" / "&INDEX(Dashboard!$AH$2:$AH$31,MATCH(LARGE(Dashboard!$AI$2:$AI$31,$A13),Dashboard!$AI$2:$AI$31,0))) -> 74 / 140 | D13: {=IF(OR($A13="",COLUMNS($D13:D13)>Management!$C$4),"",N(INDEX(Dashboard!$C$2:$AF$31,MATCH(LARGE(Dashboard!$AI$2:$AI$31,$A13),Dashboard!$AI$2:$AI$31,0),COLUMNS($D13:D13)))&"/"&INDEX(Management!$B$7:$B$36,COLUMNS($D13:D13)))} -> 4/10 | E13: {=IF(OR($A13="",COLUMNS($D13:E13)>Management!$C$4),"",N(INDEX(Dashboard!$C$2:$AF$31,MATCH(LARGE(Dashboard!$AI$2:$AI$31,$A13),Dashboard!$AI$2:$AI$31,0),COLUMNS($D13:E13)))&"/"&INDEX(Management!$B$7:$B$36,COLUMNS($D13:E13)))} -> 6/10 | F13: {=IF(OR($A13="",COLUMNS($D13:F13)>Management!$C$4),"",N(INDEX(Dashboard!$C$2:$AF$31,MATCH(LARGE(Dashboard!$AI$2:$AI$31,$A13),Dashboard!$AI$2:$AI$31,0),COLUMNS($D13:F13)))&"/"&INDEX(Management!$B$7:$B$36,COLUMNS($D13:F13)))} -> 4/10 | G13: {=IF(OR($A13="",COLUMNS($D13:G13)>Management!$C$4),"",N(INDEX(Dashboard!$C$2:$AF$31,MATCH(LARGE(Dashboard!$AI$2:$AI$31,$A13),Dashboard!$AI$2:$AI$31,0),COLUMNS($D13:G13)))&"/"&INDEX(Management!$B$7:$B$36,COLUMNS($D13:G13)))} -> 15/20 | H13: {=IF(OR($A13="",COLUMNS($D13:H13)>Management!$C$4),"",N(INDEX(Dashboard!$C$2:$AF$31,MATCH(LARGE(Dashboard!$AI$2:$AI$31,$A13),Dashboard!$AI$2:$AI$31,0),COLUMNS($D13:H13)))&"/"&INDEX(Management!$B$7:$B$36,COLUMNS($D13:H13)))} -> 2/10 | I13: {=IF(OR($A13="",COLUMNS($D13:I13)>Management!$C$4),"",N(INDEX(Dashboard!$C$2:$AF$31,MATCH(LARGE(Dashboard!$AI$2:$AI$31,$A13),Dashboard!$AI$2:$AI$31,0),COLUMNS($D13:I13)))&"/"&INDEX(Management!$B$7:$B$36,COLUMNS($D13:I13)))} -> 4/10 | J13: {=IF(OR($A13="",COLUMNS($D13:J13)>Management!$C$4),"",N(INDEX(Dashboard!$C$2:$AF$31,MATCH(LARGE(Dashboard!$AI$2:$AI$31,$A13),Dashboard!$AI$2:$AI$31,0),COLUMNS($D13:J13)))&"/"&INDEX(Management!$B$7:$B$36,COLUMNS($D13:J13)))} -> 6/10 | K13: {=IF(OR($A13="",COLUMNS($D13:K13)>Management!$C$4),"",N(INDEX(Dashboard!$C$2:$AF$31,MATCH(LARGE(Dashboard!$AI$2:$AI$31,$A13),Dashboard!$AI$2:$AI$31,0),COLUMNS($D13:K13)))&"/"&INDEX(Management!$B$7:$B$36,COLUMNS($D13:K13)))} -> 9/15 | ... AG13: {=IF(OR($A13="",COLUMNS($D13:AG13)>Management!$C$4),"",N(INDEX(Dashboard!$C$2:$AF$31,MATCH(LARGE(Dashboard!$AI$2:$AI$31,$A13),Dashboard!$AI$2:$AI$31,0),COLUMNS($D13:AG13)))&"/"&INDEX(Management!$B$7:$B$36,COLUMNS($D13:AG13)))}
... A31: =IF(ROWS($A$2:A31)>COUNTA(Management!$F$7:$F$36),"",ROWS($A$2:A31)) -> 30 | B31: =IF($A31="","",INDEX(Dashboard!$A$2:$A$31,MATCH(LARGE(Dashboard!$AI$2:$AI$31,$A31),Dashboard!$AI$2:$AI$31,0))) -> Team19 | C31: =IF($A31="","",INDEX(Dashboard!$AG$2:$AG$31,MATCH(LARGE(Dashboard!$AI$2:$AI$31,$A31),Dashboard!$AI$2:$AI$31,0))&" / "&INDEX(Dashboard!$AH$2:$AH$31,MATCH(LARGE(Dashboard!$AI$2:$AI$31,$A31),Dashboard!$AI$2:$AI$31,0))) -> 42 / 140 | D31: {=IF(OR($A31="",COLUMNS($D31:D31)>Management!$C$4),"",N(INDEX(Dashboard!$C$2:$AF$31,MATCH(LARGE(Dashboard!$AI$2:$AI$31,$A31),Dashboard!$AI$2:$AI$31,0),COLUMNS($D31:D31)))&"/"&INDEX(Management!$B$7:$B$36,COLUMNS($D31:D31)))} -> 3/10 | E31: {=IF(OR($A31="",COLUMNS($D31:E31)>Management!$C$4),"",N(INDEX(Dashboard!$C$2:$AF$31,MATCH(LARGE(Dashboard!$AI$2:$AI$31,$A31),Dashboard!$AI$2:$AI$31,0),COLUMNS($D31:E31)))&"/"&INDEX(Management!$B$7:$B$36,COLUMNS($D31:E31)))} -> 6/10 | F31: {=IF(OR($A31="",COLUMNS($D31:F31)>Management!$C$4),"",N(INDEX(Dashboard!$C$2:$AF$31,MATCH(LARGE(Dashboard!$AI$2:$AI$31,$A31),Dashboard!$AI$2:$AI$31,0),COLUMNS($D31:F31)))&"/"&INDEX(Management!$B$7:$B$36,COLUMNS($D31:F31)))} -> 6/10 | G31: {=IF(OR($A31="",COLUMNS($D31:G31)>Management!$C$4),"",N(INDEX(Dashboard!$C$2:$AF$31,MATCH(LARGE(Dashboard!$AI$2:$AI$31,$A31),Dashboard!$AI$2:$AI$31,0),COLUMNS($D31:G31)))&"/"&INDEX(Management!$B$7:$B$36,COLUMNS($D31:G31)))} -> 5/20 | H31: {=IF(OR($A31="",COLUMNS($D31:H31)>Management!$C$4),"",N(INDEX(Dashboard!$C$2:$AF$31,MATCH(LARGE(Dashboard!$AI$2:$AI$31,$A31),Dashboard!$AI$2:$AI$31,0),COLUMNS($D31:H31)))&"/"&INDEX(Management!$B$7:$B$36,COLUMNS($D31:H31)))} -> 3/10 | I31: {=IF(OR($A31="",COLUMNS($D31:I31)>Management!$C$4),"",N(INDEX(Dashboard!$C$2:$AF$31,MATCH(LARGE(Dashboard!$AI$2:$AI$31,$A31),Dashboard!$AI$2:$AI$31,0),COLUMNS($D31:I31)))&"/"&INDEX(Management!$B$7:$B$36,COLUMNS($D31:I31)))} -> 4/10 | J31: {=IF(OR($A31="",COLUMNS($D31:J31)>Management!$C$4),"",N(INDEX(Dashboard!$C$2:$AF$31,MATCH(LARGE(Dashboard!$AI$2:$AI$31,$A31),Dashboard!$AI$2:$AI$31,0),COLUMNS($D31:J31)))&"/"&INDEX(Management!$B$7:$B$36,COLUMNS($D31:J31)))} -> 0/10 | K31: {=IF(OR($A31="",COLUMNS($D31:K31)>Management!$C$4),"",N(INDEX(Dashboard!$C$2:$AF$31,MATCH(LARGE(Dashboard!$AI$2:$AI$31,$A31),Dashboard!$AI$2:$AI$31,0),COLUMNS($D31:K31)))&"/"&INDEX(Management!$B$7:$B$36,COLUMNS($D31:K31)))} -> 11/15 | ... AG31: {=IF(OR($A31="",COLUMNS($D31:AG31)>Management!$C$4),"",N(INDEX(Dashboard!$C$2:$AF$31,MATCH(LARGE(Dashboard!$AI$2:$AI$31,$A31),Dashboard!$AI$2:$AI$31,0),COLUMNS($D31:AG31)))&"/"&INDEX(Management!$B$7:$B$36,COLUMNS($D31:AG31)))}

Sheet Statistics
B2: Quiz Statistics
B5: Aggregate insights across all teams and rounds
V6: 📈 Round Difficulty
B7: TEAMS | G7: ROUNDS | L7: TOTAL POINTS | Q7: AVG / ROUND | V7: Rd | W7: Avg | X7: Max | Y7: Min | Z7: Difficulty (longer = easier) | AA7: % Perfect
V8: =IF(1<=Management!$C$4,"R1","") -> R1 | W8: =IF(1<=Management!$C$4,ROUND(AVERAGE(OFFSET(Dashboard!$B$2,0,1,COUNTA(Management!$F$7:$F$36),1)),1),"") -> 5.5 | X8: =IF(1<=Management!$C$4,MAX(OFFSET(Dashboard!$B$2,0,1,COUNTA(Management!$F$7:$F$36),1)),"") -> 8 | Y8: =IF(1<=Management!$C$4,MIN(OFFSET(Dashboard!$B$2,0,1,COUNTA(Management!$F$7:$F$36),1)),"") -> 2 | Z8: =IF(1<=Management!$C$4,REPT("█",ROUND(AVERAGE(OFFSET(Dashboard!$B$2,0,1,COUNTA(Management!$F$7:$F$36),1))*2,0)),"") -> ███████████ | AA8: =IF(1<=Management!$C$4,TEXT(COUNTIF(OFFSET(Dashboard!$B$2,0,1,COUNTA(Management!$F$7:$F$36),1),10)/COUNTA(Management!$F$7:$F$36),"0%"),"") -> 0%
B9: =COUNTA(Management!F7:F36) -> 30 | G9: =Management!C4 -> 13 | L9: =SUM(Dashboard!C2:AF31) -> 2061 | Q9: =ROUND(AVERAGE(Dashboard!C2:AF31),1) -> 5.3 | V9: =IF(2<=Management!$C$4,"R2","") -> R2 | W9: =IF(2<=Management!$C$4,ROUND(AVERAGE(OFFSET(Dashboard!$B$2,0,2,COUNTA(Management!$F$7:$F$36),1)),1),"") -> 6.5 | X9: =IF(2<=Management!$C$4,MAX(OFFSET(Dashboard!$B$2,0,2,COUNTA(Management!$F$7:$F$36),1)),"") -> 10 | Y9: =IF(2<=Management!$C$4,MIN(OFFSET(Dashboard!$B$2,0,2,COUNTA(Management!$F$7:$F$36),1)),"") -> 3 | Z9: =IF(2<=Management!$C$4,REPT("█",ROUND(AVERAGE(OFFSET(Dashboard!$B$2,0,2,COUNTA(Management!$F$7:$F$36),1))*2,0)),"") -> █████████████ | AA9: =IF(2<=Management!$C$4,TEXT(COUNTIF(OFFSET(Dashboard!$B$2,0,2,COUNTA(Management!$F$7:$F$36),1),10)/COUNTA(Management!$F$7:$F$36),"0%"),"") -> 17%
V10: =IF(3<=Management!$C$4,"R3","") -> R3 | W10: =IF(3<=Management!$C$4,ROUND(AVERAGE(OFFSET(Dashboard!$B$2,0,3,COUNTA(Management!$F$7:$F$36),1)),1),"") -> 6.4 | X10: =IF(3<=Management!$C$4,MAX(OFFSET(Dashboard!$B$2,0,3,COUNTA(Management!$F$7:$F$36),1)),"") -> 9 | Y10: =IF(3<=Management!$C$4,MIN(OFFSET(Dashboard!$B$2,0,3,COUNTA(Management!$F$7:$F$36),1)),"") -> 1 | Z10: =IF(3<=Management!$C$4,REPT("█",ROUND(AVERAGE(OFFSET(Dashboard!$B$2,0,3,COUNTA(Management!$F$7:$F$36),1))*2,0)),"") -> █████████████ | AA10: =IF(3<=Management!$C$4,TEXT(COUNTIF(OFFSET(Dashboard!$B$2,0,3,COUNTA(Management!$F$7:$F$36),1),10)/COUNTA(Management!$F$7:$F$36),"0%"),"") -> 0%
V11: =IF(4<=Management!$C$4,"R4","") -> R4 | W11: =IF(4<=Management!$C$4,ROUND(AVERAGE(OFFSET(Dashboard!$B$2,0,4,COUNTA(Management!$F$7:$F$36),1)),1),"") -> 9.5 | X11: =IF(4<=Management!$C$4,MAX(OFFSET(Dashboard!$B$2,0,4,COUNTA(Management!$F$7:$F$36),1)),"") -> 20 | Y11: =IF(4<=Management!$C$4,MIN(OFFSET(Dashboard!$B$2,0,4,COUNTA(Management!$F$7:$F$36),1)),"") -> 1 | Z11: =IF(4<=Management!$C$4,REPT("█",ROUND(AVERAGE(OFFSET(Dashboard!$B$2,0,4,COUNTA(Management!$F$7:$F$36),1))*2,0)),"") -> ███████████████████ | AA11: =IF(4<=Management!$C$4,TEXT(COUNTIF(OFFSET(Dashboard!$B$2,0,4,COUNTA(Management!$F$7:$F$36),1),10)/COUNTA(Management!$F$7:$F$36),"0%"),"") -> 10%
B12: 📊 Score Distribution | L12: 🎯 Team Performance Spread | V12: =IF(5<=Management!$C$4,"R5","") -> R5 | W12: =IF(5<=Management!$C$4,ROUND(AVERAGE(OFFSET(Dashboard!$B$2,0,5,COUNTA(Management!$F$7:$F$36),1)),1),"") -> 5.6 | X12: =IF(5<=Management!$C$4,MAX(OFFSET(Dashboard!$B$2,0,5,COUNTA(Management!$F$7:$F$36),1)),"") -> 10 | Y12: =IF(5<=Management!$C$4,MIN(OFFSET(Dashboard!$B$2,0,5,COUNTA(Management!$F$7:$F$36),1)),"") -> 0 | Z12: =IF(5<=Management!$C$4,REPT("█",ROUND(AVERAGE(OFFSET(Dashboard!$B$2,0,5,COUNTA(Management!$F$7:$F$36),1))*2,0)),"") -> ███████████ | AA12: =IF(5<=Management!$C$4,TEXT(COUNTIF(OFFSET(Dashboard!$B$2,0,5,COUNTA(Management!$F$7:$F$36),1),10)/COUNTA(Management!$F$7:$F$36),"0%"),"") -> 10%
B13: Highest single-round score | J13: =MAX(Dashboard!C2:AF31)&" pts" -> 20 pts | L13: Best team total | T13: =MAX(Dashboard!AG2:AG11)&" pts" -> 82 pts | V13: =IF(6<=Management!$C$4,"R6","") -> R6 | W13: =IF(6<=Management!$C$4,ROUND(AVERAGE(OFFSET(Dashboard!$B$2,0,6,COUNTA(Management!$F$7:$F$36),1)),1),"") -> 3.9 | X13: =IF(6<=Management!$C$4,MAX(OFFSET(Dashboard!$B$2,0,6,COUNTA(Management!$F$7:$F$36),1)),"") -> 10 | Y13: =IF(6<=Management!$C$4,MIN(OFFSET(Dashboard!$B$2,0,6,COUNTA(Management!$F$7:$F$36),1)),"") -> 0 | Z13: =IF(6<=Management!$C$4,REPT("█",ROUND(AVERAGE(OFFSET(Dashboard!$B$2,0,6,COUNTA(Management!$F$7:$F$36),1))*2,0)),"") -> ████████ | AA13: =IF(6<=Management!$C$4,TEXT(COUNTIF(OFFSET(Dashboard!$B$2,0,6,COUNTA(Management!$F$7:$F$36),1),10)/COUNTA(Management!$F$7:$F$36),"0%"),"") -> 10%
B14: Lowest single-round score | J14: =MIN(Dashboard!C2:AF31)&" pts" -> 0 pts | L14: Worst team total | T14: =MIN(Dashboard!AG2:AG11)&" pts" -> 46 pts | V14: =IF(7<=Management!$C$4,"R7","") -> R7 | W14: =IF(7<=Management!$C$4,ROUND(AVERAGE(OFFSET(Dashboard!$B$2,0,7,COUNTA(Management!$F$7:$F$36),1)),1),"") -> 4.6 | X14: =IF(7<=Management!$C$4,MAX(OFFSET(Dashboard!$B$2,0,7,COUNTA(Management!$F$7:$F$36),1)),"") -> 10 | Y14: =IF(7<=Management!$C$4,MIN(OFFSET(Dashboard!$B$2,0,7,COUNTA(Management!$F$7:$F$36),1)),"") -> 0 | Z14: =IF(7<=Management!$C$4,REPT("█",ROUND(AVERAGE(OFFSET(Dashboard!$B$2,0,7,COUNTA(Management!$F$7:$F$36),1))*2,0)),"") -> █████████ | AA14: =IF(7<=Management!$C$4,TEXT(COUNTIF(OFFSET(Dashboard!$B$2,0,7,COUNTA(Management!$F$7:$F$36),1),10)/COUNTA(Management!$F$7:$F$36),"0%"),"") -> 10%
B15: Median round score | J15: =ROUND(MEDIAN(Dashboard!C2:AF31),1)&" pts" -> 5 pts | L15: Average team total | T15: =ROUND(AVERAGE(Dashboard!AG2:AG11),1)&" pts" -> 69,3 pts | V15: =IF(8<=Management!$C$4,"R8","") -> R8 | W15: =IF(8<=Management!$C$4,ROUND(AVERAGE(OFFSET(Dashboard!$B$2,0,8,COUNTA(Management!$F$7:$F$36),1)),1),"") -> 7.9 | X15: =IF(8<=Management!$C$4,MAX(OFFSET(Dashboard!$B$2,0,8,COUNTA(Management!$F$7:$F$36),1)),"") -> 15 | Y15: =IF(8<=Management!$C$4,MIN(OFFSET(Dashboard!$B$2,0,8,COUNTA(Management!$F$7:$F$36),1)),"") -> 3 | Z15: =IF(8<=Management!$C$4,REPT("█",ROUND(AVERAGE(OFFSET(Dashboard!$B$2,0,8,COUNTA(Management!$F$7:$F$36),1))*2,0)),"") -> ████████████████ | AA15: =IF(8<=Management!$C$4,TEXT(COUNTIF(OFFSET(Dashboard!$B$2,0,8,COUNTA(Management!$F$7:$F$36),1),10)/COUNTA(Management!$F$7:$F$36),"0%"),"") -> 0%
B16: Std deviation of scores | J16: =ROUND(STDEV(Dashboard!C2:AF31),2) -> 3.49 | L16: Score gap (best − worst) | T16: =(MAX(Dashboard!AG2:AG11)-MIN(Dashboard!AG2:AG11))&" pts" -> 36 pts | V16: =IF(9<=Management!$C$4,"R9","") -> R9 | W16: =IF(9<=Management!$C$4,ROUND(AVERAGE(OFFSET(Dashboard!$B$2,0,9,COUNTA(Management!$F$7:$F$36),1)),1),"") -> 4.7 | X16: =IF(9<=Management!$C$4,MAX(OFFSET(Dashboard!$B$2,0,9,COUNTA(Management!$F$7:$F$36),1)),"") -> 9 | Y16: =IF(9<=Management!$C$4,MIN(OFFSET(Dashboard!$B$2,0,9,COUNTA(Management!$F$7:$F$36),1)),"") -> 0 | Z16: =IF(9<=Management!$C$4,REPT("█",ROUND(AVERAGE(OFFSET(Dashboard!$B$2,0,9,COUNTA(Management!$F$7:$F$36),1))*2,0)),"") -> █████████ | AA16: =IF(9<=Management!$C$4,TEXT(COUNTIF(OFFSET(Dashboard!$B$2,0,9,COUNTA(Management!$F$7:$F$36),1),10)/COUNTA(Management!$F$7:$F$36),"0%"),"") -> 0%
B17: Perfect rounds (10/10) | J17: =COUNTIF(Dashboard!C2:AF31,10) -> 18 | L17: Std deviation across teams | T17: =ROUND(STDEV(Dashboard!AG2:AG11),2) -> 13 | V17: =IF(10<=Management!$C$4,"R10","") -> R10 | W17: =IF(10<=Management!$C$4,ROUND(AVERAGE(OFFSET(Dashboard!$B$2,0,10,COUNTA(Management!$F$7:$F$36),1)),1),"") -> 4.2 | X17: =IF(10<=Management!$C$4,MAX(OFFSET(Dashboard!$B$2,0,10,COUNTA(Management!$F$7:$F$36),1)),"") -> 9 | Y17: =IF(10<=Management!$C$4,MIN(OFFSET(Dashboard!$B$2,0,10,COUNTA(Management!$F$7:$F$36),1)),"") -> 0 | Z17: =IF(10<=Management!$C$4,REPT("█",ROUND(AVERAGE(OFFSET(Dashboard!$B$2,0,10,COUNTA(Management!$F$7:$F$36),1))*2,0)),"") -> ████████ | AA17: =IF(10<=Management!$C$4,TEXT(COUNTIF(OFFSET(Dashboard!$B$2,0,10,COUNTA(Management!$F$7:$F$36),1),10)/COUNTA(Management!$F$7:$F$36),"0%"),"") -> 0%
B18: Zero rounds (0/10) | J18: =COUNTIF(Dashboard!C2:AF31,0) -> 31 | L18: Teams above average | T18: =COUNTIF(Dashboard!AG2:AG11,">"&AVERAGE(Dashboard!AG2:AG11)) -> 6 | V18: =IF(11<=Management!$C$4,"R11","") -> R11 | W18: =IF(11<=Management!$C$4,ROUND(AVERAGE(OFFSET(Dashboard!$B$2,0,11,COUNTA(Management!$F$7:$F$36),1)),1),"") -> 0.9 | X18: =IF(11<=Management!$C$4,MAX(OFFSET(Dashboard!$B$2,0,11,COUNTA(Management!$F$7:$F$36),1)),"") -> 5 | Y18: =IF(11<=Management!$C$4,MIN(OFFSET(Dashboard!$B$2,0,11,COUNTA(Management!$F$7:$F$36),1)),"") -> 0 | Z18: =IF(11<=Management!$C$4,REPT("█",ROUND(AVERAGE(OFFSET(Dashboard!$B$2,0,11,COUNTA(Management!$F$7:$F$36),1))*2,0)),"") -> ██ | AA18: =IF(11<=Management!$C$4,TEXT(COUNTIF(OFFSET(Dashboard!$B$2,0,11,COUNTA(Management!$F$7:$F$36),1),10)/COUNTA(Management!$F$7:$F$36),"0%"),"") -> 0%
B19: Rounds at or above 8/10 | J19: =COUNTIF(Dashboard!C2:AF31,">=8") -> 94 | L19: Best score % of max | T19: =TEXT(MAX(Dashboard!AG2:AG11)/MAX(Dashboard!AH2:AH11),"0.0%") -> 59% | V19: =IF(12<=Management!$C$4,"R12","") -> R12 | W19: =IF(12<=Management!$C$4,ROUND(AVERAGE(OFFSET(Dashboard!$B$2,0,12,COUNTA(Management!$F$7:$F$36),1)),1),"") -> 4.3 | X19: =IF(12<=Management!$C$4,MAX(OFFSET(Dashboard!$B$2,0,12,COUNTA(Management!$F$7:$F$36),1)),"") -> 9 | Y19: =IF(12<=Management!$C$4,MIN(OFFSET(Dashboard!$B$2,0,12,COUNTA(Management!$F$7:$F$36),1)),"") -> 0 | Z19: =IF(12<=Management!$C$4,REPT("█",ROUND(AVERAGE(OFFSET(Dashboard!$B$2,0,12,COUNTA(Management!$F$7:$F$36),1))*2,0)),"") -> █████████ | AA19: =IF(12<=Management!$C$4,TEXT(COUNTIF(OFFSET(Dashboard!$B$2,0,12,COUNTA(Management!$F$7:$F$36),1),10)/COUNTA(Management!$F$7:$F$36),"0%"),"") -> 0%
B20: Rounds at or below 3/10 | J20: =COUNTIF(Dashboard!C2:AF31,"<=3") -> 109 | L20: Field average % of max | T20: =TEXT(AVERAGE(Dashboard!AG2:AG11)/MAX(Dashboard!AH2:AH11),"0.0%") -> 50% | V20: =IF(13<=Management!$C$4,"R13","") -> R13 | W20: =IF(13<=Management!$C$4,ROUND(AVERAGE(OFFSET(Dashboard!$B$2,0,13,COUNTA(Management!$F$7:$F$36),1)),1),"") -> 4.7 | X20: =IF(13<=Management!$C$4,MAX(OFFSET(Dashboard!$B$2,0,13,COUNTA(Management!$F$7:$F$36),1)),"") -> 10 | Y20: =IF(13<=Management!$C$4,MIN(OFFSET(Dashboard!$B$2,0,13,COUNTA(Management!$F$7:$F$36),1)),"") -> 1 | Z20: =IF(13<=Management!$C$4,REPT("█",ROUND(AVERAGE(OFFSET(Dashboard!$B$2,0,13,COUNTA(Management!$F$7:$F$36),1))*2,0)),"") -> █████████ | AA20: =IF(13<=Management!$C$4,TEXT(COUNTIF(OFFSET(Dashboard!$B$2,0,13,COUNTA(Management!$F$7:$F$36),1),10)/COUNTA(Management!$F$7:$F$36),"0%"),"") -> 3%
V21: =IF(14<=Management!$C$4,"R14","") | W21: =IF(14<=Management!$C$4,ROUND(AVERAGE(OFFSET(Dashboard!$B$2,0,14,COUNTA(Management!$F$7:$F$36),1)),1),"") | X21: =IF(14<=Management!$C$4,MAX(OFFSET(Dashboard!$B$2,0,14,COUNTA(Management!$F$7:$F$36),1)),"") | Y21: =IF(14<=Management!$C$4,MIN(OFFSET(Dashboard!$B$2,0,14,COUNTA(Management!$F$7:$F$36),1)),"") | Z21: =IF(14<=Management!$C$4,REPT("█",ROUND(AVERAGE(OFFSET(Dashboard!$B$2,0,14,COUNTA(Management!$F$7:$F$36),1))*2,0)),"") | AA21: =IF(14<=Management!$C$4,TEXT(COUNTIF(OFFSET(Dashboard!$B$2,0,14,COUNTA(Management!$F$7:$F$36),1),10)/COUNTA(Management!$F$7:$F$36),"0%"),"")
V22: =IF(15<=Management!$C$4,"R15","") | W22: =IF(15<=Management!$C$4,ROUND(AVERAGE(OFFSET(Dashboard!$B$2,0,15,COUNTA(Management!$F$7:$F$36),1)),1),"") | X22: =IF(15<=Management!$C$4,MAX(OFFSET(Dashboard!$B$2,0,15,COUNTA(Management!$F$7:$F$36),1)),"") | Y22: =IF(15<=Management!$C$4,MIN(OFFSET(Dashboard!$B$2,0,15,COUNTA(Management!$F$7:$F$36),1)),"") | Z22: =IF(15<=Management!$C$4,REPT("█",ROUND(AVERAGE(OFFSET(Dashboard!$B$2,0,15,COUNTA(Management!$F$7:$F$36),1))*2,0)),"") | AA22: =IF(15<=Management!$C$4,TEXT(COUNTIF(OFFSET(Dashboard!$B$2,0,15,COUNTA(Management!$F$7:$F$36),1),10)/COUNTA(Management!$F$7:$F$36),"0%"),"")
